{"num_games": 100, "student_agent_wins": [0, 1, 0, 0, 0, 0, 0, 0, 1, 0, 0, 1, 0, 1, 0, 0, 0, 0, 0, 1, 0, 0, 1, 1, 0, 0, 0, 1, 0, 0, 0, 0, 0, 0, 0, 1, 0, 0, 1, 0, 0, 0, 0, 0, 0, 0, 0, 0, 0, 1, 1, 0, 0, 1, 0, 0, 1, 0, 0, 0, 0, 0, 0, 0, 0, 1, 1, 0, 0, 1, 0, 0, 0, 0, 0, 0, 0, 0, 0, 0, 0, 1, 1, 0, 1, 0, 0, 0, 0, 0, 0, 1, 1, 0, 0, 0, 0, 0, 1, 1], "random_agent_wins": [1, 0, 1, 1, 1, 1, 1, 1, 0, 1, 1, 0, 1, 0, 1, 1, 1, 1, 1, 0, 1, 1, 0, 0, 1, 1, 1, 0, 1, 1, 1, 1, 1, 1, 1, 0, 1, 1, 0, 1, 1, 1, 1, 1, 1, 1, 1, 1, 1, 0, 0, 1, 1, 0, 1, 1, 0, 1, 1, 1, 1, 1, 1, 1, 1, 0, 0, 1, 1, 0, 1, 1, 1, 1, 1, 1, 1, 1, 1, 1, 1, 0, 0, 1, 0, 1, 1, 1, 1, 1, 1, 0, 0, 1, 1, 1, 1, 1, 0, 0], "student_agent_win_count": 24, "random_agent_win_count": 76, "student_agent_win_percentage": 0.24, "random_agent_win_percentage": 0.76, "student_agent_time_taken": 0.0036926722526550294, "random_agent_time_taken": 0.0032256817817687988, "run_info": [{"student_agent_score": 1, "random_agent_score": 35, "student_agent_time": 0.002844572067260742, "random_agent_time": 0.0008952617645263672, "board_size": 6, "swap_players": false, "run_out": "An exception raised. The traceback is as follows:\nTraceback (most recent call last):\n  File \"/home/ml/users/ksinha4/mlp/comp424_final_project/submissions/comp424mcgill/final-project-a_team_name/world.py\", line 310, in step\n    raise ValueError(\nValueError: [INVALID:STEP] Not a valid step from [2 2] to [2 2] and put barrier at 0, with max steps = 3\n\nExecute Random Walk!\nAn exception raised. The traceback is as follows:\nTraceback (most recent call last):\n  File \"/home/ml/users/ksinha4/mlp/comp424_final_project/submissions/comp424mcgill/final-project-a_team_name/world.py\", line 310, in step\n    raise ValueError(\nValueError: [INVALID:STEP] Not a valid step from [3 0] to [3 0] and put barrier at 0, with max steps = 3\n\nExecute Random Walk!\n"}, {"student_agent_score": 63, "random_agent_score": 1, "student_agent_time": 0.002557039260864258, "random_agent_time": 0.0027382373809814453, "board_size": 8, "swap_players": true, "run_out": "An exception raised. The traceback is as follows:\nTraceback (most recent call last):\n  File \"/home/ml/users/ksinha4/mlp/comp424_final_project/submissions/comp424mcgill/final-project-a_team_name/world.py\", line 310, in step\n    raise ValueError(\nValueError: [INVALID:STEP] Not a valid step from [5 5] to [5 5] and put barrier at 0, with max steps = 4\n\nExecute Random Walk!\nAn exception raised. The traceback is as follows:\nTraceback (most recent call last):\n  File \"/home/ml/users/ksinha4/mlp/comp424_final_project/submissions/comp424mcgill/final-project-a_team_name/world.py\", line 310, in step\n    raise ValueError(\nValueError: [INVALID:STEP] Not a valid step from [5 4] to [5 4] and put barrier at 0, with max steps = 4\n\nExecute Random Walk!\nAn exception raised. The traceback is as follows:\nTraceback (most recent call last):\n  File \"/home/ml/users/ksinha4/mlp/comp424_final_project/submissions/comp424mcgill/final-project-a_team_name/world.py\", line 310, in step\n    raise ValueError(\nValueError: [INVALID:STEP] Not a valid step from [5 4] to [5 4] and put barrier at 0, with max steps = 4\n\nExecute Random Walk!\n"}, {"student_agent_score": 1, "random_agent_score": 48, "student_agent_time": 0.004172325134277344, "random_agent_time": 0.002171754837036133, "board_size": 7, "swap_players": false, "run_out": "An exception raised. The traceback is as follows:\nTraceback (most recent call last):\n  File \"/home/ml/users/ksinha4/mlp/comp424_final_project/submissions/comp424mcgill/final-project-a_team_name/world.py\", line 310, in step\n    raise ValueError(\nValueError: [INVALID:STEP] Not a valid step from [4 3] to [4 3] and put barrier at 0, with max steps = 4\n\nExecute Random Walk!\nAn exception raised. The traceback is as follows:\nTraceback (most recent call last):\n  File \"/home/ml/users/ksinha4/mlp/comp424_final_project/submissions/comp424mcgill/final-project-a_team_name/world.py\", line 310, in step\n    raise ValueError(\nValueError: [INVALID:STEP] Not a valid step from [4 2] to [4 2] and put barrier at 0, with max steps = 4\n\nExecute Random Walk!\nAn exception raised. The traceback is as follows:\nTraceback (most recent call last):\n  File \"/home/ml/users/ksinha4/mlp/comp424_final_project/submissions/comp424mcgill/final-project-a_team_name/world.py\", line 310, in step\n    raise ValueError(\nValueError: [INVALID:STEP] Not a valid step from [4 3] to [4 3] and put barrier at 0, with max steps = 4\n\nExecute Random Walk!\nAn exception raised. The traceback is as follows:\nTraceback (most recent call last):\n  File \"/home/ml/users/ksinha4/mlp/comp424_final_project/submissions/comp424mcgill/final-project-a_team_name/world.py\", line 310, in step\n    raise ValueError(\nValueError: [INVALID:STEP] Not a valid step from [5 4] to [5 4] and put barrier at 0, with max steps = 4\n\nExecute Random Walk!\nAn exception raised. The traceback is as follows:\nTraceback (most recent call last):\n  File \"/home/ml/users/ksinha4/mlp/comp424_final_project/submissions/comp424mcgill/final-project-a_team_name/world.py\", line 310, in step\n    raise ValueError(\nValueError: [INVALID:STEP] Not a valid step from [6 3] to [6 3] and put barrier at 0, with max steps = 4\n\nExecute Random Walk!\n"}, {"student_agent_score": 1, "random_agent_score": 48, "student_agent_time": 0.002226114273071289, "random_agent_time": 0.0020477771759033203, "board_size": 7, "swap_players": true, "run_out": "An exception raised. The traceback is as follows:\nTraceback (most recent call last):\n  File \"/home/ml/users/ksinha4/mlp/comp424_final_project/submissions/comp424mcgill/final-project-a_team_name/world.py\", line 310, in step\n    raise ValueError(\nValueError: [INVALID:STEP] Not a valid step from [2 3] to [2 3] and put barrier at 0, with max steps = 4\n\nExecute Random Walk!\nAn exception raised. The traceback is as follows:\nTraceback (most recent call last):\n  File \"/home/ml/users/ksinha4/mlp/comp424_final_project/submissions/comp424mcgill/final-project-a_team_name/world.py\", line 310, in step\n    raise ValueError(\nValueError: [INVALID:STEP] Not a valid step from [5 4] to [5 4] and put barrier at 0, with max steps = 4\n\nExecute Random Walk!\nAn exception raised. The traceback is as follows:\nTraceback (most recent call last):\n  File \"/home/ml/users/ksinha4/mlp/comp424_final_project/submissions/comp424mcgill/final-project-a_team_name/world.py\", line 310, in step\n    raise ValueError(\nValueError: [INVALID:STEP] Not a valid step from [6 3] to [6 3] and put barrier at 0, with max steps = 4\n\nExecute Random Walk!\n"}, {"student_agent_score": 1, "random_agent_score": 48, "student_agent_time": 0.0030803680419921875, "random_agent_time": 0.0020148754119873047, "board_size": 7, "swap_players": false, "run_out": "An exception raised. The traceback is as follows:\nTraceback (most recent call last):\n  File \"/home/ml/users/ksinha4/mlp/comp424_final_project/submissions/comp424mcgill/final-project-a_team_name/world.py\", line 310, in step\n    raise ValueError(\nValueError: [INVALID:STEP] Not a valid step from [4 3] to [4 3] and put barrier at 0, with max steps = 4\n\nExecute Random Walk!\nAn exception raised. The traceback is as follows:\nTraceback (most recent call last):\n  File \"/home/ml/users/ksinha4/mlp/comp424_final_project/submissions/comp424mcgill/final-project-a_team_name/world.py\", line 310, in step\n    raise ValueError(\nValueError: [INVALID:STEP] Not a valid step from [4 2] to [4 2] and put barrier at 0, with max steps = 4\n\nExecute Random Walk!\nAn exception raised. The traceback is as follows:\nTraceback (most recent call last):\n  File \"/home/ml/users/ksinha4/mlp/comp424_final_project/submissions/comp424mcgill/final-project-a_team_name/world.py\", line 310, in step\n    raise ValueError(\nValueError: [INVALID:STEP] Not a valid step from [4 3] to [4 3] and put barrier at 0, with max steps = 4\n\nExecute Random Walk!\nAn exception raised. The traceback is as follows:\nTraceback (most recent call last):\n  File \"/home/ml/users/ksinha4/mlp/comp424_final_project/submissions/comp424mcgill/final-project-a_team_name/world.py\", line 310, in step\n    raise ValueError(\nValueError: [INVALID:STEP] Not a valid step from [5 4] to [5 4] and put barrier at 0, with max steps = 4\n\nExecute Random Walk!\nAn exception raised. The traceback is as follows:\nTraceback (most recent call last):\n  File \"/home/ml/users/ksinha4/mlp/comp424_final_project/submissions/comp424mcgill/final-project-a_team_name/world.py\", line 310, in step\n    raise ValueError(\nValueError: [INVALID:STEP] Not a valid step from [6 3] to [6 3] and put barrier at 0, with max steps = 4\n\nExecute Random Walk!\n"}, {"student_agent_score": 1, "random_agent_score": 35, "student_agent_time": 0.0028350353240966797, "random_agent_time": 0.002088308334350586, "board_size": 6, "swap_players": true, "run_out": "An exception raised. The traceback is as follows:\nTraceback (most recent call last):\n  File \"/home/ml/users/ksinha4/mlp/comp424_final_project/submissions/comp424mcgill/final-project-a_team_name/world.py\", line 310, in step\n    raise ValueError(\nValueError: [INVALID:STEP] Not a valid step from [3 3] to [3 3] and put barrier at 0, with max steps = 3\n\nExecute Random Walk!\nAn exception raised. The traceback is as follows:\nTraceback (most recent call last):\n  File \"/home/ml/users/ksinha4/mlp/comp424_final_project/submissions/comp424mcgill/final-project-a_team_name/world.py\", line 310, in step\n    raise ValueError(\nValueError: [INVALID:STEP] Not a valid step from [3 3] to [3 3] and put barrier at 0, with max steps = 3\n\nExecute Random Walk!\n"}, {"student_agent_score": 2, "random_agent_score": 79, "student_agent_time": 0.004072904586791992, "random_agent_time": 0.0022735595703125, "board_size": 9, "swap_players": false, "run_out": "An exception raised. The traceback is as follows:\nTraceback (most recent call last):\n  File \"/home/ml/users/ksinha4/mlp/comp424_final_project/submissions/comp424mcgill/final-project-a_team_name/world.py\", line 310, in step\n    raise ValueError(\nValueError: [INVALID:STEP] Not a valid step from [5 4] to [5 4] and put barrier at 0, with max steps = 5\n\nExecute Random Walk!\nAn exception raised. The traceback is as follows:\nTraceback (most recent call last):\n  File \"/home/ml/users/ksinha4/mlp/comp424_final_project/submissions/comp424mcgill/final-project-a_team_name/world.py\", line 310, in step\n    raise ValueError(\nValueError: [INVALID:STEP] Not a valid step from [5 3] to [5 3] and put barrier at 0, with max steps = 5\n\nExecute Random Walk!\n"}, {"student_agent_score": 1, "random_agent_score": 48, "student_agent_time": 0.0032548904418945312, "random_agent_time": 0.00312042236328125, "board_size": 7, "swap_players": true, "run_out": "An exception raised. The traceback is as follows:\nTraceback (most recent call last):\n  File \"/home/ml/users/ksinha4/mlp/comp424_final_project/submissions/comp424mcgill/final-project-a_team_name/world.py\", line 310, in step\n    raise ValueError(\nValueError: [INVALID:STEP] Not a valid step from [2 3] to [2 3] and put barrier at 0, with max steps = 4\n\nExecute Random Walk!\nAn exception raised. The traceback is as follows:\nTraceback (most recent call last):\n  File \"/home/ml/users/ksinha4/mlp/comp424_final_project/submissions/comp424mcgill/final-project-a_team_name/world.py\", line 310, in step\n    raise ValueError(\nValueError: [INVALID:STEP] Not a valid step from [5 4] to [5 4] and put barrier at 0, with max steps = 4\n\nExecute Random Walk!\nAn exception raised. The traceback is as follows:\nTraceback (most recent call last):\n  File \"/home/ml/users/ksinha4/mlp/comp424_final_project/submissions/comp424mcgill/final-project-a_team_name/world.py\", line 310, in step\n    raise ValueError(\nValueError: [INVALID:STEP] Not a valid step from [6 3] to [6 3] and put barrier at 0, with max steps = 4\n\nExecute Random Walk!\n"}, {"student_agent_score": 99, "random_agent_score": 1, "student_agent_time": 0.0003306865692138672, "random_agent_time": 0.0009415149688720703, "board_size": 10, "swap_players": true, "run_out": ""}, {"student_agent_score": 1, "random_agent_score": 48, "student_agent_time": 0.003396272659301758, "random_agent_time": 0.0016970634460449219, "board_size": 7, "swap_players": false, "run_out": "An exception raised. The traceback is as follows:\nTraceback (most recent call last):\n  File \"/home/ml/users/ksinha4/mlp/comp424_final_project/submissions/comp424mcgill/final-project-a_team_name/world.py\", line 310, in step\n    raise ValueError(\nValueError: [INVALID:STEP] Not a valid step from [4 3] to [4 3] and put barrier at 0, with max steps = 4\n\nExecute Random Walk!\nAn exception raised. The traceback is as follows:\nTraceback (most recent call last):\n  File \"/home/ml/users/ksinha4/mlp/comp424_final_project/submissions/comp424mcgill/final-project-a_team_name/world.py\", line 310, in step\n    raise ValueError(\nValueError: [INVALID:STEP] Not a valid step from [4 2] to [4 2] and put barrier at 0, with max steps = 4\n\nExecute Random Walk!\nAn exception raised. The traceback is as follows:\nTraceback (most recent call last):\n  File \"/home/ml/users/ksinha4/mlp/comp424_final_project/submissions/comp424mcgill/final-project-a_team_name/world.py\", line 310, in step\n    raise ValueError(\nValueError: [INVALID:STEP] Not a valid step from [4 3] to [4 3] and put barrier at 0, with max steps = 4\n\nExecute Random Walk!\nAn exception raised. The traceback is as follows:\nTraceback (most recent call last):\n  File \"/home/ml/users/ksinha4/mlp/comp424_final_project/submissions/comp424mcgill/final-project-a_team_name/world.py\", line 310, in step\n    raise ValueError(\nValueError: [INVALID:STEP] Not a valid step from [5 4] to [5 4] and put barrier at 0, with max steps = 4\n\nExecute Random Walk!\nAn exception raised. The traceback is as follows:\nTraceback (most recent call last):\n  File \"/home/ml/users/ksinha4/mlp/comp424_final_project/submissions/comp424mcgill/final-project-a_team_name/world.py\", line 310, in step\n    raise ValueError(\nValueError: [INVALID:STEP] Not a valid step from [6 3] to [6 3] and put barrier at 0, with max steps = 4\n\nExecute Random Walk!\n"}, {"student_agent_score": 1, "random_agent_score": 48, "student_agent_time": 0.003480672836303711, "random_agent_time": 0.003242015838623047, "board_size": 7, "swap_players": true, "run_out": "An exception raised. The traceback is as follows:\nTraceback (most recent call last):\n  File \"/home/ml/users/ksinha4/mlp/comp424_final_project/submissions/comp424mcgill/final-project-a_team_name/world.py\", line 310, in step\n    raise ValueError(\nValueError: [INVALID:STEP] Not a valid step from [2 3] to [2 3] and put barrier at 0, with max steps = 4\n\nExecute Random Walk!\nAn exception raised. The traceback is as follows:\nTraceback (most recent call last):\n  File \"/home/ml/users/ksinha4/mlp/comp424_final_project/submissions/comp424mcgill/final-project-a_team_name/world.py\", line 310, in step\n    raise ValueError(\nValueError: [INVALID:STEP] Not a valid step from [5 4] to [5 4] and put barrier at 0, with max steps = 4\n\nExecute Random Walk!\nAn exception raised. The traceback is as follows:\nTraceback (most recent call last):\n  File \"/home/ml/users/ksinha4/mlp/comp424_final_project/submissions/comp424mcgill/final-project-a_team_name/world.py\", line 310, in step\n    raise ValueError(\nValueError: [INVALID:STEP] Not a valid step from [6 3] to [6 3] and put barrier at 0, with max steps = 4\n\nExecute Random Walk!\n"}, {"student_agent_score": 120, "random_agent_score": 1, "student_agent_time": 0.002056598663330078, "random_agent_time": 0.0033333301544189453, "board_size": 11, "swap_players": true, "run_out": "An exception raised. The traceback is as follows:\nTraceback (most recent call last):\n  File \"/home/ml/users/ksinha4/mlp/comp424_final_project/submissions/comp424mcgill/final-project-a_team_name/world.py\", line 310, in step\n    raise ValueError(\nValueError: [INVALID:STEP] Not a valid step from [9 3] to [9 3] and put barrier at 0, with max steps = 6\n\nExecute Random Walk!\nAn exception raised. The traceback is as follows:\nTraceback (most recent call last):\n  File \"/home/ml/users/ksinha4/mlp/comp424_final_project/submissions/comp424mcgill/final-project-a_team_name/world.py\", line 310, in step\n    raise ValueError(\nValueError: [INVALID:STEP] Not a valid step from [9 3] to [9 3] and put barrier at 0, with max steps = 6\n\nExecute Random Walk!\n"}, {"student_agent_score": 1, "random_agent_score": 48, "student_agent_time": 0.003904581069946289, "random_agent_time": 0.0033004283905029297, "board_size": 7, "swap_players": false, "run_out": "An exception raised. The traceback is as follows:\nTraceback (most recent call last):\n  File \"/home/ml/users/ksinha4/mlp/comp424_final_project/submissions/comp424mcgill/final-project-a_team_name/world.py\", line 310, in step\n    raise ValueError(\nValueError: [INVALID:STEP] Not a valid step from [4 3] to [4 3] and put barrier at 0, with max steps = 4\n\nExecute Random Walk!\nAn exception raised. The traceback is as follows:\nTraceback (most recent call last):\n  File \"/home/ml/users/ksinha4/mlp/comp424_final_project/submissions/comp424mcgill/final-project-a_team_name/world.py\", line 310, in step\n    raise ValueError(\nValueError: [INVALID:STEP] Not a valid step from [4 2] to [4 2] and put barrier at 0, with max steps = 4\n\nExecute Random Walk!\nAn exception raised. The traceback is as follows:\nTraceback (most recent call last):\n  File \"/home/ml/users/ksinha4/mlp/comp424_final_project/submissions/comp424mcgill/final-project-a_team_name/world.py\", line 310, in step\n    raise ValueError(\nValueError: [INVALID:STEP] Not a valid step from [4 3] to [4 3] and put barrier at 0, with max steps = 4\n\nExecute Random Walk!\nAn exception raised. The traceback is as follows:\nTraceback (most recent call last):\n  File \"/home/ml/users/ksinha4/mlp/comp424_final_project/submissions/comp424mcgill/final-project-a_team_name/world.py\", line 310, in step\n    raise ValueError(\nValueError: [INVALID:STEP] Not a valid step from [5 4] to [5 4] and put barrier at 0, with max steps = 4\n\nExecute Random Walk!\nAn exception raised. The traceback is as follows:\nTraceback (most recent call last):\n  File \"/home/ml/users/ksinha4/mlp/comp424_final_project/submissions/comp424mcgill/final-project-a_team_name/world.py\", line 310, in step\n    raise ValueError(\nValueError: [INVALID:STEP] Not a valid step from [6 3] to [6 3] and put barrier at 0, with max steps = 4\n\nExecute Random Walk!\n"}, {"student_agent_score": 117, "random_agent_score": 1, "student_agent_time": 0.007590055465698242, "random_agent_time": 0.007016658782958984, "board_size": 11, "swap_players": false, "run_out": "An exception raised. The traceback is as follows:\nTraceback (most recent call last):\n  File \"/home/ml/users/ksinha4/mlp/comp424_final_project/submissions/comp424mcgill/final-project-a_team_name/world.py\", line 310, in step\n    raise ValueError(\nValueError: [INVALID:STEP] Not a valid step from [1 7] to [1 7] and put barrier at 0, with max steps = 6\n\nExecute Random Walk!\nAn exception raised. The traceback is as follows:\nTraceback (most recent call last):\n  File \"/home/ml/users/ksinha4/mlp/comp424_final_project/submissions/comp424mcgill/final-project-a_team_name/world.py\", line 310, in step\n    raise ValueError(\nValueError: [INVALID:STEP] Not a valid step from [1 8] to [1 8] and put barrier at 0, with max steps = 6\n\nExecute Random Walk!\nAn exception raised. The traceback is as follows:\nTraceback (most recent call last):\n  File \"/home/ml/users/ksinha4/mlp/comp424_final_project/submissions/comp424mcgill/final-project-a_team_name/world.py\", line 310, in step\n    raise ValueError(\nValueError: [INVALID:STEP] Not a valid step from [1 6] to [1 6] and put barrier at 0, with max steps = 6\n\nExecute Random Walk!\nAn exception raised. The traceback is as follows:\nTraceback (most recent call last):\n  File \"/home/ml/users/ksinha4/mlp/comp424_final_project/submissions/comp424mcgill/final-project-a_team_name/world.py\", line 310, in step\n    raise ValueError(\nValueError: [INVALID:STEP] Not a valid step from [3 3] to [3 3] and put barrier at 0, with max steps = 6\n\nExecute Random Walk!\nAn exception raised. The traceback is as follows:\nTraceback (most recent call last):\n  File \"/home/ml/users/ksinha4/mlp/comp424_final_project/submissions/comp424mcgill/final-project-a_team_name/world.py\", line 310, in step\n    raise ValueError(\nValueError: [INVALID:STEP] Not a valid step from [3 4] to [3 4] and put barrier at 0, with max steps = 6\n\nExecute Random Walk!\nAn exception raised. The traceback is as follows:\nTraceback (most recent call last):\n  File \"/home/ml/users/ksinha4/mlp/comp424_final_project/submissions/comp424mcgill/final-project-a_team_name/world.py\", line 310, in step\n    raise ValueError(\nValueError: [INVALID:STEP] Not a valid step from [3 4] to [3 4] and put barrier at 0, with max steps = 6\n\nExecute Random Walk!\nAn exception raised. The traceback is as follows:\nTraceback (most recent call last):\n  File \"/home/ml/users/ksinha4/mlp/comp424_final_project/submissions/comp424mcgill/final-project-a_team_name/world.py\", line 310, in step\n    raise ValueError(\nValueError: [INVALID:STEP] Not a valid step from [4 4] to [4 4] and put barrier at 0, with max steps = 6\n\nExecute Random Walk!\nAn exception raised. The traceback is as follows:\nTraceback (most recent call last):\n  File \"/home/ml/users/ksinha4/mlp/comp424_final_project/submissions/comp424mcgill/final-project-a_team_name/world.py\", line 310, in step\n    raise ValueError(\nValueError: [INVALID:STEP] Not a valid step from [4 4] to [4 4] and put barrier at 0, with max steps = 6\n\nExecute Random Walk!\n"}, {"student_agent_score": 1, "random_agent_score": 63, "student_agent_time": 0.006918430328369141, "random_agent_time": 0.0031654834747314453, "board_size": 8, "swap_players": false, "run_out": "An exception raised. The traceback is as follows:\nTraceback (most recent call last):\n  File \"/home/ml/users/ksinha4/mlp/comp424_final_project/submissions/comp424mcgill/final-project-a_team_name/world.py\", line 310, in step\n    raise ValueError(\nValueError: [INVALID:STEP] Not a valid step from [2 2] to [2 2] and put barrier at 0, with max steps = 4\n\nExecute Random Walk!\nAn exception raised. The traceback is as follows:\nTraceback (most recent call last):\n  File \"/home/ml/users/ksinha4/mlp/comp424_final_project/submissions/comp424mcgill/final-project-a_team_name/world.py\", line 310, in step\n    raise ValueError(\nValueError: [INVALID:STEP] Not a valid step from [3 1] to [3 1] and put barrier at 0, with max steps = 4\n\nExecute Random Walk!\nAn exception raised. The traceback is as follows:\nTraceback (most recent call last):\n  File \"/home/ml/users/ksinha4/mlp/comp424_final_project/submissions/comp424mcgill/final-project-a_team_name/world.py\", line 310, in step\n    raise ValueError(\nValueError: [INVALID:STEP] Not a valid step from [3 0] to [3 0] and put barrier at 0, with max steps = 4\n\nExecute Random Walk!\nAn exception raised. The traceback is as follows:\nTraceback (most recent call last):\n  File \"/home/ml/users/ksinha4/mlp/comp424_final_project/submissions/comp424mcgill/final-project-a_team_name/world.py\", line 310, in step\n    raise ValueError(\nValueError: [INVALID:STEP] Not a valid step from [6 1] to [6 1] and put barrier at 0, with max steps = 4\n\nExecute Random Walk!\n"}, {"student_agent_score": 1, "random_agent_score": 48, "student_agent_time": 0.002923250198364258, "random_agent_time": 0.00522160530090332, "board_size": 7, "swap_players": true, "run_out": "An exception raised. The traceback is as follows:\nTraceback (most recent call last):\n  File \"/home/ml/users/ksinha4/mlp/comp424_final_project/submissions/comp424mcgill/final-project-a_team_name/world.py\", line 310, in step\n    raise ValueError(\nValueError: [INVALID:STEP] Not a valid step from [2 3] to [2 3] and put barrier at 0, with max steps = 4\n\nExecute Random Walk!\nAn exception raised. The traceback is as follows:\nTraceback (most recent call last):\n  File \"/home/ml/users/ksinha4/mlp/comp424_final_project/submissions/comp424mcgill/final-project-a_team_name/world.py\", line 310, in step\n    raise ValueError(\nValueError: [INVALID:STEP] Not a valid step from [5 4] to [5 4] and put barrier at 0, with max steps = 4\n\nExecute Random Walk!\nAn exception raised. The traceback is as follows:\nTraceback (most recent call last):\n  File \"/home/ml/users/ksinha4/mlp/comp424_final_project/submissions/comp424mcgill/final-project-a_team_name/world.py\", line 310, in step\n    raise ValueError(\nValueError: [INVALID:STEP] Not a valid step from [6 3] to [6 3] and put barrier at 0, with max steps = 4\n\nExecute Random Walk!\n"}, {"student_agent_score": 1, "random_agent_score": 48, "student_agent_time": 0.0028238296508789062, "random_agent_time": 0.0051653385162353516, "board_size": 7, "swap_players": true, "run_out": "An exception raised. The traceback is as follows:\nTraceback (most recent call last):\n  File \"/home/ml/users/ksinha4/mlp/comp424_final_project/submissions/comp424mcgill/final-project-a_team_name/world.py\", line 310, in step\n    raise ValueError(\nValueError: [INVALID:STEP] Not a valid step from [2 3] to [2 3] and put barrier at 0, with max steps = 4\n\nExecute Random Walk!\nAn exception raised. The traceback is as follows:\nTraceback (most recent call last):\n  File \"/home/ml/users/ksinha4/mlp/comp424_final_project/submissions/comp424mcgill/final-project-a_team_name/world.py\", line 310, in step\n    raise ValueError(\nValueError: [INVALID:STEP] Not a valid step from [5 4] to [5 4] and put barrier at 0, with max steps = 4\n\nExecute Random Walk!\nAn exception raised. The traceback is as follows:\nTraceback (most recent call last):\n  File \"/home/ml/users/ksinha4/mlp/comp424_final_project/submissions/comp424mcgill/final-project-a_team_name/world.py\", line 310, in step\n    raise ValueError(\nValueError: [INVALID:STEP] Not a valid step from [6 3] to [6 3] and put barrier at 0, with max steps = 4\n\nExecute Random Walk!\n"}, {"student_agent_score": 2, "random_agent_score": 79, "student_agent_time": 0.0034508705139160156, "random_agent_time": 0.0030019283294677734, "board_size": 9, "swap_players": false, "run_out": "An exception raised. The traceback is as follows:\nTraceback (most recent call last):\n  File \"/home/ml/users/ksinha4/mlp/comp424_final_project/submissions/comp424mcgill/final-project-a_team_name/world.py\", line 310, in step\n    raise ValueError(\nValueError: [INVALID:STEP] Not a valid step from [5 4] to [5 4] and put barrier at 0, with max steps = 5\n\nExecute Random Walk!\nAn exception raised. The traceback is as follows:\nTraceback (most recent call last):\n  File \"/home/ml/users/ksinha4/mlp/comp424_final_project/submissions/comp424mcgill/final-project-a_team_name/world.py\", line 310, in step\n    raise ValueError(\nValueError: [INVALID:STEP] Not a valid step from [5 3] to [5 3] and put barrier at 0, with max steps = 5\n\nExecute Random Walk!\n"}, {"student_agent_score": 1, "random_agent_score": 35, "student_agent_time": 0.0019037723541259766, "random_agent_time": 0.0014605522155761719, "board_size": 6, "swap_players": false, "run_out": "An exception raised. The traceback is as follows:\nTraceback (most recent call last):\n  File \"/home/ml/users/ksinha4/mlp/comp424_final_project/submissions/comp424mcgill/final-project-a_team_name/world.py\", line 310, in step\n    raise ValueError(\nValueError: [INVALID:STEP] Not a valid step from [2 2] to [2 2] and put barrier at 0, with max steps = 3\n\nExecute Random Walk!\nAn exception raised. The traceback is as follows:\nTraceback (most recent call last):\n  File \"/home/ml/users/ksinha4/mlp/comp424_final_project/submissions/comp424mcgill/final-project-a_team_name/world.py\", line 310, in step\n    raise ValueError(\nValueError: [INVALID:STEP] Not a valid step from [3 0] to [3 0] and put barrier at 0, with max steps = 3\n\nExecute Random Walk!\n"}, {"student_agent_score": 99, "random_agent_score": 1, "student_agent_time": 0.0003275871276855469, "random_agent_time": 0.0016057491302490234, "board_size": 10, "swap_players": true, "run_out": ""}, {"student_agent_score": 1, "random_agent_score": 48, "student_agent_time": 0.0032854080200195312, "random_agent_time": 0.0026578903198242188, "board_size": 7, "swap_players": true, "run_out": "An exception raised. The traceback is as follows:\nTraceback (most recent call last):\n  File \"/home/ml/users/ksinha4/mlp/comp424_final_project/submissions/comp424mcgill/final-project-a_team_name/world.py\", line 310, in step\n    raise ValueError(\nValueError: [INVALID:STEP] Not a valid step from [2 3] to [2 3] and put barrier at 0, with max steps = 4\n\nExecute Random Walk!\nAn exception raised. The traceback is as follows:\nTraceback (most recent call last):\n  File \"/home/ml/users/ksinha4/mlp/comp424_final_project/submissions/comp424mcgill/final-project-a_team_name/world.py\", line 310, in step\n    raise ValueError(\nValueError: [INVALID:STEP] Not a valid step from [5 4] to [5 4] and put barrier at 0, with max steps = 4\n\nExecute Random Walk!\nAn exception raised. The traceback is as follows:\nTraceback (most recent call last):\n  File \"/home/ml/users/ksinha4/mlp/comp424_final_project/submissions/comp424mcgill/final-project-a_team_name/world.py\", line 310, in step\n    raise ValueError(\nValueError: [INVALID:STEP] Not a valid step from [6 3] to [6 3] and put barrier at 0, with max steps = 4\n\nExecute Random Walk!\n"}, {"student_agent_score": 1, "random_agent_score": 48, "student_agent_time": 0.005664348602294922, "random_agent_time": 0.002989530563354492, "board_size": 7, "swap_players": false, "run_out": "An exception raised. The traceback is as follows:\nTraceback (most recent call last):\n  File \"/home/ml/users/ksinha4/mlp/comp424_final_project/submissions/comp424mcgill/final-project-a_team_name/world.py\", line 310, in step\n    raise ValueError(\nValueError: [INVALID:STEP] Not a valid step from [4 3] to [4 3] and put barrier at 0, with max steps = 4\n\nExecute Random Walk!\nAn exception raised. The traceback is as follows:\nTraceback (most recent call last):\n  File \"/home/ml/users/ksinha4/mlp/comp424_final_project/submissions/comp424mcgill/final-project-a_team_name/world.py\", line 310, in step\n    raise ValueError(\nValueError: [INVALID:STEP] Not a valid step from [4 2] to [4 2] and put barrier at 0, with max steps = 4\n\nExecute Random Walk!\nAn exception raised. The traceback is as follows:\nTraceback (most recent call last):\n  File \"/home/ml/users/ksinha4/mlp/comp424_final_project/submissions/comp424mcgill/final-project-a_team_name/world.py\", line 310, in step\n    raise ValueError(\nValueError: [INVALID:STEP] Not a valid step from [4 3] to [4 3] and put barrier at 0, with max steps = 4\n\nExecute Random Walk!\nAn exception raised. The traceback is as follows:\nTraceback (most recent call last):\n  File \"/home/ml/users/ksinha4/mlp/comp424_final_project/submissions/comp424mcgill/final-project-a_team_name/world.py\", line 310, in step\n    raise ValueError(\nValueError: [INVALID:STEP] Not a valid step from [5 4] to [5 4] and put barrier at 0, with max steps = 4\n\nExecute Random Walk!\nAn exception raised. The traceback is as follows:\nTraceback (most recent call last):\n  File \"/home/ml/users/ksinha4/mlp/comp424_final_project/submissions/comp424mcgill/final-project-a_team_name/world.py\", line 310, in step\n    raise ValueError(\nValueError: [INVALID:STEP] Not a valid step from [6 3] to [6 3] and put barrier at 0, with max steps = 4\n\nExecute Random Walk!\n"}, {"student_agent_score": 63, "random_agent_score": 1, "student_agent_time": 0.0031125545501708984, "random_agent_time": 0.0026514530181884766, "board_size": 8, "swap_players": true, "run_out": "An exception raised. The traceback is as follows:\nTraceback (most recent call last):\n  File \"/home/ml/users/ksinha4/mlp/comp424_final_project/submissions/comp424mcgill/final-project-a_team_name/world.py\", line 310, in step\n    raise ValueError(\nValueError: [INVALID:STEP] Not a valid step from [5 5] to [5 5] and put barrier at 0, with max steps = 4\n\nExecute Random Walk!\nAn exception raised. The traceback is as follows:\nTraceback (most recent call last):\n  File \"/home/ml/users/ksinha4/mlp/comp424_final_project/submissions/comp424mcgill/final-project-a_team_name/world.py\", line 310, in step\n    raise ValueError(\nValueError: [INVALID:STEP] Not a valid step from [5 4] to [5 4] and put barrier at 0, with max steps = 4\n\nExecute Random Walk!\nAn exception raised. The traceback is as follows:\nTraceback (most recent call last):\n  File \"/home/ml/users/ksinha4/mlp/comp424_final_project/submissions/comp424mcgill/final-project-a_team_name/world.py\", line 310, in step\n    raise ValueError(\nValueError: [INVALID:STEP] Not a valid step from [5 4] to [5 4] and put barrier at 0, with max steps = 4\n\nExecute Random Walk!\n"}, {"student_agent_score": 120, "random_agent_score": 1, "student_agent_time": 0.003034353256225586, "random_agent_time": 0.003103494644165039, "board_size": 11, "swap_players": true, "run_out": "An exception raised. The traceback is as follows:\nTraceback (most recent call last):\n  File \"/home/ml/users/ksinha4/mlp/comp424_final_project/submissions/comp424mcgill/final-project-a_team_name/world.py\", line 310, in step\n    raise ValueError(\nValueError: [INVALID:STEP] Not a valid step from [9 3] to [9 3] and put barrier at 0, with max steps = 6\n\nExecute Random Walk!\nAn exception raised. The traceback is as follows:\nTraceback (most recent call last):\n  File \"/home/ml/users/ksinha4/mlp/comp424_final_project/submissions/comp424mcgill/final-project-a_team_name/world.py\", line 310, in step\n    raise ValueError(\nValueError: [INVALID:STEP] Not a valid step from [9 3] to [9 3] and put barrier at 0, with max steps = 6\n\nExecute Random Walk!\n"}, {"student_agent_score": 1, "random_agent_score": 48, "student_agent_time": 0.0027625560760498047, "random_agent_time": 0.0030329227447509766, "board_size": 7, "swap_players": true, "run_out": "An exception raised. The traceback is as follows:\nTraceback (most recent call last):\n  File \"/home/ml/users/ksinha4/mlp/comp424_final_project/submissions/comp424mcgill/final-project-a_team_name/world.py\", line 310, in step\n    raise ValueError(\nValueError: [INVALID:STEP] Not a valid step from [2 3] to [2 3] and put barrier at 0, with max steps = 4\n\nExecute Random Walk!\nAn exception raised. The traceback is as follows:\nTraceback (most recent call last):\n  File \"/home/ml/users/ksinha4/mlp/comp424_final_project/submissions/comp424mcgill/final-project-a_team_name/world.py\", line 310, in step\n    raise ValueError(\nValueError: [INVALID:STEP] Not a valid step from [5 4] to [5 4] and put barrier at 0, with max steps = 4\n\nExecute Random Walk!\nAn exception raised. The traceback is as follows:\nTraceback (most recent call last):\n  File \"/home/ml/users/ksinha4/mlp/comp424_final_project/submissions/comp424mcgill/final-project-a_team_name/world.py\", line 310, in step\n    raise ValueError(\nValueError: [INVALID:STEP] Not a valid step from [6 3] to [6 3] and put barrier at 0, with max steps = 4\n\nExecute Random Walk!\n"}, {"student_agent_score": 1, "random_agent_score": 48, "student_agent_time": 0.003825664520263672, "random_agent_time": 0.0019681453704833984, "board_size": 7, "swap_players": false, "run_out": "An exception raised. The traceback is as follows:\nTraceback (most recent call last):\n  File \"/home/ml/users/ksinha4/mlp/comp424_final_project/submissions/comp424mcgill/final-project-a_team_name/world.py\", line 310, in step\n    raise ValueError(\nValueError: [INVALID:STEP] Not a valid step from [4 3] to [4 3] and put barrier at 0, with max steps = 4\n\nExecute Random Walk!\nAn exception raised. The traceback is as follows:\nTraceback (most recent call last):\n  File \"/home/ml/users/ksinha4/mlp/comp424_final_project/submissions/comp424mcgill/final-project-a_team_name/world.py\", line 310, in step\n    raise ValueError(\nValueError: [INVALID:STEP] Not a valid step from [4 2] to [4 2] and put barrier at 0, with max steps = 4\n\nExecute Random Walk!\nAn exception raised. The traceback is as follows:\nTraceback (most recent call last):\n  File \"/home/ml/users/ksinha4/mlp/comp424_final_project/submissions/comp424mcgill/final-project-a_team_name/world.py\", line 310, in step\n    raise ValueError(\nValueError: [INVALID:STEP] Not a valid step from [4 3] to [4 3] and put barrier at 0, with max steps = 4\n\nExecute Random Walk!\nAn exception raised. The traceback is as follows:\nTraceback (most recent call last):\n  File \"/home/ml/users/ksinha4/mlp/comp424_final_project/submissions/comp424mcgill/final-project-a_team_name/world.py\", line 310, in step\n    raise ValueError(\nValueError: [INVALID:STEP] Not a valid step from [5 4] to [5 4] and put barrier at 0, with max steps = 4\n\nExecute Random Walk!\nAn exception raised. The traceback is as follows:\nTraceback (most recent call last):\n  File \"/home/ml/users/ksinha4/mlp/comp424_final_project/submissions/comp424mcgill/final-project-a_team_name/world.py\", line 310, in step\n    raise ValueError(\nValueError: [INVALID:STEP] Not a valid step from [6 3] to [6 3] and put barrier at 0, with max steps = 4\n\nExecute Random Walk!\n"}, {"student_agent_score": 1, "random_agent_score": 48, "student_agent_time": 0.004967689514160156, "random_agent_time": 0.003823995590209961, "board_size": 7, "swap_players": true, "run_out": "An exception raised. The traceback is as follows:\nTraceback (most recent call last):\n  File \"/home/ml/users/ksinha4/mlp/comp424_final_project/submissions/comp424mcgill/final-project-a_team_name/world.py\", line 310, in step\n    raise ValueError(\nValueError: [INVALID:STEP] Not a valid step from [2 3] to [2 3] and put barrier at 0, with max steps = 4\n\nExecute Random Walk!\nAn exception raised. The traceback is as follows:\nTraceback (most recent call last):\n  File \"/home/ml/users/ksinha4/mlp/comp424_final_project/submissions/comp424mcgill/final-project-a_team_name/world.py\", line 310, in step\n    raise ValueError(\nValueError: [INVALID:STEP] Not a valid step from [5 4] to [5 4] and put barrier at 0, with max steps = 4\n\nExecute Random Walk!\nAn exception raised. The traceback is as follows:\nTraceback (most recent call last):\n  File \"/home/ml/users/ksinha4/mlp/comp424_final_project/submissions/comp424mcgill/final-project-a_team_name/world.py\", line 310, in step\n    raise ValueError(\nValueError: [INVALID:STEP] Not a valid step from [6 3] to [6 3] and put barrier at 0, with max steps = 4\n\nExecute Random Walk!\n"}, {"student_agent_score": 120, "random_agent_score": 1, "student_agent_time": 0.0033578872680664062, "random_agent_time": 0.003485441207885742, "board_size": 11, "swap_players": true, "run_out": "An exception raised. The traceback is as follows:\nTraceback (most recent call last):\n  File \"/home/ml/users/ksinha4/mlp/comp424_final_project/submissions/comp424mcgill/final-project-a_team_name/world.py\", line 310, in step\n    raise ValueError(\nValueError: [INVALID:STEP] Not a valid step from [9 3] to [9 3] and put barrier at 0, with max steps = 6\n\nExecute Random Walk!\nAn exception raised. The traceback is as follows:\nTraceback (most recent call last):\n  File \"/home/ml/users/ksinha4/mlp/comp424_final_project/submissions/comp424mcgill/final-project-a_team_name/world.py\", line 310, in step\n    raise ValueError(\nValueError: [INVALID:STEP] Not a valid step from [9 3] to [9 3] and put barrier at 0, with max steps = 6\n\nExecute Random Walk!\n"}, {"student_agent_score": 2, "random_agent_score": 98, "student_agent_time": 0.0043604373931884766, "random_agent_time": 0.0061359405517578125, "board_size": 10, "swap_players": false, "run_out": "An exception raised. The traceback is as follows:\nTraceback (most recent call last):\n  File \"/home/ml/users/ksinha4/mlp/comp424_final_project/submissions/comp424mcgill/final-project-a_team_name/world.py\", line 310, in step\n    raise ValueError(\nValueError: [INVALID:STEP] Not a valid step from [7 5] to [7 5] and put barrier at 0, with max steps = 5\n\nExecute Random Walk!\nAn exception raised. The traceback is as follows:\nTraceback (most recent call last):\n  File \"/home/ml/users/ksinha4/mlp/comp424_final_project/submissions/comp424mcgill/final-project-a_team_name/world.py\", line 310, in step\n    raise ValueError(\nValueError: [INVALID:STEP] Not a valid step from [6 6] to [6 6] and put barrier at 0, with max steps = 5\n\nExecute Random Walk!\nAn exception raised. The traceback is as follows:\nTraceback (most recent call last):\n  File \"/home/ml/users/ksinha4/mlp/comp424_final_project/submissions/comp424mcgill/final-project-a_team_name/world.py\", line 310, in step\n    raise ValueError(\nValueError: [INVALID:STEP] Not a valid step from [7 8] to [7 8] and put barrier at 0, with max steps = 5\n\nExecute Random Walk!\nAn exception raised. The traceback is as follows:\nTraceback (most recent call last):\n  File \"/home/ml/users/ksinha4/mlp/comp424_final_project/submissions/comp424mcgill/final-project-a_team_name/world.py\", line 310, in step\n    raise ValueError(\nValueError: [INVALID:STEP] Not a valid step from [7 8] to [7 8] and put barrier at 0, with max steps = 5\n\nExecute Random Walk!\n"}, {"student_agent_score": 2, "random_agent_score": 79, "student_agent_time": 0.003056049346923828, "random_agent_time": 0.002933025360107422, "board_size": 9, "swap_players": false, "run_out": "An exception raised. The traceback is as follows:\nTraceback (most recent call last):\n  File \"/home/ml/users/ksinha4/mlp/comp424_final_project/submissions/comp424mcgill/final-project-a_team_name/world.py\", line 310, in step\n    raise ValueError(\nValueError: [INVALID:STEP] Not a valid step from [5 4] to [5 4] and put barrier at 0, with max steps = 5\n\nExecute Random Walk!\nAn exception raised. The traceback is as follows:\nTraceback (most recent call last):\n  File \"/home/ml/users/ksinha4/mlp/comp424_final_project/submissions/comp424mcgill/final-project-a_team_name/world.py\", line 310, in step\n    raise ValueError(\nValueError: [INVALID:STEP] Not a valid step from [5 3] to [5 3] and put barrier at 0, with max steps = 5\n\nExecute Random Walk!\n"}, {"student_agent_score": 1, "random_agent_score": 48, "student_agent_time": 0.002885580062866211, "random_agent_time": 0.003473043441772461, "board_size": 7, "swap_players": true, "run_out": "An exception raised. The traceback is as follows:\nTraceback (most recent call last):\n  File \"/home/ml/users/ksinha4/mlp/comp424_final_project/submissions/comp424mcgill/final-project-a_team_name/world.py\", line 310, in step\n    raise ValueError(\nValueError: [INVALID:STEP] Not a valid step from [2 3] to [2 3] and put barrier at 0, with max steps = 4\n\nExecute Random Walk!\nAn exception raised. The traceback is as follows:\nTraceback (most recent call last):\n  File \"/home/ml/users/ksinha4/mlp/comp424_final_project/submissions/comp424mcgill/final-project-a_team_name/world.py\", line 310, in step\n    raise ValueError(\nValueError: [INVALID:STEP] Not a valid step from [5 4] to [5 4] and put barrier at 0, with max steps = 4\n\nExecute Random Walk!\nAn exception raised. The traceback is as follows:\nTraceback (most recent call last):\n  File \"/home/ml/users/ksinha4/mlp/comp424_final_project/submissions/comp424mcgill/final-project-a_team_name/world.py\", line 310, in step\n    raise ValueError(\nValueError: [INVALID:STEP] Not a valid step from [6 3] to [6 3] and put barrier at 0, with max steps = 4\n\nExecute Random Walk!\n"}, {"student_agent_score": 1, "random_agent_score": 48, "student_agent_time": 0.003426074981689453, "random_agent_time": 0.002565145492553711, "board_size": 7, "swap_players": false, "run_out": "An exception raised. The traceback is as follows:\nTraceback (most recent call last):\n  File \"/home/ml/users/ksinha4/mlp/comp424_final_project/submissions/comp424mcgill/final-project-a_team_name/world.py\", line 310, in step\n    raise ValueError(\nValueError: [INVALID:STEP] Not a valid step from [4 3] to [4 3] and put barrier at 0, with max steps = 4\n\nExecute Random Walk!\nAn exception raised. The traceback is as follows:\nTraceback (most recent call last):\n  File \"/home/ml/users/ksinha4/mlp/comp424_final_project/submissions/comp424mcgill/final-project-a_team_name/world.py\", line 310, in step\n    raise ValueError(\nValueError: [INVALID:STEP] Not a valid step from [4 2] to [4 2] and put barrier at 0, with max steps = 4\n\nExecute Random Walk!\nAn exception raised. The traceback is as follows:\nTraceback (most recent call last):\n  File \"/home/ml/users/ksinha4/mlp/comp424_final_project/submissions/comp424mcgill/final-project-a_team_name/world.py\", line 310, in step\n    raise ValueError(\nValueError: [INVALID:STEP] Not a valid step from [4 3] to [4 3] and put barrier at 0, with max steps = 4\n\nExecute Random Walk!\nAn exception raised. The traceback is as follows:\nTraceback (most recent call last):\n  File \"/home/ml/users/ksinha4/mlp/comp424_final_project/submissions/comp424mcgill/final-project-a_team_name/world.py\", line 310, in step\n    raise ValueError(\nValueError: [INVALID:STEP] Not a valid step from [5 4] to [5 4] and put barrier at 0, with max steps = 4\n\nExecute Random Walk!\nAn exception raised. The traceback is as follows:\nTraceback (most recent call last):\n  File \"/home/ml/users/ksinha4/mlp/comp424_final_project/submissions/comp424mcgill/final-project-a_team_name/world.py\", line 310, in step\n    raise ValueError(\nValueError: [INVALID:STEP] Not a valid step from [6 3] to [6 3] and put barrier at 0, with max steps = 4\n\nExecute Random Walk!\n"}, {"student_agent_score": 1, "random_agent_score": 48, "student_agent_time": 0.0031332969665527344, "random_agent_time": 0.0025746822357177734, "board_size": 7, "swap_players": true, "run_out": "An exception raised. The traceback is as follows:\nTraceback (most recent call last):\n  File \"/home/ml/users/ksinha4/mlp/comp424_final_project/submissions/comp424mcgill/final-project-a_team_name/world.py\", line 310, in step\n    raise ValueError(\nValueError: [INVALID:STEP] Not a valid step from [2 3] to [2 3] and put barrier at 0, with max steps = 4\n\nExecute Random Walk!\nAn exception raised. The traceback is as follows:\nTraceback (most recent call last):\n  File \"/home/ml/users/ksinha4/mlp/comp424_final_project/submissions/comp424mcgill/final-project-a_team_name/world.py\", line 310, in step\n    raise ValueError(\nValueError: [INVALID:STEP] Not a valid step from [5 4] to [5 4] and put barrier at 0, with max steps = 4\n\nExecute Random Walk!\nAn exception raised. The traceback is as follows:\nTraceback (most recent call last):\n  File \"/home/ml/users/ksinha4/mlp/comp424_final_project/submissions/comp424mcgill/final-project-a_team_name/world.py\", line 310, in step\n    raise ValueError(\nValueError: [INVALID:STEP] Not a valid step from [6 3] to [6 3] and put barrier at 0, with max steps = 4\n\nExecute Random Walk!\n"}, {"student_agent_score": 1, "random_agent_score": 63, "student_agent_time": 0.0031948089599609375, "random_agent_time": 0.002592802047729492, "board_size": 8, "swap_players": false, "run_out": "An exception raised. The traceback is as follows:\nTraceback (most recent call last):\n  File \"/home/ml/users/ksinha4/mlp/comp424_final_project/submissions/comp424mcgill/final-project-a_team_name/world.py\", line 310, in step\n    raise ValueError(\nValueError: [INVALID:STEP] Not a valid step from [2 2] to [2 2] and put barrier at 0, with max steps = 4\n\nExecute Random Walk!\nAn exception raised. The traceback is as follows:\nTraceback (most recent call last):\n  File \"/home/ml/users/ksinha4/mlp/comp424_final_project/submissions/comp424mcgill/final-project-a_team_name/world.py\", line 310, in step\n    raise ValueError(\nValueError: [INVALID:STEP] Not a valid step from [3 1] to [3 1] and put barrier at 0, with max steps = 4\n\nExecute Random Walk!\nAn exception raised. The traceback is as follows:\nTraceback (most recent call last):\n  File \"/home/ml/users/ksinha4/mlp/comp424_final_project/submissions/comp424mcgill/final-project-a_team_name/world.py\", line 310, in step\n    raise ValueError(\nValueError: [INVALID:STEP] Not a valid step from [3 0] to [3 0] and put barrier at 0, with max steps = 4\n\nExecute Random Walk!\nAn exception raised. The traceback is as follows:\nTraceback (most recent call last):\n  File \"/home/ml/users/ksinha4/mlp/comp424_final_project/submissions/comp424mcgill/final-project-a_team_name/world.py\", line 310, in step\n    raise ValueError(\nValueError: [INVALID:STEP] Not a valid step from [6 1] to [6 1] and put barrier at 0, with max steps = 4\n\nExecute Random Walk!\n"}, {"student_agent_score": 1, "random_agent_score": 48, "student_agent_time": 0.003417491912841797, "random_agent_time": 0.0026597976684570312, "board_size": 7, "swap_players": true, "run_out": "An exception raised. The traceback is as follows:\nTraceback (most recent call last):\n  File \"/home/ml/users/ksinha4/mlp/comp424_final_project/submissions/comp424mcgill/final-project-a_team_name/world.py\", line 310, in step\n    raise ValueError(\nValueError: [INVALID:STEP] Not a valid step from [2 3] to [2 3] and put barrier at 0, with max steps = 4\n\nExecute Random Walk!\nAn exception raised. The traceback is as follows:\nTraceback (most recent call last):\n  File \"/home/ml/users/ksinha4/mlp/comp424_final_project/submissions/comp424mcgill/final-project-a_team_name/world.py\", line 310, in step\n    raise ValueError(\nValueError: [INVALID:STEP] Not a valid step from [5 4] to [5 4] and put barrier at 0, with max steps = 4\n\nExecute Random Walk!\nAn exception raised. The traceback is as follows:\nTraceback (most recent call last):\n  File \"/home/ml/users/ksinha4/mlp/comp424_final_project/submissions/comp424mcgill/final-project-a_team_name/world.py\", line 310, in step\n    raise ValueError(\nValueError: [INVALID:STEP] Not a valid step from [6 3] to [6 3] and put barrier at 0, with max steps = 4\n\nExecute Random Walk!\n"}, {"student_agent_score": 117, "random_agent_score": 1, "student_agent_time": 0.008563041687011719, "random_agent_time": 0.008887529373168945, "board_size": 11, "swap_players": false, "run_out": "An exception raised. The traceback is as follows:\nTraceback (most recent call last):\n  File \"/home/ml/users/ksinha4/mlp/comp424_final_project/submissions/comp424mcgill/final-project-a_team_name/world.py\", line 310, in step\n    raise ValueError(\nValueError: [INVALID:STEP] Not a valid step from [1 7] to [1 7] and put barrier at 0, with max steps = 6\n\nExecute Random Walk!\nAn exception raised. The traceback is as follows:\nTraceback (most recent call last):\n  File \"/home/ml/users/ksinha4/mlp/comp424_final_project/submissions/comp424mcgill/final-project-a_team_name/world.py\", line 310, in step\n    raise ValueError(\nValueError: [INVALID:STEP] Not a valid step from [1 8] to [1 8] and put barrier at 0, with max steps = 6\n\nExecute Random Walk!\nAn exception raised. The traceback is as follows:\nTraceback (most recent call last):\n  File \"/home/ml/users/ksinha4/mlp/comp424_final_project/submissions/comp424mcgill/final-project-a_team_name/world.py\", line 310, in step\n    raise ValueError(\nValueError: [INVALID:STEP] Not a valid step from [1 6] to [1 6] and put barrier at 0, with max steps = 6\n\nExecute Random Walk!\nAn exception raised. The traceback is as follows:\nTraceback (most recent call last):\n  File \"/home/ml/users/ksinha4/mlp/comp424_final_project/submissions/comp424mcgill/final-project-a_team_name/world.py\", line 310, in step\n    raise ValueError(\nValueError: [INVALID:STEP] Not a valid step from [3 3] to [3 3] and put barrier at 0, with max steps = 6\n\nExecute Random Walk!\nAn exception raised. The traceback is as follows:\nTraceback (most recent call last):\n  File \"/home/ml/users/ksinha4/mlp/comp424_final_project/submissions/comp424mcgill/final-project-a_team_name/world.py\", line 310, in step\n    raise ValueError(\nValueError: [INVALID:STEP] Not a valid step from [3 4] to [3 4] and put barrier at 0, with max steps = 6\n\nExecute Random Walk!\nAn exception raised. The traceback is as follows:\nTraceback (most recent call last):\n  File \"/home/ml/users/ksinha4/mlp/comp424_final_project/submissions/comp424mcgill/final-project-a_team_name/world.py\", line 310, in step\n    raise ValueError(\nValueError: [INVALID:STEP] Not a valid step from [3 4] to [3 4] and put barrier at 0, with max steps = 6\n\nExecute Random Walk!\nAn exception raised. The traceback is as follows:\nTraceback (most recent call last):\n  File \"/home/ml/users/ksinha4/mlp/comp424_final_project/submissions/comp424mcgill/final-project-a_team_name/world.py\", line 310, in step\n    raise ValueError(\nValueError: [INVALID:STEP] Not a valid step from [4 4] to [4 4] and put barrier at 0, with max steps = 6\n\nExecute Random Walk!\nAn exception raised. The traceback is as follows:\nTraceback (most recent call last):\n  File \"/home/ml/users/ksinha4/mlp/comp424_final_project/submissions/comp424mcgill/final-project-a_team_name/world.py\", line 310, in step\n    raise ValueError(\nValueError: [INVALID:STEP] Not a valid step from [4 4] to [4 4] and put barrier at 0, with max steps = 6\n\nExecute Random Walk!\n"}, {"student_agent_score": 1, "random_agent_score": 48, "student_agent_time": 0.0022275447845458984, "random_agent_time": 0.003926753997802734, "board_size": 7, "swap_players": true, "run_out": "An exception raised. The traceback is as follows:\nTraceback (most recent call last):\n  File \"/home/ml/users/ksinha4/mlp/comp424_final_project/submissions/comp424mcgill/final-project-a_team_name/world.py\", line 310, in step\n    raise ValueError(\nValueError: [INVALID:STEP] Not a valid step from [2 3] to [2 3] and put barrier at 0, with max steps = 4\n\nExecute Random Walk!\nAn exception raised. The traceback is as follows:\nTraceback (most recent call last):\n  File \"/home/ml/users/ksinha4/mlp/comp424_final_project/submissions/comp424mcgill/final-project-a_team_name/world.py\", line 310, in step\n    raise ValueError(\nValueError: [INVALID:STEP] Not a valid step from [5 4] to [5 4] and put barrier at 0, with max steps = 4\n\nExecute Random Walk!\nAn exception raised. The traceback is as follows:\nTraceback (most recent call last):\n  File \"/home/ml/users/ksinha4/mlp/comp424_final_project/submissions/comp424mcgill/final-project-a_team_name/world.py\", line 310, in step\n    raise ValueError(\nValueError: [INVALID:STEP] Not a valid step from [6 3] to [6 3] and put barrier at 0, with max steps = 4\n\nExecute Random Walk!\n"}, {"student_agent_score": 1, "random_agent_score": 48, "student_agent_time": 0.003782987594604492, "random_agent_time": 0.0021011829376220703, "board_size": 7, "swap_players": false, "run_out": "An exception raised. The traceback is as follows:\nTraceback (most recent call last):\n  File \"/home/ml/users/ksinha4/mlp/comp424_final_project/submissions/comp424mcgill/final-project-a_team_name/world.py\", line 310, in step\n    raise ValueError(\nValueError: [INVALID:STEP] Not a valid step from [4 3] to [4 3] and put barrier at 0, with max steps = 4\n\nExecute Random Walk!\nAn exception raised. The traceback is as follows:\nTraceback (most recent call last):\n  File \"/home/ml/users/ksinha4/mlp/comp424_final_project/submissions/comp424mcgill/final-project-a_team_name/world.py\", line 310, in step\n    raise ValueError(\nValueError: [INVALID:STEP] Not a valid step from [4 2] to [4 2] and put barrier at 0, with max steps = 4\n\nExecute Random Walk!\nAn exception raised. The traceback is as follows:\nTraceback (most recent call last):\n  File \"/home/ml/users/ksinha4/mlp/comp424_final_project/submissions/comp424mcgill/final-project-a_team_name/world.py\", line 310, in step\n    raise ValueError(\nValueError: [INVALID:STEP] Not a valid step from [4 3] to [4 3] and put barrier at 0, with max steps = 4\n\nExecute Random Walk!\nAn exception raised. The traceback is as follows:\nTraceback (most recent call last):\n  File \"/home/ml/users/ksinha4/mlp/comp424_final_project/submissions/comp424mcgill/final-project-a_team_name/world.py\", line 310, in step\n    raise ValueError(\nValueError: [INVALID:STEP] Not a valid step from [5 4] to [5 4] and put barrier at 0, with max steps = 4\n\nExecute Random Walk!\nAn exception raised. The traceback is as follows:\nTraceback (most recent call last):\n  File \"/home/ml/users/ksinha4/mlp/comp424_final_project/submissions/comp424mcgill/final-project-a_team_name/world.py\", line 310, in step\n    raise ValueError(\nValueError: [INVALID:STEP] Not a valid step from [6 3] to [6 3] and put barrier at 0, with max steps = 4\n\nExecute Random Walk!\n"}, {"student_agent_score": 80, "random_agent_score": 1, "student_agent_time": 0.004144906997680664, "random_agent_time": 0.007322788238525391, "board_size": 9, "swap_players": true, "run_out": "An exception raised. The traceback is as follows:\nTraceback (most recent call last):\n  File \"/home/ml/users/ksinha4/mlp/comp424_final_project/submissions/comp424mcgill/final-project-a_team_name/world.py\", line 310, in step\n    raise ValueError(\nValueError: [INVALID:STEP] Not a valid step from [3 4] to [3 4] and put barrier at 0, with max steps = 5\n\nExecute Random Walk!\nAn exception raised. The traceback is as follows:\nTraceback (most recent call last):\n  File \"/home/ml/users/ksinha4/mlp/comp424_final_project/submissions/comp424mcgill/final-project-a_team_name/world.py\", line 310, in step\n    raise ValueError(\nValueError: [INVALID:STEP] Not a valid step from [3 5] to [3 5] and put barrier at 0, with max steps = 5\n\nExecute Random Walk!\nAn exception raised. The traceback is as follows:\nTraceback (most recent call last):\n  File \"/home/ml/users/ksinha4/mlp/comp424_final_project/submissions/comp424mcgill/final-project-a_team_name/world.py\", line 310, in step\n    raise ValueError(\nValueError: [INVALID:STEP] Not a valid step from [3 4] to [3 4] and put barrier at 0, with max steps = 5\n\nExecute Random Walk!\nAn exception raised. The traceback is as follows:\nTraceback (most recent call last):\n  File \"/home/ml/users/ksinha4/mlp/comp424_final_project/submissions/comp424mcgill/final-project-a_team_name/world.py\", line 310, in step\n    raise ValueError(\nValueError: [INVALID:STEP] Not a valid step from [5 4] to [5 4] and put barrier at 0, with max steps = 5\n\nExecute Random Walk!\nAn exception raised. The traceback is as follows:\nTraceback (most recent call last):\n  File \"/home/ml/users/ksinha4/mlp/comp424_final_project/submissions/comp424mcgill/final-project-a_team_name/world.py\", line 310, in step\n    raise ValueError(\nValueError: [INVALID:STEP] Not a valid step from [5 5] to [5 5] and put barrier at 0, with max steps = 5\n\nExecute Random Walk!\n"}, {"student_agent_score": 1, "random_agent_score": 35, "student_agent_time": 0.0016078948974609375, "random_agent_time": 0.0007221698760986328, "board_size": 6, "swap_players": false, "run_out": "An exception raised. The traceback is as follows:\nTraceback (most recent call last):\n  File \"/home/ml/users/ksinha4/mlp/comp424_final_project/submissions/comp424mcgill/final-project-a_team_name/world.py\", line 310, in step\n    raise ValueError(\nValueError: [INVALID:STEP] Not a valid step from [2 2] to [2 2] and put barrier at 0, with max steps = 3\n\nExecute Random Walk!\nAn exception raised. The traceback is as follows:\nTraceback (most recent call last):\n  File \"/home/ml/users/ksinha4/mlp/comp424_final_project/submissions/comp424mcgill/final-project-a_team_name/world.py\", line 310, in step\n    raise ValueError(\nValueError: [INVALID:STEP] Not a valid step from [3 0] to [3 0] and put barrier at 0, with max steps = 3\n\nExecute Random Walk!\n"}, {"student_agent_score": 1, "random_agent_score": 48, "student_agent_time": 0.003629922866821289, "random_agent_time": 0.003028392791748047, "board_size": 7, "swap_players": true, "run_out": "An exception raised. The traceback is as follows:\nTraceback (most recent call last):\n  File \"/home/ml/users/ksinha4/mlp/comp424_final_project/submissions/comp424mcgill/final-project-a_team_name/world.py\", line 310, in step\n    raise ValueError(\nValueError: [INVALID:STEP] Not a valid step from [2 3] to [2 3] and put barrier at 0, with max steps = 4\n\nExecute Random Walk!\nAn exception raised. The traceback is as follows:\nTraceback (most recent call last):\n  File \"/home/ml/users/ksinha4/mlp/comp424_final_project/submissions/comp424mcgill/final-project-a_team_name/world.py\", line 310, in step\n    raise ValueError(\nValueError: [INVALID:STEP] Not a valid step from [5 4] to [5 4] and put barrier at 0, with max steps = 4\n\nExecute Random Walk!\nAn exception raised. The traceback is as follows:\nTraceback (most recent call last):\n  File \"/home/ml/users/ksinha4/mlp/comp424_final_project/submissions/comp424mcgill/final-project-a_team_name/world.py\", line 310, in step\n    raise ValueError(\nValueError: [INVALID:STEP] Not a valid step from [6 3] to [6 3] and put barrier at 0, with max steps = 4\n\nExecute Random Walk!\n"}, {"student_agent_score": 2, "random_agent_score": 98, "student_agent_time": 0.005750179290771484, "random_agent_time": 0.006476640701293945, "board_size": 10, "swap_players": false, "run_out": "An exception raised. The traceback is as follows:\nTraceback (most recent call last):\n  File \"/home/ml/users/ksinha4/mlp/comp424_final_project/submissions/comp424mcgill/final-project-a_team_name/world.py\", line 310, in step\n    raise ValueError(\nValueError: [INVALID:STEP] Not a valid step from [7 5] to [7 5] and put barrier at 0, with max steps = 5\n\nExecute Random Walk!\nAn exception raised. The traceback is as follows:\nTraceback (most recent call last):\n  File \"/home/ml/users/ksinha4/mlp/comp424_final_project/submissions/comp424mcgill/final-project-a_team_name/world.py\", line 310, in step\n    raise ValueError(\nValueError: [INVALID:STEP] Not a valid step from [6 6] to [6 6] and put barrier at 0, with max steps = 5\n\nExecute Random Walk!\nAn exception raised. The traceback is as follows:\nTraceback (most recent call last):\n  File \"/home/ml/users/ksinha4/mlp/comp424_final_project/submissions/comp424mcgill/final-project-a_team_name/world.py\", line 310, in step\n    raise ValueError(\nValueError: [INVALID:STEP] Not a valid step from [7 8] to [7 8] and put barrier at 0, with max steps = 5\n\nExecute Random Walk!\nAn exception raised. The traceback is as follows:\nTraceback (most recent call last):\n  File \"/home/ml/users/ksinha4/mlp/comp424_final_project/submissions/comp424mcgill/final-project-a_team_name/world.py\", line 310, in step\n    raise ValueError(\nValueError: [INVALID:STEP] Not a valid step from [7 8] to [7 8] and put barrier at 0, with max steps = 5\n\nExecute Random Walk!\n"}, {"student_agent_score": 1, "random_agent_score": 48, "student_agent_time": 0.005702495574951172, "random_agent_time": 0.0027201175689697266, "board_size": 7, "swap_players": true, "run_out": "An exception raised. The traceback is as follows:\nTraceback (most recent call last):\n  File \"/home/ml/users/ksinha4/mlp/comp424_final_project/submissions/comp424mcgill/final-project-a_team_name/world.py\", line 310, in step\n    raise ValueError(\nValueError: [INVALID:STEP] Not a valid step from [2 3] to [2 3] and put barrier at 0, with max steps = 4\n\nExecute Random Walk!\nAn exception raised. The traceback is as follows:\nTraceback (most recent call last):\n  File \"/home/ml/users/ksinha4/mlp/comp424_final_project/submissions/comp424mcgill/final-project-a_team_name/world.py\", line 310, in step\n    raise ValueError(\nValueError: [INVALID:STEP] Not a valid step from [5 4] to [5 4] and put barrier at 0, with max steps = 4\n\nExecute Random Walk!\nAn exception raised. The traceback is as follows:\nTraceback (most recent call last):\n  File \"/home/ml/users/ksinha4/mlp/comp424_final_project/submissions/comp424mcgill/final-project-a_team_name/world.py\", line 310, in step\n    raise ValueError(\nValueError: [INVALID:STEP] Not a valid step from [6 3] to [6 3] and put barrier at 0, with max steps = 4\n\nExecute Random Walk!\n"}, {"student_agent_score": 1, "random_agent_score": 63, "student_agent_time": 0.003963947296142578, "random_agent_time": 0.0019240379333496094, "board_size": 8, "swap_players": false, "run_out": "An exception raised. The traceback is as follows:\nTraceback (most recent call last):\n  File \"/home/ml/users/ksinha4/mlp/comp424_final_project/submissions/comp424mcgill/final-project-a_team_name/world.py\", line 310, in step\n    raise ValueError(\nValueError: [INVALID:STEP] Not a valid step from [2 2] to [2 2] and put barrier at 0, with max steps = 4\n\nExecute Random Walk!\nAn exception raised. The traceback is as follows:\nTraceback (most recent call last):\n  File \"/home/ml/users/ksinha4/mlp/comp424_final_project/submissions/comp424mcgill/final-project-a_team_name/world.py\", line 310, in step\n    raise ValueError(\nValueError: [INVALID:STEP] Not a valid step from [3 1] to [3 1] and put barrier at 0, with max steps = 4\n\nExecute Random Walk!\nAn exception raised. The traceback is as follows:\nTraceback (most recent call last):\n  File \"/home/ml/users/ksinha4/mlp/comp424_final_project/submissions/comp424mcgill/final-project-a_team_name/world.py\", line 310, in step\n    raise ValueError(\nValueError: [INVALID:STEP] Not a valid step from [3 0] to [3 0] and put barrier at 0, with max steps = 4\n\nExecute Random Walk!\nAn exception raised. The traceback is as follows:\nTraceback (most recent call last):\n  File \"/home/ml/users/ksinha4/mlp/comp424_final_project/submissions/comp424mcgill/final-project-a_team_name/world.py\", line 310, in step\n    raise ValueError(\nValueError: [INVALID:STEP] Not a valid step from [6 1] to [6 1] and put barrier at 0, with max steps = 4\n\nExecute Random Walk!\n"}, {"student_agent_score": 2, "random_agent_score": 98, "student_agent_time": 0.0065233707427978516, "random_agent_time": 0.004938840866088867, "board_size": 10, "swap_players": false, "run_out": "An exception raised. The traceback is as follows:\nTraceback (most recent call last):\n  File \"/home/ml/users/ksinha4/mlp/comp424_final_project/submissions/comp424mcgill/final-project-a_team_name/world.py\", line 310, in step\n    raise ValueError(\nValueError: [INVALID:STEP] Not a valid step from [7 5] to [7 5] and put barrier at 0, with max steps = 5\n\nExecute Random Walk!\nAn exception raised. The traceback is as follows:\nTraceback (most recent call last):\n  File \"/home/ml/users/ksinha4/mlp/comp424_final_project/submissions/comp424mcgill/final-project-a_team_name/world.py\", line 310, in step\n    raise ValueError(\nValueError: [INVALID:STEP] Not a valid step from [6 6] to [6 6] and put barrier at 0, with max steps = 5\n\nExecute Random Walk!\nAn exception raised. The traceback is as follows:\nTraceback (most recent call last):\n  File \"/home/ml/users/ksinha4/mlp/comp424_final_project/submissions/comp424mcgill/final-project-a_team_name/world.py\", line 310, in step\n    raise ValueError(\nValueError: [INVALID:STEP] Not a valid step from [7 8] to [7 8] and put barrier at 0, with max steps = 5\n\nExecute Random Walk!\nAn exception raised. The traceback is as follows:\nTraceback (most recent call last):\n  File \"/home/ml/users/ksinha4/mlp/comp424_final_project/submissions/comp424mcgill/final-project-a_team_name/world.py\", line 310, in step\n    raise ValueError(\nValueError: [INVALID:STEP] Not a valid step from [7 8] to [7 8] and put barrier at 0, with max steps = 5\n\nExecute Random Walk!\n"}, {"student_agent_score": 1, "random_agent_score": 48, "student_agent_time": 0.006726503372192383, "random_agent_time": 0.005697488784790039, "board_size": 7, "swap_players": false, "run_out": "An exception raised. The traceback is as follows:\nTraceback (most recent call last):\n  File \"/home/ml/users/ksinha4/mlp/comp424_final_project/submissions/comp424mcgill/final-project-a_team_name/world.py\", line 310, in step\n    raise ValueError(\nValueError: [INVALID:STEP] Not a valid step from [4 3] to [4 3] and put barrier at 0, with max steps = 4\n\nExecute Random Walk!\nAn exception raised. The traceback is as follows:\nTraceback (most recent call last):\n  File \"/home/ml/users/ksinha4/mlp/comp424_final_project/submissions/comp424mcgill/final-project-a_team_name/world.py\", line 310, in step\n    raise ValueError(\nValueError: [INVALID:STEP] Not a valid step from [4 2] to [4 2] and put barrier at 0, with max steps = 4\n\nExecute Random Walk!\nAn exception raised. The traceback is as follows:\nTraceback (most recent call last):\n  File \"/home/ml/users/ksinha4/mlp/comp424_final_project/submissions/comp424mcgill/final-project-a_team_name/world.py\", line 310, in step\n    raise ValueError(\nValueError: [INVALID:STEP] Not a valid step from [4 3] to [4 3] and put barrier at 0, with max steps = 4\n\nExecute Random Walk!\nAn exception raised. The traceback is as follows:\nTraceback (most recent call last):\n  File \"/home/ml/users/ksinha4/mlp/comp424_final_project/submissions/comp424mcgill/final-project-a_team_name/world.py\", line 310, in step\n    raise ValueError(\nValueError: [INVALID:STEP] Not a valid step from [5 4] to [5 4] and put barrier at 0, with max steps = 4\n\nExecute Random Walk!\nAn exception raised. The traceback is as follows:\nTraceback (most recent call last):\n  File \"/home/ml/users/ksinha4/mlp/comp424_final_project/submissions/comp424mcgill/final-project-a_team_name/world.py\", line 310, in step\n    raise ValueError(\nValueError: [INVALID:STEP] Not a valid step from [6 3] to [6 3] and put barrier at 0, with max steps = 4\n\nExecute Random Walk!\n"}, {"student_agent_score": 1, "random_agent_score": 48, "student_agent_time": 0.002435922622680664, "random_agent_time": 0.002897500991821289, "board_size": 7, "swap_players": true, "run_out": "An exception raised. The traceback is as follows:\nTraceback (most recent call last):\n  File \"/home/ml/users/ksinha4/mlp/comp424_final_project/submissions/comp424mcgill/final-project-a_team_name/world.py\", line 310, in step\n    raise ValueError(\nValueError: [INVALID:STEP] Not a valid step from [2 3] to [2 3] and put barrier at 0, with max steps = 4\n\nExecute Random Walk!\nAn exception raised. The traceback is as follows:\nTraceback (most recent call last):\n  File \"/home/ml/users/ksinha4/mlp/comp424_final_project/submissions/comp424mcgill/final-project-a_team_name/world.py\", line 310, in step\n    raise ValueError(\nValueError: [INVALID:STEP] Not a valid step from [5 4] to [5 4] and put barrier at 0, with max steps = 4\n\nExecute Random Walk!\nAn exception raised. The traceback is as follows:\nTraceback (most recent call last):\n  File \"/home/ml/users/ksinha4/mlp/comp424_final_project/submissions/comp424mcgill/final-project-a_team_name/world.py\", line 310, in step\n    raise ValueError(\nValueError: [INVALID:STEP] Not a valid step from [6 3] to [6 3] and put barrier at 0, with max steps = 4\n\nExecute Random Walk!\n"}, {"student_agent_score": 1, "random_agent_score": 48, "student_agent_time": 0.0024323463439941406, "random_agent_time": 0.002252340316772461, "board_size": 7, "swap_players": true, "run_out": "An exception raised. The traceback is as follows:\nTraceback (most recent call last):\n  File \"/home/ml/users/ksinha4/mlp/comp424_final_project/submissions/comp424mcgill/final-project-a_team_name/world.py\", line 310, in step\n    raise ValueError(\nValueError: [INVALID:STEP] Not a valid step from [2 3] to [2 3] and put barrier at 0, with max steps = 4\n\nExecute Random Walk!\nAn exception raised. The traceback is as follows:\nTraceback (most recent call last):\n  File \"/home/ml/users/ksinha4/mlp/comp424_final_project/submissions/comp424mcgill/final-project-a_team_name/world.py\", line 310, in step\n    raise ValueError(\nValueError: [INVALID:STEP] Not a valid step from [5 4] to [5 4] and put barrier at 0, with max steps = 4\n\nExecute Random Walk!\nAn exception raised. The traceback is as follows:\nTraceback (most recent call last):\n  File \"/home/ml/users/ksinha4/mlp/comp424_final_project/submissions/comp424mcgill/final-project-a_team_name/world.py\", line 310, in step\n    raise ValueError(\nValueError: [INVALID:STEP] Not a valid step from [6 3] to [6 3] and put barrier at 0, with max steps = 4\n\nExecute Random Walk!\n"}, {"student_agent_score": 1, "random_agent_score": 63, "student_agent_time": 0.004063129425048828, "random_agent_time": 0.0021169185638427734, "board_size": 8, "swap_players": false, "run_out": "An exception raised. The traceback is as follows:\nTraceback (most recent call last):\n  File \"/home/ml/users/ksinha4/mlp/comp424_final_project/submissions/comp424mcgill/final-project-a_team_name/world.py\", line 310, in step\n    raise ValueError(\nValueError: [INVALID:STEP] Not a valid step from [2 2] to [2 2] and put barrier at 0, with max steps = 4\n\nExecute Random Walk!\nAn exception raised. The traceback is as follows:\nTraceback (most recent call last):\n  File \"/home/ml/users/ksinha4/mlp/comp424_final_project/submissions/comp424mcgill/final-project-a_team_name/world.py\", line 310, in step\n    raise ValueError(\nValueError: [INVALID:STEP] Not a valid step from [3 1] to [3 1] and put barrier at 0, with max steps = 4\n\nExecute Random Walk!\nAn exception raised. The traceback is as follows:\nTraceback (most recent call last):\n  File \"/home/ml/users/ksinha4/mlp/comp424_final_project/submissions/comp424mcgill/final-project-a_team_name/world.py\", line 310, in step\n    raise ValueError(\nValueError: [INVALID:STEP] Not a valid step from [3 0] to [3 0] and put barrier at 0, with max steps = 4\n\nExecute Random Walk!\nAn exception raised. The traceback is as follows:\nTraceback (most recent call last):\n  File \"/home/ml/users/ksinha4/mlp/comp424_final_project/submissions/comp424mcgill/final-project-a_team_name/world.py\", line 310, in step\n    raise ValueError(\nValueError: [INVALID:STEP] Not a valid step from [6 1] to [6 1] and put barrier at 0, with max steps = 4\n\nExecute Random Walk!\n"}, {"student_agent_score": 80, "random_agent_score": 1, "student_agent_time": 0.006499767303466797, "random_agent_time": 0.0070285797119140625, "board_size": 9, "swap_players": true, "run_out": "An exception raised. The traceback is as follows:\nTraceback (most recent call last):\n  File \"/home/ml/users/ksinha4/mlp/comp424_final_project/submissions/comp424mcgill/final-project-a_team_name/world.py\", line 310, in step\n    raise ValueError(\nValueError: [INVALID:STEP] Not a valid step from [3 4] to [3 4] and put barrier at 0, with max steps = 5\n\nExecute Random Walk!\nAn exception raised. The traceback is as follows:\nTraceback (most recent call last):\n  File \"/home/ml/users/ksinha4/mlp/comp424_final_project/submissions/comp424mcgill/final-project-a_team_name/world.py\", line 310, in step\n    raise ValueError(\nValueError: [INVALID:STEP] Not a valid step from [3 5] to [3 5] and put barrier at 0, with max steps = 5\n\nExecute Random Walk!\nAn exception raised. The traceback is as follows:\nTraceback (most recent call last):\n  File \"/home/ml/users/ksinha4/mlp/comp424_final_project/submissions/comp424mcgill/final-project-a_team_name/world.py\", line 310, in step\n    raise ValueError(\nValueError: [INVALID:STEP] Not a valid step from [3 4] to [3 4] and put barrier at 0, with max steps = 5\n\nExecute Random Walk!\nAn exception raised. The traceback is as follows:\nTraceback (most recent call last):\n  File \"/home/ml/users/ksinha4/mlp/comp424_final_project/submissions/comp424mcgill/final-project-a_team_name/world.py\", line 310, in step\n    raise ValueError(\nValueError: [INVALID:STEP] Not a valid step from [5 4] to [5 4] and put barrier at 0, with max steps = 5\n\nExecute Random Walk!\nAn exception raised. The traceback is as follows:\nTraceback (most recent call last):\n  File \"/home/ml/users/ksinha4/mlp/comp424_final_project/submissions/comp424mcgill/final-project-a_team_name/world.py\", line 310, in step\n    raise ValueError(\nValueError: [INVALID:STEP] Not a valid step from [5 5] to [5 5] and put barrier at 0, with max steps = 5\n\nExecute Random Walk!\n"}, {"student_agent_score": 63, "random_agent_score": 1, "student_agent_time": 0.002584218978881836, "random_agent_time": 0.002446413040161133, "board_size": 8, "swap_players": true, "run_out": "An exception raised. The traceback is as follows:\nTraceback (most recent call last):\n  File \"/home/ml/users/ksinha4/mlp/comp424_final_project/submissions/comp424mcgill/final-project-a_team_name/world.py\", line 310, in step\n    raise ValueError(\nValueError: [INVALID:STEP] Not a valid step from [5 5] to [5 5] and put barrier at 0, with max steps = 4\n\nExecute Random Walk!\nAn exception raised. The traceback is as follows:\nTraceback (most recent call last):\n  File \"/home/ml/users/ksinha4/mlp/comp424_final_project/submissions/comp424mcgill/final-project-a_team_name/world.py\", line 310, in step\n    raise ValueError(\nValueError: [INVALID:STEP] Not a valid step from [5 4] to [5 4] and put barrier at 0, with max steps = 4\n\nExecute Random Walk!\nAn exception raised. The traceback is as follows:\nTraceback (most recent call last):\n  File \"/home/ml/users/ksinha4/mlp/comp424_final_project/submissions/comp424mcgill/final-project-a_team_name/world.py\", line 310, in step\n    raise ValueError(\nValueError: [INVALID:STEP] Not a valid step from [5 4] to [5 4] and put barrier at 0, with max steps = 4\n\nExecute Random Walk!\n"}, {"student_agent_score": 1, "random_agent_score": 48, "student_agent_time": 0.004720926284790039, "random_agent_time": 0.0038635730743408203, "board_size": 7, "swap_players": false, "run_out": "An exception raised. The traceback is as follows:\nTraceback (most recent call last):\n  File \"/home/ml/users/ksinha4/mlp/comp424_final_project/submissions/comp424mcgill/final-project-a_team_name/world.py\", line 310, in step\n    raise ValueError(\nValueError: [INVALID:STEP] Not a valid step from [4 3] to [4 3] and put barrier at 0, with max steps = 4\n\nExecute Random Walk!\nAn exception raised. The traceback is as follows:\nTraceback (most recent call last):\n  File \"/home/ml/users/ksinha4/mlp/comp424_final_project/submissions/comp424mcgill/final-project-a_team_name/world.py\", line 310, in step\n    raise ValueError(\nValueError: [INVALID:STEP] Not a valid step from [4 2] to [4 2] and put barrier at 0, with max steps = 4\n\nExecute Random Walk!\nAn exception raised. The traceback is as follows:\nTraceback (most recent call last):\n  File \"/home/ml/users/ksinha4/mlp/comp424_final_project/submissions/comp424mcgill/final-project-a_team_name/world.py\", line 310, in step\n    raise ValueError(\nValueError: [INVALID:STEP] Not a valid step from [4 3] to [4 3] and put barrier at 0, with max steps = 4\n\nExecute Random Walk!\nAn exception raised. The traceback is as follows:\nTraceback (most recent call last):\n  File \"/home/ml/users/ksinha4/mlp/comp424_final_project/submissions/comp424mcgill/final-project-a_team_name/world.py\", line 310, in step\n    raise ValueError(\nValueError: [INVALID:STEP] Not a valid step from [5 4] to [5 4] and put barrier at 0, with max steps = 4\n\nExecute Random Walk!\nAn exception raised. The traceback is as follows:\nTraceback (most recent call last):\n  File \"/home/ml/users/ksinha4/mlp/comp424_final_project/submissions/comp424mcgill/final-project-a_team_name/world.py\", line 310, in step\n    raise ValueError(\nValueError: [INVALID:STEP] Not a valid step from [6 3] to [6 3] and put barrier at 0, with max steps = 4\n\nExecute Random Walk!\n"}, {"student_agent_score": 1, "random_agent_score": 48, "student_agent_time": 0.0028600692749023438, "random_agent_time": 0.003543376922607422, "board_size": 7, "swap_players": true, "run_out": "An exception raised. The traceback is as follows:\nTraceback (most recent call last):\n  File \"/home/ml/users/ksinha4/mlp/comp424_final_project/submissions/comp424mcgill/final-project-a_team_name/world.py\", line 310, in step\n    raise ValueError(\nValueError: [INVALID:STEP] Not a valid step from [2 3] to [2 3] and put barrier at 0, with max steps = 4\n\nExecute Random Walk!\nAn exception raised. The traceback is as follows:\nTraceback (most recent call last):\n  File \"/home/ml/users/ksinha4/mlp/comp424_final_project/submissions/comp424mcgill/final-project-a_team_name/world.py\", line 310, in step\n    raise ValueError(\nValueError: [INVALID:STEP] Not a valid step from [5 4] to [5 4] and put barrier at 0, with max steps = 4\n\nExecute Random Walk!\nAn exception raised. The traceback is as follows:\nTraceback (most recent call last):\n  File \"/home/ml/users/ksinha4/mlp/comp424_final_project/submissions/comp424mcgill/final-project-a_team_name/world.py\", line 310, in step\n    raise ValueError(\nValueError: [INVALID:STEP] Not a valid step from [6 3] to [6 3] and put barrier at 0, with max steps = 4\n\nExecute Random Walk!\n"}, {"student_agent_score": 99, "random_agent_score": 1, "student_agent_time": 0.00034046173095703125, "random_agent_time": 0.0009348392486572266, "board_size": 10, "swap_players": true, "run_out": ""}, {"student_agent_score": 1, "random_agent_score": 48, "student_agent_time": 0.004747152328491211, "random_agent_time": 0.0029370784759521484, "board_size": 7, "swap_players": false, "run_out": "An exception raised. The traceback is as follows:\nTraceback (most recent call last):\n  File \"/home/ml/users/ksinha4/mlp/comp424_final_project/submissions/comp424mcgill/final-project-a_team_name/world.py\", line 310, in step\n    raise ValueError(\nValueError: [INVALID:STEP] Not a valid step from [4 3] to [4 3] and put barrier at 0, with max steps = 4\n\nExecute Random Walk!\nAn exception raised. The traceback is as follows:\nTraceback (most recent call last):\n  File \"/home/ml/users/ksinha4/mlp/comp424_final_project/submissions/comp424mcgill/final-project-a_team_name/world.py\", line 310, in step\n    raise ValueError(\nValueError: [INVALID:STEP] Not a valid step from [4 2] to [4 2] and put barrier at 0, with max steps = 4\n\nExecute Random Walk!\nAn exception raised. The traceback is as follows:\nTraceback (most recent call last):\n  File \"/home/ml/users/ksinha4/mlp/comp424_final_project/submissions/comp424mcgill/final-project-a_team_name/world.py\", line 310, in step\n    raise ValueError(\nValueError: [INVALID:STEP] Not a valid step from [4 3] to [4 3] and put barrier at 0, with max steps = 4\n\nExecute Random Walk!\nAn exception raised. The traceback is as follows:\nTraceback (most recent call last):\n  File \"/home/ml/users/ksinha4/mlp/comp424_final_project/submissions/comp424mcgill/final-project-a_team_name/world.py\", line 310, in step\n    raise ValueError(\nValueError: [INVALID:STEP] Not a valid step from [5 4] to [5 4] and put barrier at 0, with max steps = 4\n\nExecute Random Walk!\nAn exception raised. The traceback is as follows:\nTraceback (most recent call last):\n  File \"/home/ml/users/ksinha4/mlp/comp424_final_project/submissions/comp424mcgill/final-project-a_team_name/world.py\", line 310, in step\n    raise ValueError(\nValueError: [INVALID:STEP] Not a valid step from [6 3] to [6 3] and put barrier at 0, with max steps = 4\n\nExecute Random Walk!\n"}, {"student_agent_score": 1, "random_agent_score": 63, "student_agent_time": 0.00405430793762207, "random_agent_time": 0.0030629634857177734, "board_size": 8, "swap_players": false, "run_out": "An exception raised. The traceback is as follows:\nTraceback (most recent call last):\n  File \"/home/ml/users/ksinha4/mlp/comp424_final_project/submissions/comp424mcgill/final-project-a_team_name/world.py\", line 310, in step\n    raise ValueError(\nValueError: [INVALID:STEP] Not a valid step from [2 2] to [2 2] and put barrier at 0, with max steps = 4\n\nExecute Random Walk!\nAn exception raised. The traceback is as follows:\nTraceback (most recent call last):\n  File \"/home/ml/users/ksinha4/mlp/comp424_final_project/submissions/comp424mcgill/final-project-a_team_name/world.py\", line 310, in step\n    raise ValueError(\nValueError: [INVALID:STEP] Not a valid step from [3 1] to [3 1] and put barrier at 0, with max steps = 4\n\nExecute Random Walk!\nAn exception raised. The traceback is as follows:\nTraceback (most recent call last):\n  File \"/home/ml/users/ksinha4/mlp/comp424_final_project/submissions/comp424mcgill/final-project-a_team_name/world.py\", line 310, in step\n    raise ValueError(\nValueError: [INVALID:STEP] Not a valid step from [3 0] to [3 0] and put barrier at 0, with max steps = 4\n\nExecute Random Walk!\nAn exception raised. The traceback is as follows:\nTraceback (most recent call last):\n  File \"/home/ml/users/ksinha4/mlp/comp424_final_project/submissions/comp424mcgill/final-project-a_team_name/world.py\", line 310, in step\n    raise ValueError(\nValueError: [INVALID:STEP] Not a valid step from [6 1] to [6 1] and put barrier at 0, with max steps = 4\n\nExecute Random Walk!\n"}, {"student_agent_score": 117, "random_agent_score": 1, "student_agent_time": 0.010610342025756836, "random_agent_time": 0.006473541259765625, "board_size": 11, "swap_players": false, "run_out": "An exception raised. The traceback is as follows:\nTraceback (most recent call last):\n  File \"/home/ml/users/ksinha4/mlp/comp424_final_project/submissions/comp424mcgill/final-project-a_team_name/world.py\", line 310, in step\n    raise ValueError(\nValueError: [INVALID:STEP] Not a valid step from [1 7] to [1 7] and put barrier at 0, with max steps = 6\n\nExecute Random Walk!\nAn exception raised. The traceback is as follows:\nTraceback (most recent call last):\n  File \"/home/ml/users/ksinha4/mlp/comp424_final_project/submissions/comp424mcgill/final-project-a_team_name/world.py\", line 310, in step\n    raise ValueError(\nValueError: [INVALID:STEP] Not a valid step from [1 8] to [1 8] and put barrier at 0, with max steps = 6\n\nExecute Random Walk!\nAn exception raised. The traceback is as follows:\nTraceback (most recent call last):\n  File \"/home/ml/users/ksinha4/mlp/comp424_final_project/submissions/comp424mcgill/final-project-a_team_name/world.py\", line 310, in step\n    raise ValueError(\nValueError: [INVALID:STEP] Not a valid step from [1 6] to [1 6] and put barrier at 0, with max steps = 6\n\nExecute Random Walk!\nAn exception raised. The traceback is as follows:\nTraceback (most recent call last):\n  File \"/home/ml/users/ksinha4/mlp/comp424_final_project/submissions/comp424mcgill/final-project-a_team_name/world.py\", line 310, in step\n    raise ValueError(\nValueError: [INVALID:STEP] Not a valid step from [3 3] to [3 3] and put barrier at 0, with max steps = 6\n\nExecute Random Walk!\nAn exception raised. The traceback is as follows:\nTraceback (most recent call last):\n  File \"/home/ml/users/ksinha4/mlp/comp424_final_project/submissions/comp424mcgill/final-project-a_team_name/world.py\", line 310, in step\n    raise ValueError(\nValueError: [INVALID:STEP] Not a valid step from [3 4] to [3 4] and put barrier at 0, with max steps = 6\n\nExecute Random Walk!\nAn exception raised. The traceback is as follows:\nTraceback (most recent call last):\n  File \"/home/ml/users/ksinha4/mlp/comp424_final_project/submissions/comp424mcgill/final-project-a_team_name/world.py\", line 310, in step\n    raise ValueError(\nValueError: [INVALID:STEP] Not a valid step from [3 4] to [3 4] and put barrier at 0, with max steps = 6\n\nExecute Random Walk!\nAn exception raised. The traceback is as follows:\nTraceback (most recent call last):\n  File \"/home/ml/users/ksinha4/mlp/comp424_final_project/submissions/comp424mcgill/final-project-a_team_name/world.py\", line 310, in step\n    raise ValueError(\nValueError: [INVALID:STEP] Not a valid step from [4 4] to [4 4] and put barrier at 0, with max steps = 6\n\nExecute Random Walk!\nAn exception raised. The traceback is as follows:\nTraceback (most recent call last):\n  File \"/home/ml/users/ksinha4/mlp/comp424_final_project/submissions/comp424mcgill/final-project-a_team_name/world.py\", line 310, in step\n    raise ValueError(\nValueError: [INVALID:STEP] Not a valid step from [4 4] to [4 4] and put barrier at 0, with max steps = 6\n\nExecute Random Walk!\n"}, {"student_agent_score": 1, "random_agent_score": 48, "student_agent_time": 0.0035686492919921875, "random_agent_time": 0.0030906200408935547, "board_size": 7, "swap_players": true, "run_out": "An exception raised. The traceback is as follows:\nTraceback (most recent call last):\n  File \"/home/ml/users/ksinha4/mlp/comp424_final_project/submissions/comp424mcgill/final-project-a_team_name/world.py\", line 310, in step\n    raise ValueError(\nValueError: [INVALID:STEP] Not a valid step from [2 3] to [2 3] and put barrier at 0, with max steps = 4\n\nExecute Random Walk!\nAn exception raised. The traceback is as follows:\nTraceback (most recent call last):\n  File \"/home/ml/users/ksinha4/mlp/comp424_final_project/submissions/comp424mcgill/final-project-a_team_name/world.py\", line 310, in step\n    raise ValueError(\nValueError: [INVALID:STEP] Not a valid step from [5 4] to [5 4] and put barrier at 0, with max steps = 4\n\nExecute Random Walk!\nAn exception raised. The traceback is as follows:\nTraceback (most recent call last):\n  File \"/home/ml/users/ksinha4/mlp/comp424_final_project/submissions/comp424mcgill/final-project-a_team_name/world.py\", line 310, in step\n    raise ValueError(\nValueError: [INVALID:STEP] Not a valid step from [6 3] to [6 3] and put barrier at 0, with max steps = 4\n\nExecute Random Walk!\n"}, {"student_agent_score": 2, "random_agent_score": 98, "student_agent_time": 0.005468130111694336, "random_agent_time": 0.005052804946899414, "board_size": 10, "swap_players": false, "run_out": "An exception raised. The traceback is as follows:\nTraceback (most recent call last):\n  File \"/home/ml/users/ksinha4/mlp/comp424_final_project/submissions/comp424mcgill/final-project-a_team_name/world.py\", line 310, in step\n    raise ValueError(\nValueError: [INVALID:STEP] Not a valid step from [7 5] to [7 5] and put barrier at 0, with max steps = 5\n\nExecute Random Walk!\nAn exception raised. The traceback is as follows:\nTraceback (most recent call last):\n  File \"/home/ml/users/ksinha4/mlp/comp424_final_project/submissions/comp424mcgill/final-project-a_team_name/world.py\", line 310, in step\n    raise ValueError(\nValueError: [INVALID:STEP] Not a valid step from [6 6] to [6 6] and put barrier at 0, with max steps = 5\n\nExecute Random Walk!\nAn exception raised. The traceback is as follows:\nTraceback (most recent call last):\n  File \"/home/ml/users/ksinha4/mlp/comp424_final_project/submissions/comp424mcgill/final-project-a_team_name/world.py\", line 310, in step\n    raise ValueError(\nValueError: [INVALID:STEP] Not a valid step from [7 8] to [7 8] and put barrier at 0, with max steps = 5\n\nExecute Random Walk!\nAn exception raised. The traceback is as follows:\nTraceback (most recent call last):\n  File \"/home/ml/users/ksinha4/mlp/comp424_final_project/submissions/comp424mcgill/final-project-a_team_name/world.py\", line 310, in step\n    raise ValueError(\nValueError: [INVALID:STEP] Not a valid step from [7 8] to [7 8] and put barrier at 0, with max steps = 5\n\nExecute Random Walk!\n"}, {"student_agent_score": 2, "random_agent_score": 79, "student_agent_time": 0.0035240650177001953, "random_agent_time": 0.0021469593048095703, "board_size": 9, "swap_players": false, "run_out": "An exception raised. The traceback is as follows:\nTraceback (most recent call last):\n  File \"/home/ml/users/ksinha4/mlp/comp424_final_project/submissions/comp424mcgill/final-project-a_team_name/world.py\", line 310, in step\n    raise ValueError(\nValueError: [INVALID:STEP] Not a valid step from [5 4] to [5 4] and put barrier at 0, with max steps = 5\n\nExecute Random Walk!\nAn exception raised. The traceback is as follows:\nTraceback (most recent call last):\n  File \"/home/ml/users/ksinha4/mlp/comp424_final_project/submissions/comp424mcgill/final-project-a_team_name/world.py\", line 310, in step\n    raise ValueError(\nValueError: [INVALID:STEP] Not a valid step from [5 3] to [5 3] and put barrier at 0, with max steps = 5\n\nExecute Random Walk!\n"}, {"student_agent_score": 1, "random_agent_score": 35, "student_agent_time": 0.002749204635620117, "random_agent_time": 0.0024983882904052734, "board_size": 6, "swap_players": true, "run_out": "An exception raised. The traceback is as follows:\nTraceback (most recent call last):\n  File \"/home/ml/users/ksinha4/mlp/comp424_final_project/submissions/comp424mcgill/final-project-a_team_name/world.py\", line 310, in step\n    raise ValueError(\nValueError: [INVALID:STEP] Not a valid step from [3 3] to [3 3] and put barrier at 0, with max steps = 3\n\nExecute Random Walk!\nAn exception raised. The traceback is as follows:\nTraceback (most recent call last):\n  File \"/home/ml/users/ksinha4/mlp/comp424_final_project/submissions/comp424mcgill/final-project-a_team_name/world.py\", line 310, in step\n    raise ValueError(\nValueError: [INVALID:STEP] Not a valid step from [3 3] to [3 3] and put barrier at 0, with max steps = 3\n\nExecute Random Walk!\n"}, {"student_agent_score": 1, "random_agent_score": 48, "student_agent_time": 0.003444194793701172, "random_agent_time": 0.003833293914794922, "board_size": 7, "swap_players": false, "run_out": "An exception raised. The traceback is as follows:\nTraceback (most recent call last):\n  File \"/home/ml/users/ksinha4/mlp/comp424_final_project/submissions/comp424mcgill/final-project-a_team_name/world.py\", line 310, in step\n    raise ValueError(\nValueError: [INVALID:STEP] Not a valid step from [4 3] to [4 3] and put barrier at 0, with max steps = 4\n\nExecute Random Walk!\nAn exception raised. The traceback is as follows:\nTraceback (most recent call last):\n  File \"/home/ml/users/ksinha4/mlp/comp424_final_project/submissions/comp424mcgill/final-project-a_team_name/world.py\", line 310, in step\n    raise ValueError(\nValueError: [INVALID:STEP] Not a valid step from [4 2] to [4 2] and put barrier at 0, with max steps = 4\n\nExecute Random Walk!\nAn exception raised. The traceback is as follows:\nTraceback (most recent call last):\n  File \"/home/ml/users/ksinha4/mlp/comp424_final_project/submissions/comp424mcgill/final-project-a_team_name/world.py\", line 310, in step\n    raise ValueError(\nValueError: [INVALID:STEP] Not a valid step from [4 3] to [4 3] and put barrier at 0, with max steps = 4\n\nExecute Random Walk!\nAn exception raised. The traceback is as follows:\nTraceback (most recent call last):\n  File \"/home/ml/users/ksinha4/mlp/comp424_final_project/submissions/comp424mcgill/final-project-a_team_name/world.py\", line 310, in step\n    raise ValueError(\nValueError: [INVALID:STEP] Not a valid step from [5 4] to [5 4] and put barrier at 0, with max steps = 4\n\nExecute Random Walk!\nAn exception raised. The traceback is as follows:\nTraceback (most recent call last):\n  File \"/home/ml/users/ksinha4/mlp/comp424_final_project/submissions/comp424mcgill/final-project-a_team_name/world.py\", line 310, in step\n    raise ValueError(\nValueError: [INVALID:STEP] Not a valid step from [6 3] to [6 3] and put barrier at 0, with max steps = 4\n\nExecute Random Walk!\n"}, {"student_agent_score": 1, "random_agent_score": 48, "student_agent_time": 0.0041561126708984375, "random_agent_time": 0.0026967525482177734, "board_size": 7, "swap_players": false, "run_out": "An exception raised. The traceback is as follows:\nTraceback (most recent call last):\n  File \"/home/ml/users/ksinha4/mlp/comp424_final_project/submissions/comp424mcgill/final-project-a_team_name/world.py\", line 310, in step\n    raise ValueError(\nValueError: [INVALID:STEP] Not a valid step from [4 3] to [4 3] and put barrier at 0, with max steps = 4\n\nExecute Random Walk!\nAn exception raised. The traceback is as follows:\nTraceback (most recent call last):\n  File \"/home/ml/users/ksinha4/mlp/comp424_final_project/submissions/comp424mcgill/final-project-a_team_name/world.py\", line 310, in step\n    raise ValueError(\nValueError: [INVALID:STEP] Not a valid step from [4 2] to [4 2] and put barrier at 0, with max steps = 4\n\nExecute Random Walk!\nAn exception raised. The traceback is as follows:\nTraceback (most recent call last):\n  File \"/home/ml/users/ksinha4/mlp/comp424_final_project/submissions/comp424mcgill/final-project-a_team_name/world.py\", line 310, in step\n    raise ValueError(\nValueError: [INVALID:STEP] Not a valid step from [4 3] to [4 3] and put barrier at 0, with max steps = 4\n\nExecute Random Walk!\nAn exception raised. The traceback is as follows:\nTraceback (most recent call last):\n  File \"/home/ml/users/ksinha4/mlp/comp424_final_project/submissions/comp424mcgill/final-project-a_team_name/world.py\", line 310, in step\n    raise ValueError(\nValueError: [INVALID:STEP] Not a valid step from [5 4] to [5 4] and put barrier at 0, with max steps = 4\n\nExecute Random Walk!\nAn exception raised. The traceback is as follows:\nTraceback (most recent call last):\n  File \"/home/ml/users/ksinha4/mlp/comp424_final_project/submissions/comp424mcgill/final-project-a_team_name/world.py\", line 310, in step\n    raise ValueError(\nValueError: [INVALID:STEP] Not a valid step from [6 3] to [6 3] and put barrier at 0, with max steps = 4\n\nExecute Random Walk!\n"}, {"student_agent_score": 1, "random_agent_score": 48, "student_agent_time": 0.0030066967010498047, "random_agent_time": 0.0027642250061035156, "board_size": 7, "swap_players": true, "run_out": "An exception raised. The traceback is as follows:\nTraceback (most recent call last):\n  File \"/home/ml/users/ksinha4/mlp/comp424_final_project/submissions/comp424mcgill/final-project-a_team_name/world.py\", line 310, in step\n    raise ValueError(\nValueError: [INVALID:STEP] Not a valid step from [2 3] to [2 3] and put barrier at 0, with max steps = 4\n\nExecute Random Walk!\nAn exception raised. The traceback is as follows:\nTraceback (most recent call last):\n  File \"/home/ml/users/ksinha4/mlp/comp424_final_project/submissions/comp424mcgill/final-project-a_team_name/world.py\", line 310, in step\n    raise ValueError(\nValueError: [INVALID:STEP] Not a valid step from [5 4] to [5 4] and put barrier at 0, with max steps = 4\n\nExecute Random Walk!\nAn exception raised. The traceback is as follows:\nTraceback (most recent call last):\n  File \"/home/ml/users/ksinha4/mlp/comp424_final_project/submissions/comp424mcgill/final-project-a_team_name/world.py\", line 310, in step\n    raise ValueError(\nValueError: [INVALID:STEP] Not a valid step from [6 3] to [6 3] and put barrier at 0, with max steps = 4\n\nExecute Random Walk!\n"}, {"student_agent_score": 1, "random_agent_score": 35, "student_agent_time": 0.0019233226776123047, "random_agent_time": 0.0019948482513427734, "board_size": 6, "swap_players": true, "run_out": "An exception raised. The traceback is as follows:\nTraceback (most recent call last):\n  File \"/home/ml/users/ksinha4/mlp/comp424_final_project/submissions/comp424mcgill/final-project-a_team_name/world.py\", line 310, in step\n    raise ValueError(\nValueError: [INVALID:STEP] Not a valid step from [3 3] to [3 3] and put barrier at 0, with max steps = 3\n\nExecute Random Walk!\nAn exception raised. The traceback is as follows:\nTraceback (most recent call last):\n  File \"/home/ml/users/ksinha4/mlp/comp424_final_project/submissions/comp424mcgill/final-project-a_team_name/world.py\", line 310, in step\n    raise ValueError(\nValueError: [INVALID:STEP] Not a valid step from [3 3] to [3 3] and put barrier at 0, with max steps = 3\n\nExecute Random Walk!\n"}, {"student_agent_score": 120, "random_agent_score": 1, "student_agent_time": 0.002544879913330078, "random_agent_time": 0.0029621124267578125, "board_size": 11, "swap_players": true, "run_out": "An exception raised. The traceback is as follows:\nTraceback (most recent call last):\n  File \"/home/ml/users/ksinha4/mlp/comp424_final_project/submissions/comp424mcgill/final-project-a_team_name/world.py\", line 310, in step\n    raise ValueError(\nValueError: [INVALID:STEP] Not a valid step from [9 3] to [9 3] and put barrier at 0, with max steps = 6\n\nExecute Random Walk!\nAn exception raised. The traceback is as follows:\nTraceback (most recent call last):\n  File \"/home/ml/users/ksinha4/mlp/comp424_final_project/submissions/comp424mcgill/final-project-a_team_name/world.py\", line 310, in step\n    raise ValueError(\nValueError: [INVALID:STEP] Not a valid step from [9 3] to [9 3] and put barrier at 0, with max steps = 6\n\nExecute Random Walk!\n"}, {"student_agent_score": 63, "random_agent_score": 1, "student_agent_time": 0.0028123855590820312, "random_agent_time": 0.0026884078979492188, "board_size": 8, "swap_players": true, "run_out": "An exception raised. The traceback is as follows:\nTraceback (most recent call last):\n  File \"/home/ml/users/ksinha4/mlp/comp424_final_project/submissions/comp424mcgill/final-project-a_team_name/world.py\", line 310, in step\n    raise ValueError(\nValueError: [INVALID:STEP] Not a valid step from [5 5] to [5 5] and put barrier at 0, with max steps = 4\n\nExecute Random Walk!\nAn exception raised. The traceback is as follows:\nTraceback (most recent call last):\n  File \"/home/ml/users/ksinha4/mlp/comp424_final_project/submissions/comp424mcgill/final-project-a_team_name/world.py\", line 310, in step\n    raise ValueError(\nValueError: [INVALID:STEP] Not a valid step from [5 4] to [5 4] and put barrier at 0, with max steps = 4\n\nExecute Random Walk!\nAn exception raised. The traceback is as follows:\nTraceback (most recent call last):\n  File \"/home/ml/users/ksinha4/mlp/comp424_final_project/submissions/comp424mcgill/final-project-a_team_name/world.py\", line 310, in step\n    raise ValueError(\nValueError: [INVALID:STEP] Not a valid step from [5 4] to [5 4] and put barrier at 0, with max steps = 4\n\nExecute Random Walk!\n"}, {"student_agent_score": 1, "random_agent_score": 48, "student_agent_time": 0.004766225814819336, "random_agent_time": 0.0024530887603759766, "board_size": 7, "swap_players": false, "run_out": "An exception raised. The traceback is as follows:\nTraceback (most recent call last):\n  File \"/home/ml/users/ksinha4/mlp/comp424_final_project/submissions/comp424mcgill/final-project-a_team_name/world.py\", line 310, in step\n    raise ValueError(\nValueError: [INVALID:STEP] Not a valid step from [4 3] to [4 3] and put barrier at 0, with max steps = 4\n\nExecute Random Walk!\nAn exception raised. The traceback is as follows:\nTraceback (most recent call last):\n  File \"/home/ml/users/ksinha4/mlp/comp424_final_project/submissions/comp424mcgill/final-project-a_team_name/world.py\", line 310, in step\n    raise ValueError(\nValueError: [INVALID:STEP] Not a valid step from [4 2] to [4 2] and put barrier at 0, with max steps = 4\n\nExecute Random Walk!\nAn exception raised. The traceback is as follows:\nTraceback (most recent call last):\n  File \"/home/ml/users/ksinha4/mlp/comp424_final_project/submissions/comp424mcgill/final-project-a_team_name/world.py\", line 310, in step\n    raise ValueError(\nValueError: [INVALID:STEP] Not a valid step from [4 3] to [4 3] and put barrier at 0, with max steps = 4\n\nExecute Random Walk!\nAn exception raised. The traceback is as follows:\nTraceback (most recent call last):\n  File \"/home/ml/users/ksinha4/mlp/comp424_final_project/submissions/comp424mcgill/final-project-a_team_name/world.py\", line 310, in step\n    raise ValueError(\nValueError: [INVALID:STEP] Not a valid step from [5 4] to [5 4] and put barrier at 0, with max steps = 4\n\nExecute Random Walk!\nAn exception raised. The traceback is as follows:\nTraceback (most recent call last):\n  File \"/home/ml/users/ksinha4/mlp/comp424_final_project/submissions/comp424mcgill/final-project-a_team_name/world.py\", line 310, in step\n    raise ValueError(\nValueError: [INVALID:STEP] Not a valid step from [6 3] to [6 3] and put barrier at 0, with max steps = 4\n\nExecute Random Walk!\n"}, {"student_agent_score": 1, "random_agent_score": 48, "student_agent_time": 0.0025930404663085938, "random_agent_time": 0.002584218978881836, "board_size": 7, "swap_players": true, "run_out": "An exception raised. The traceback is as follows:\nTraceback (most recent call last):\n  File \"/home/ml/users/ksinha4/mlp/comp424_final_project/submissions/comp424mcgill/final-project-a_team_name/world.py\", line 310, in step\n    raise ValueError(\nValueError: [INVALID:STEP] Not a valid step from [2 3] to [2 3] and put barrier at 0, with max steps = 4\n\nExecute Random Walk!\nAn exception raised. The traceback is as follows:\nTraceback (most recent call last):\n  File \"/home/ml/users/ksinha4/mlp/comp424_final_project/submissions/comp424mcgill/final-project-a_team_name/world.py\", line 310, in step\n    raise ValueError(\nValueError: [INVALID:STEP] Not a valid step from [5 4] to [5 4] and put barrier at 0, with max steps = 4\n\nExecute Random Walk!\nAn exception raised. The traceback is as follows:\nTraceback (most recent call last):\n  File \"/home/ml/users/ksinha4/mlp/comp424_final_project/submissions/comp424mcgill/final-project-a_team_name/world.py\", line 310, in step\n    raise ValueError(\nValueError: [INVALID:STEP] Not a valid step from [6 3] to [6 3] and put barrier at 0, with max steps = 4\n\nExecute Random Walk!\n"}, {"student_agent_score": 120, "random_agent_score": 1, "student_agent_time": 0.002415180206298828, "random_agent_time": 0.0026345252990722656, "board_size": 11, "swap_players": true, "run_out": "An exception raised. The traceback is as follows:\nTraceback (most recent call last):\n  File \"/home/ml/users/ksinha4/mlp/comp424_final_project/submissions/comp424mcgill/final-project-a_team_name/world.py\", line 310, in step\n    raise ValueError(\nValueError: [INVALID:STEP] Not a valid step from [9 3] to [9 3] and put barrier at 0, with max steps = 6\n\nExecute Random Walk!\nAn exception raised. The traceback is as follows:\nTraceback (most recent call last):\n  File \"/home/ml/users/ksinha4/mlp/comp424_final_project/submissions/comp424mcgill/final-project-a_team_name/world.py\", line 310, in step\n    raise ValueError(\nValueError: [INVALID:STEP] Not a valid step from [9 3] to [9 3] and put barrier at 0, with max steps = 6\n\nExecute Random Walk!\n"}, {"student_agent_score": 1, "random_agent_score": 48, "student_agent_time": 0.004580259323120117, "random_agent_time": 0.0033655166625976562, "board_size": 7, "swap_players": false, "run_out": "An exception raised. The traceback is as follows:\nTraceback (most recent call last):\n  File \"/home/ml/users/ksinha4/mlp/comp424_final_project/submissions/comp424mcgill/final-project-a_team_name/world.py\", line 310, in step\n    raise ValueError(\nValueError: [INVALID:STEP] Not a valid step from [4 3] to [4 3] and put barrier at 0, with max steps = 4\n\nExecute Random Walk!\nAn exception raised. The traceback is as follows:\nTraceback (most recent call last):\n  File \"/home/ml/users/ksinha4/mlp/comp424_final_project/submissions/comp424mcgill/final-project-a_team_name/world.py\", line 310, in step\n    raise ValueError(\nValueError: [INVALID:STEP] Not a valid step from [4 2] to [4 2] and put barrier at 0, with max steps = 4\n\nExecute Random Walk!\nAn exception raised. The traceback is as follows:\nTraceback (most recent call last):\n  File \"/home/ml/users/ksinha4/mlp/comp424_final_project/submissions/comp424mcgill/final-project-a_team_name/world.py\", line 310, in step\n    raise ValueError(\nValueError: [INVALID:STEP] Not a valid step from [4 3] to [4 3] and put barrier at 0, with max steps = 4\n\nExecute Random Walk!\nAn exception raised. The traceback is as follows:\nTraceback (most recent call last):\n  File \"/home/ml/users/ksinha4/mlp/comp424_final_project/submissions/comp424mcgill/final-project-a_team_name/world.py\", line 310, in step\n    raise ValueError(\nValueError: [INVALID:STEP] Not a valid step from [5 4] to [5 4] and put barrier at 0, with max steps = 4\n\nExecute Random Walk!\nAn exception raised. The traceback is as follows:\nTraceback (most recent call last):\n  File \"/home/ml/users/ksinha4/mlp/comp424_final_project/submissions/comp424mcgill/final-project-a_team_name/world.py\", line 310, in step\n    raise ValueError(\nValueError: [INVALID:STEP] Not a valid step from [6 3] to [6 3] and put barrier at 0, with max steps = 4\n\nExecute Random Walk!\n"}, {"student_agent_score": 1, "random_agent_score": 48, "student_agent_time": 0.004230499267578125, "random_agent_time": 0.0036163330078125, "board_size": 7, "swap_players": true, "run_out": "An exception raised. The traceback is as follows:\nTraceback (most recent call last):\n  File \"/home/ml/users/ksinha4/mlp/comp424_final_project/submissions/comp424mcgill/final-project-a_team_name/world.py\", line 310, in step\n    raise ValueError(\nValueError: [INVALID:STEP] Not a valid step from [2 3] to [2 3] and put barrier at 0, with max steps = 4\n\nExecute Random Walk!\nAn exception raised. The traceback is as follows:\nTraceback (most recent call last):\n  File \"/home/ml/users/ksinha4/mlp/comp424_final_project/submissions/comp424mcgill/final-project-a_team_name/world.py\", line 310, in step\n    raise ValueError(\nValueError: [INVALID:STEP] Not a valid step from [5 4] to [5 4] and put barrier at 0, with max steps = 4\n\nExecute Random Walk!\nAn exception raised. The traceback is as follows:\nTraceback (most recent call last):\n  File \"/home/ml/users/ksinha4/mlp/comp424_final_project/submissions/comp424mcgill/final-project-a_team_name/world.py\", line 310, in step\n    raise ValueError(\nValueError: [INVALID:STEP] Not a valid step from [6 3] to [6 3] and put barrier at 0, with max steps = 4\n\nExecute Random Walk!\n"}, {"student_agent_score": 2, "random_agent_score": 79, "student_agent_time": 0.0026607513427734375, "random_agent_time": 0.0022864341735839844, "board_size": 9, "swap_players": false, "run_out": "An exception raised. The traceback is as follows:\nTraceback (most recent call last):\n  File \"/home/ml/users/ksinha4/mlp/comp424_final_project/submissions/comp424mcgill/final-project-a_team_name/world.py\", line 310, in step\n    raise ValueError(\nValueError: [INVALID:STEP] Not a valid step from [5 4] to [5 4] and put barrier at 0, with max steps = 5\n\nExecute Random Walk!\nAn exception raised. The traceback is as follows:\nTraceback (most recent call last):\n  File \"/home/ml/users/ksinha4/mlp/comp424_final_project/submissions/comp424mcgill/final-project-a_team_name/world.py\", line 310, in step\n    raise ValueError(\nValueError: [INVALID:STEP] Not a valid step from [5 3] to [5 3] and put barrier at 0, with max steps = 5\n\nExecute Random Walk!\n"}, {"student_agent_score": 1, "random_agent_score": 48, "student_agent_time": 0.0028104782104492188, "random_agent_time": 0.002572298049926758, "board_size": 7, "swap_players": true, "run_out": "An exception raised. The traceback is as follows:\nTraceback (most recent call last):\n  File \"/home/ml/users/ksinha4/mlp/comp424_final_project/submissions/comp424mcgill/final-project-a_team_name/world.py\", line 310, in step\n    raise ValueError(\nValueError: [INVALID:STEP] Not a valid step from [2 3] to [2 3] and put barrier at 0, with max steps = 4\n\nExecute Random Walk!\nAn exception raised. The traceback is as follows:\nTraceback (most recent call last):\n  File \"/home/ml/users/ksinha4/mlp/comp424_final_project/submissions/comp424mcgill/final-project-a_team_name/world.py\", line 310, in step\n    raise ValueError(\nValueError: [INVALID:STEP] Not a valid step from [5 4] to [5 4] and put barrier at 0, with max steps = 4\n\nExecute Random Walk!\nAn exception raised. The traceback is as follows:\nTraceback (most recent call last):\n  File \"/home/ml/users/ksinha4/mlp/comp424_final_project/submissions/comp424mcgill/final-project-a_team_name/world.py\", line 310, in step\n    raise ValueError(\nValueError: [INVALID:STEP] Not a valid step from [6 3] to [6 3] and put barrier at 0, with max steps = 4\n\nExecute Random Walk!\n"}, {"student_agent_score": 2, "random_agent_score": 98, "student_agent_time": 0.004646778106689453, "random_agent_time": 0.009079217910766602, "board_size": 10, "swap_players": false, "run_out": "An exception raised. The traceback is as follows:\nTraceback (most recent call last):\n  File \"/home/ml/users/ksinha4/mlp/comp424_final_project/submissions/comp424mcgill/final-project-a_team_name/world.py\", line 310, in step\n    raise ValueError(\nValueError: [INVALID:STEP] Not a valid step from [7 5] to [7 5] and put barrier at 0, with max steps = 5\n\nExecute Random Walk!\nAn exception raised. The traceback is as follows:\nTraceback (most recent call last):\n  File \"/home/ml/users/ksinha4/mlp/comp424_final_project/submissions/comp424mcgill/final-project-a_team_name/world.py\", line 310, in step\n    raise ValueError(\nValueError: [INVALID:STEP] Not a valid step from [6 6] to [6 6] and put barrier at 0, with max steps = 5\n\nExecute Random Walk!\nAn exception raised. The traceback is as follows:\nTraceback (most recent call last):\n  File \"/home/ml/users/ksinha4/mlp/comp424_final_project/submissions/comp424mcgill/final-project-a_team_name/world.py\", line 310, in step\n    raise ValueError(\nValueError: [INVALID:STEP] Not a valid step from [7 8] to [7 8] and put barrier at 0, with max steps = 5\n\nExecute Random Walk!\nAn exception raised. The traceback is as follows:\nTraceback (most recent call last):\n  File \"/home/ml/users/ksinha4/mlp/comp424_final_project/submissions/comp424mcgill/final-project-a_team_name/world.py\", line 310, in step\n    raise ValueError(\nValueError: [INVALID:STEP] Not a valid step from [7 8] to [7 8] and put barrier at 0, with max steps = 5\n\nExecute Random Walk!\n"}, {"student_agent_score": 1, "random_agent_score": 48, "student_agent_time": 0.0030531883239746094, "random_agent_time": 0.0027167797088623047, "board_size": 7, "swap_players": true, "run_out": "An exception raised. The traceback is as follows:\nTraceback (most recent call last):\n  File \"/home/ml/users/ksinha4/mlp/comp424_final_project/submissions/comp424mcgill/final-project-a_team_name/world.py\", line 310, in step\n    raise ValueError(\nValueError: [INVALID:STEP] Not a valid step from [2 3] to [2 3] and put barrier at 0, with max steps = 4\n\nExecute Random Walk!\nAn exception raised. The traceback is as follows:\nTraceback (most recent call last):\n  File \"/home/ml/users/ksinha4/mlp/comp424_final_project/submissions/comp424mcgill/final-project-a_team_name/world.py\", line 310, in step\n    raise ValueError(\nValueError: [INVALID:STEP] Not a valid step from [5 4] to [5 4] and put barrier at 0, with max steps = 4\n\nExecute Random Walk!\nAn exception raised. The traceback is as follows:\nTraceback (most recent call last):\n  File \"/home/ml/users/ksinha4/mlp/comp424_final_project/submissions/comp424mcgill/final-project-a_team_name/world.py\", line 310, in step\n    raise ValueError(\nValueError: [INVALID:STEP] Not a valid step from [6 3] to [6 3] and put barrier at 0, with max steps = 4\n\nExecute Random Walk!\n"}, {"student_agent_score": 1, "random_agent_score": 48, "student_agent_time": 0.004666566848754883, "random_agent_time": 0.002865314483642578, "board_size": 7, "swap_players": false, "run_out": "An exception raised. The traceback is as follows:\nTraceback (most recent call last):\n  File \"/home/ml/users/ksinha4/mlp/comp424_final_project/submissions/comp424mcgill/final-project-a_team_name/world.py\", line 310, in step\n    raise ValueError(\nValueError: [INVALID:STEP] Not a valid step from [4 3] to [4 3] and put barrier at 0, with max steps = 4\n\nExecute Random Walk!\nAn exception raised. The traceback is as follows:\nTraceback (most recent call last):\n  File \"/home/ml/users/ksinha4/mlp/comp424_final_project/submissions/comp424mcgill/final-project-a_team_name/world.py\", line 310, in step\n    raise ValueError(\nValueError: [INVALID:STEP] Not a valid step from [4 2] to [4 2] and put barrier at 0, with max steps = 4\n\nExecute Random Walk!\nAn exception raised. The traceback is as follows:\nTraceback (most recent call last):\n  File \"/home/ml/users/ksinha4/mlp/comp424_final_project/submissions/comp424mcgill/final-project-a_team_name/world.py\", line 310, in step\n    raise ValueError(\nValueError: [INVALID:STEP] Not a valid step from [4 3] to [4 3] and put barrier at 0, with max steps = 4\n\nExecute Random Walk!\nAn exception raised. The traceback is as follows:\nTraceback (most recent call last):\n  File \"/home/ml/users/ksinha4/mlp/comp424_final_project/submissions/comp424mcgill/final-project-a_team_name/world.py\", line 310, in step\n    raise ValueError(\nValueError: [INVALID:STEP] Not a valid step from [5 4] to [5 4] and put barrier at 0, with max steps = 4\n\nExecute Random Walk!\nAn exception raised. The traceback is as follows:\nTraceback (most recent call last):\n  File \"/home/ml/users/ksinha4/mlp/comp424_final_project/submissions/comp424mcgill/final-project-a_team_name/world.py\", line 310, in step\n    raise ValueError(\nValueError: [INVALID:STEP] Not a valid step from [6 3] to [6 3] and put barrier at 0, with max steps = 4\n\nExecute Random Walk!\n"}, {"student_agent_score": 2, "random_agent_score": 98, "student_agent_time": 0.007941961288452148, "random_agent_time": 0.007010936737060547, "board_size": 10, "swap_players": false, "run_out": "An exception raised. The traceback is as follows:\nTraceback (most recent call last):\n  File \"/home/ml/users/ksinha4/mlp/comp424_final_project/submissions/comp424mcgill/final-project-a_team_name/world.py\", line 310, in step\n    raise ValueError(\nValueError: [INVALID:STEP] Not a valid step from [7 5] to [7 5] and put barrier at 0, with max steps = 5\n\nExecute Random Walk!\nAn exception raised. The traceback is as follows:\nTraceback (most recent call last):\n  File \"/home/ml/users/ksinha4/mlp/comp424_final_project/submissions/comp424mcgill/final-project-a_team_name/world.py\", line 310, in step\n    raise ValueError(\nValueError: [INVALID:STEP] Not a valid step from [6 6] to [6 6] and put barrier at 0, with max steps = 5\n\nExecute Random Walk!\nAn exception raised. The traceback is as follows:\nTraceback (most recent call last):\n  File \"/home/ml/users/ksinha4/mlp/comp424_final_project/submissions/comp424mcgill/final-project-a_team_name/world.py\", line 310, in step\n    raise ValueError(\nValueError: [INVALID:STEP] Not a valid step from [7 8] to [7 8] and put barrier at 0, with max steps = 5\n\nExecute Random Walk!\nAn exception raised. The traceback is as follows:\nTraceback (most recent call last):\n  File \"/home/ml/users/ksinha4/mlp/comp424_final_project/submissions/comp424mcgill/final-project-a_team_name/world.py\", line 310, in step\n    raise ValueError(\nValueError: [INVALID:STEP] Not a valid step from [7 8] to [7 8] and put barrier at 0, with max steps = 5\n\nExecute Random Walk!\n"}, {"student_agent_score": 1, "random_agent_score": 48, "student_agent_time": 0.0029397010803222656, "random_agent_time": 0.0029277801513671875, "board_size": 7, "swap_players": true, "run_out": "An exception raised. The traceback is as follows:\nTraceback (most recent call last):\n  File \"/home/ml/users/ksinha4/mlp/comp424_final_project/submissions/comp424mcgill/final-project-a_team_name/world.py\", line 310, in step\n    raise ValueError(\nValueError: [INVALID:STEP] Not a valid step from [2 3] to [2 3] and put barrier at 0, with max steps = 4\n\nExecute Random Walk!\nAn exception raised. The traceback is as follows:\nTraceback (most recent call last):\n  File \"/home/ml/users/ksinha4/mlp/comp424_final_project/submissions/comp424mcgill/final-project-a_team_name/world.py\", line 310, in step\n    raise ValueError(\nValueError: [INVALID:STEP] Not a valid step from [5 4] to [5 4] and put barrier at 0, with max steps = 4\n\nExecute Random Walk!\nAn exception raised. The traceback is as follows:\nTraceback (most recent call last):\n  File \"/home/ml/users/ksinha4/mlp/comp424_final_project/submissions/comp424mcgill/final-project-a_team_name/world.py\", line 310, in step\n    raise ValueError(\nValueError: [INVALID:STEP] Not a valid step from [6 3] to [6 3] and put barrier at 0, with max steps = 4\n\nExecute Random Walk!\n"}, {"student_agent_score": 1, "random_agent_score": 48, "student_agent_time": 0.004286766052246094, "random_agent_time": 0.0023453235626220703, "board_size": 7, "swap_players": false, "run_out": "An exception raised. The traceback is as follows:\nTraceback (most recent call last):\n  File \"/home/ml/users/ksinha4/mlp/comp424_final_project/submissions/comp424mcgill/final-project-a_team_name/world.py\", line 310, in step\n    raise ValueError(\nValueError: [INVALID:STEP] Not a valid step from [4 3] to [4 3] and put barrier at 0, with max steps = 4\n\nExecute Random Walk!\nAn exception raised. The traceback is as follows:\nTraceback (most recent call last):\n  File \"/home/ml/users/ksinha4/mlp/comp424_final_project/submissions/comp424mcgill/final-project-a_team_name/world.py\", line 310, in step\n    raise ValueError(\nValueError: [INVALID:STEP] Not a valid step from [4 2] to [4 2] and put barrier at 0, with max steps = 4\n\nExecute Random Walk!\nAn exception raised. The traceback is as follows:\nTraceback (most recent call last):\n  File \"/home/ml/users/ksinha4/mlp/comp424_final_project/submissions/comp424mcgill/final-project-a_team_name/world.py\", line 310, in step\n    raise ValueError(\nValueError: [INVALID:STEP] Not a valid step from [4 3] to [4 3] and put barrier at 0, with max steps = 4\n\nExecute Random Walk!\nAn exception raised. The traceback is as follows:\nTraceback (most recent call last):\n  File \"/home/ml/users/ksinha4/mlp/comp424_final_project/submissions/comp424mcgill/final-project-a_team_name/world.py\", line 310, in step\n    raise ValueError(\nValueError: [INVALID:STEP] Not a valid step from [5 4] to [5 4] and put barrier at 0, with max steps = 4\n\nExecute Random Walk!\nAn exception raised. The traceback is as follows:\nTraceback (most recent call last):\n  File \"/home/ml/users/ksinha4/mlp/comp424_final_project/submissions/comp424mcgill/final-project-a_team_name/world.py\", line 310, in step\n    raise ValueError(\nValueError: [INVALID:STEP] Not a valid step from [6 3] to [6 3] and put barrier at 0, with max steps = 4\n\nExecute Random Walk!\n"}, {"student_agent_score": 2, "random_agent_score": 79, "student_agent_time": 0.0033092498779296875, "random_agent_time": 0.0032820701599121094, "board_size": 9, "swap_players": false, "run_out": "An exception raised. The traceback is as follows:\nTraceback (most recent call last):\n  File \"/home/ml/users/ksinha4/mlp/comp424_final_project/submissions/comp424mcgill/final-project-a_team_name/world.py\", line 310, in step\n    raise ValueError(\nValueError: [INVALID:STEP] Not a valid step from [5 4] to [5 4] and put barrier at 0, with max steps = 5\n\nExecute Random Walk!\nAn exception raised. The traceback is as follows:\nTraceback (most recent call last):\n  File \"/home/ml/users/ksinha4/mlp/comp424_final_project/submissions/comp424mcgill/final-project-a_team_name/world.py\", line 310, in step\n    raise ValueError(\nValueError: [INVALID:STEP] Not a valid step from [5 3] to [5 3] and put barrier at 0, with max steps = 5\n\nExecute Random Walk!\n"}, {"student_agent_score": 99, "random_agent_score": 1, "student_agent_time": 0.0008411407470703125, "random_agent_time": 0.0010559558868408203, "board_size": 10, "swap_players": true, "run_out": ""}, {"student_agent_score": 63, "random_agent_score": 1, "student_agent_time": 0.002483844757080078, "random_agent_time": 0.002359151840209961, "board_size": 8, "swap_players": true, "run_out": "An exception raised. The traceback is as follows:\nTraceback (most recent call last):\n  File \"/home/ml/users/ksinha4/mlp/comp424_final_project/submissions/comp424mcgill/final-project-a_team_name/world.py\", line 310, in step\n    raise ValueError(\nValueError: [INVALID:STEP] Not a valid step from [5 5] to [5 5] and put barrier at 0, with max steps = 4\n\nExecute Random Walk!\nAn exception raised. The traceback is as follows:\nTraceback (most recent call last):\n  File \"/home/ml/users/ksinha4/mlp/comp424_final_project/submissions/comp424mcgill/final-project-a_team_name/world.py\", line 310, in step\n    raise ValueError(\nValueError: [INVALID:STEP] Not a valid step from [5 4] to [5 4] and put barrier at 0, with max steps = 4\n\nExecute Random Walk!\nAn exception raised. The traceback is as follows:\nTraceback (most recent call last):\n  File \"/home/ml/users/ksinha4/mlp/comp424_final_project/submissions/comp424mcgill/final-project-a_team_name/world.py\", line 310, in step\n    raise ValueError(\nValueError: [INVALID:STEP] Not a valid step from [5 4] to [5 4] and put barrier at 0, with max steps = 4\n\nExecute Random Walk!\n"}, {"student_agent_score": 1, "random_agent_score": 48, "student_agent_time": 0.0054666996002197266, "random_agent_time": 0.0023369789123535156, "board_size": 7, "swap_players": false, "run_out": "An exception raised. The traceback is as follows:\nTraceback (most recent call last):\n  File \"/home/ml/users/ksinha4/mlp/comp424_final_project/submissions/comp424mcgill/final-project-a_team_name/world.py\", line 310, in step\n    raise ValueError(\nValueError: [INVALID:STEP] Not a valid step from [4 3] to [4 3] and put barrier at 0, with max steps = 4\n\nExecute Random Walk!\nAn exception raised. The traceback is as follows:\nTraceback (most recent call last):\n  File \"/home/ml/users/ksinha4/mlp/comp424_final_project/submissions/comp424mcgill/final-project-a_team_name/world.py\", line 310, in step\n    raise ValueError(\nValueError: [INVALID:STEP] Not a valid step from [4 2] to [4 2] and put barrier at 0, with max steps = 4\n\nExecute Random Walk!\nAn exception raised. The traceback is as follows:\nTraceback (most recent call last):\n  File \"/home/ml/users/ksinha4/mlp/comp424_final_project/submissions/comp424mcgill/final-project-a_team_name/world.py\", line 310, in step\n    raise ValueError(\nValueError: [INVALID:STEP] Not a valid step from [4 3] to [4 3] and put barrier at 0, with max steps = 4\n\nExecute Random Walk!\nAn exception raised. The traceback is as follows:\nTraceback (most recent call last):\n  File \"/home/ml/users/ksinha4/mlp/comp424_final_project/submissions/comp424mcgill/final-project-a_team_name/world.py\", line 310, in step\n    raise ValueError(\nValueError: [INVALID:STEP] Not a valid step from [5 4] to [5 4] and put barrier at 0, with max steps = 4\n\nExecute Random Walk!\nAn exception raised. The traceback is as follows:\nTraceback (most recent call last):\n  File \"/home/ml/users/ksinha4/mlp/comp424_final_project/submissions/comp424mcgill/final-project-a_team_name/world.py\", line 310, in step\n    raise ValueError(\nValueError: [INVALID:STEP] Not a valid step from [6 3] to [6 3] and put barrier at 0, with max steps = 4\n\nExecute Random Walk!\n"}, {"student_agent_score": 99, "random_agent_score": 1, "student_agent_time": 0.0003628730773925781, "random_agent_time": 0.0012106895446777344, "board_size": 10, "swap_players": true, "run_out": ""}, {"student_agent_score": 1, "random_agent_score": 48, "student_agent_time": 0.0039408206939697266, "random_agent_time": 0.0021545886993408203, "board_size": 7, "swap_players": false, "run_out": "An exception raised. The traceback is as follows:\nTraceback (most recent call last):\n  File \"/home/ml/users/ksinha4/mlp/comp424_final_project/submissions/comp424mcgill/final-project-a_team_name/world.py\", line 310, in step\n    raise ValueError(\nValueError: [INVALID:STEP] Not a valid step from [4 3] to [4 3] and put barrier at 0, with max steps = 4\n\nExecute Random Walk!\nAn exception raised. The traceback is as follows:\nTraceback (most recent call last):\n  File \"/home/ml/users/ksinha4/mlp/comp424_final_project/submissions/comp424mcgill/final-project-a_team_name/world.py\", line 310, in step\n    raise ValueError(\nValueError: [INVALID:STEP] Not a valid step from [4 2] to [4 2] and put barrier at 0, with max steps = 4\n\nExecute Random Walk!\nAn exception raised. The traceback is as follows:\nTraceback (most recent call last):\n  File \"/home/ml/users/ksinha4/mlp/comp424_final_project/submissions/comp424mcgill/final-project-a_team_name/world.py\", line 310, in step\n    raise ValueError(\nValueError: [INVALID:STEP] Not a valid step from [4 3] to [4 3] and put barrier at 0, with max steps = 4\n\nExecute Random Walk!\nAn exception raised. The traceback is as follows:\nTraceback (most recent call last):\n  File \"/home/ml/users/ksinha4/mlp/comp424_final_project/submissions/comp424mcgill/final-project-a_team_name/world.py\", line 310, in step\n    raise ValueError(\nValueError: [INVALID:STEP] Not a valid step from [5 4] to [5 4] and put barrier at 0, with max steps = 4\n\nExecute Random Walk!\nAn exception raised. The traceback is as follows:\nTraceback (most recent call last):\n  File \"/home/ml/users/ksinha4/mlp/comp424_final_project/submissions/comp424mcgill/final-project-a_team_name/world.py\", line 310, in step\n    raise ValueError(\nValueError: [INVALID:STEP] Not a valid step from [6 3] to [6 3] and put barrier at 0, with max steps = 4\n\nExecute Random Walk!\n"}, {"student_agent_score": 1, "random_agent_score": 48, "student_agent_time": 0.0038628578186035156, "random_agent_time": 0.0025925636291503906, "board_size": 7, "swap_players": true, "run_out": "An exception raised. The traceback is as follows:\nTraceback (most recent call last):\n  File \"/home/ml/users/ksinha4/mlp/comp424_final_project/submissions/comp424mcgill/final-project-a_team_name/world.py\", line 310, in step\n    raise ValueError(\nValueError: [INVALID:STEP] Not a valid step from [2 3] to [2 3] and put barrier at 0, with max steps = 4\n\nExecute Random Walk!\nAn exception raised. The traceback is as follows:\nTraceback (most recent call last):\n  File \"/home/ml/users/ksinha4/mlp/comp424_final_project/submissions/comp424mcgill/final-project-a_team_name/world.py\", line 310, in step\n    raise ValueError(\nValueError: [INVALID:STEP] Not a valid step from [5 4] to [5 4] and put barrier at 0, with max steps = 4\n\nExecute Random Walk!\nAn exception raised. The traceback is as follows:\nTraceback (most recent call last):\n  File \"/home/ml/users/ksinha4/mlp/comp424_final_project/submissions/comp424mcgill/final-project-a_team_name/world.py\", line 310, in step\n    raise ValueError(\nValueError: [INVALID:STEP] Not a valid step from [6 3] to [6 3] and put barrier at 0, with max steps = 4\n\nExecute Random Walk!\n"}, {"student_agent_score": 1, "random_agent_score": 48, "student_agent_time": 0.0026237964630126953, "random_agent_time": 0.0029761791229248047, "board_size": 7, "swap_players": true, "run_out": "An exception raised. The traceback is as follows:\nTraceback (most recent call last):\n  File \"/home/ml/users/ksinha4/mlp/comp424_final_project/submissions/comp424mcgill/final-project-a_team_name/world.py\", line 310, in step\n    raise ValueError(\nValueError: [INVALID:STEP] Not a valid step from [2 3] to [2 3] and put barrier at 0, with max steps = 4\n\nExecute Random Walk!\nAn exception raised. The traceback is as follows:\nTraceback (most recent call last):\n  File \"/home/ml/users/ksinha4/mlp/comp424_final_project/submissions/comp424mcgill/final-project-a_team_name/world.py\", line 310, in step\n    raise ValueError(\nValueError: [INVALID:STEP] Not a valid step from [5 4] to [5 4] and put barrier at 0, with max steps = 4\n\nExecute Random Walk!\nAn exception raised. The traceback is as follows:\nTraceback (most recent call last):\n  File \"/home/ml/users/ksinha4/mlp/comp424_final_project/submissions/comp424mcgill/final-project-a_team_name/world.py\", line 310, in step\n    raise ValueError(\nValueError: [INVALID:STEP] Not a valid step from [6 3] to [6 3] and put barrier at 0, with max steps = 4\n\nExecute Random Walk!\n"}, {"student_agent_score": 1, "random_agent_score": 63, "student_agent_time": 0.003386974334716797, "random_agent_time": 0.002522706985473633, "board_size": 8, "swap_players": false, "run_out": "An exception raised. The traceback is as follows:\nTraceback (most recent call last):\n  File \"/home/ml/users/ksinha4/mlp/comp424_final_project/submissions/comp424mcgill/final-project-a_team_name/world.py\", line 310, in step\n    raise ValueError(\nValueError: [INVALID:STEP] Not a valid step from [2 2] to [2 2] and put barrier at 0, with max steps = 4\n\nExecute Random Walk!\nAn exception raised. The traceback is as follows:\nTraceback (most recent call last):\n  File \"/home/ml/users/ksinha4/mlp/comp424_final_project/submissions/comp424mcgill/final-project-a_team_name/world.py\", line 310, in step\n    raise ValueError(\nValueError: [INVALID:STEP] Not a valid step from [3 1] to [3 1] and put barrier at 0, with max steps = 4\n\nExecute Random Walk!\nAn exception raised. The traceback is as follows:\nTraceback (most recent call last):\n  File \"/home/ml/users/ksinha4/mlp/comp424_final_project/submissions/comp424mcgill/final-project-a_team_name/world.py\", line 310, in step\n    raise ValueError(\nValueError: [INVALID:STEP] Not a valid step from [3 0] to [3 0] and put barrier at 0, with max steps = 4\n\nExecute Random Walk!\nAn exception raised. The traceback is as follows:\nTraceback (most recent call last):\n  File \"/home/ml/users/ksinha4/mlp/comp424_final_project/submissions/comp424mcgill/final-project-a_team_name/world.py\", line 310, in step\n    raise ValueError(\nValueError: [INVALID:STEP] Not a valid step from [6 1] to [6 1] and put barrier at 0, with max steps = 4\n\nExecute Random Walk!\n"}, {"student_agent_score": 1, "random_agent_score": 48, "student_agent_time": 0.004828214645385742, "random_agent_time": 0.0031480789184570312, "board_size": 7, "swap_players": false, "run_out": "An exception raised. The traceback is as follows:\nTraceback (most recent call last):\n  File \"/home/ml/users/ksinha4/mlp/comp424_final_project/submissions/comp424mcgill/final-project-a_team_name/world.py\", line 310, in step\n    raise ValueError(\nValueError: [INVALID:STEP] Not a valid step from [4 3] to [4 3] and put barrier at 0, with max steps = 4\n\nExecute Random Walk!\nAn exception raised. The traceback is as follows:\nTraceback (most recent call last):\n  File \"/home/ml/users/ksinha4/mlp/comp424_final_project/submissions/comp424mcgill/final-project-a_team_name/world.py\", line 310, in step\n    raise ValueError(\nValueError: [INVALID:STEP] Not a valid step from [4 2] to [4 2] and put barrier at 0, with max steps = 4\n\nExecute Random Walk!\nAn exception raised. The traceback is as follows:\nTraceback (most recent call last):\n  File \"/home/ml/users/ksinha4/mlp/comp424_final_project/submissions/comp424mcgill/final-project-a_team_name/world.py\", line 310, in step\n    raise ValueError(\nValueError: [INVALID:STEP] Not a valid step from [4 3] to [4 3] and put barrier at 0, with max steps = 4\n\nExecute Random Walk!\nAn exception raised. The traceback is as follows:\nTraceback (most recent call last):\n  File \"/home/ml/users/ksinha4/mlp/comp424_final_project/submissions/comp424mcgill/final-project-a_team_name/world.py\", line 310, in step\n    raise ValueError(\nValueError: [INVALID:STEP] Not a valid step from [5 4] to [5 4] and put barrier at 0, with max steps = 4\n\nExecute Random Walk!\nAn exception raised. The traceback is as follows:\nTraceback (most recent call last):\n  File \"/home/ml/users/ksinha4/mlp/comp424_final_project/submissions/comp424mcgill/final-project-a_team_name/world.py\", line 310, in step\n    raise ValueError(\nValueError: [INVALID:STEP] Not a valid step from [6 3] to [6 3] and put barrier at 0, with max steps = 4\n\nExecute Random Walk!\n"}, {"student_agent_score": 1, "random_agent_score": 48, "student_agent_time": 0.002540111541748047, "random_agent_time": 0.002104043960571289, "board_size": 7, "swap_players": true, "run_out": "An exception raised. The traceback is as follows:\nTraceback (most recent call last):\n  File \"/home/ml/users/ksinha4/mlp/comp424_final_project/submissions/comp424mcgill/final-project-a_team_name/world.py\", line 310, in step\n    raise ValueError(\nValueError: [INVALID:STEP] Not a valid step from [2 3] to [2 3] and put barrier at 0, with max steps = 4\n\nExecute Random Walk!\nAn exception raised. The traceback is as follows:\nTraceback (most recent call last):\n  File \"/home/ml/users/ksinha4/mlp/comp424_final_project/submissions/comp424mcgill/final-project-a_team_name/world.py\", line 310, in step\n    raise ValueError(\nValueError: [INVALID:STEP] Not a valid step from [5 4] to [5 4] and put barrier at 0, with max steps = 4\n\nExecute Random Walk!\nAn exception raised. The traceback is as follows:\nTraceback (most recent call last):\n  File \"/home/ml/users/ksinha4/mlp/comp424_final_project/submissions/comp424mcgill/final-project-a_team_name/world.py\", line 310, in step\n    raise ValueError(\nValueError: [INVALID:STEP] Not a valid step from [6 3] to [6 3] and put barrier at 0, with max steps = 4\n\nExecute Random Walk!\n"}, {"student_agent_score": 117, "random_agent_score": 1, "student_agent_time": 0.008948564529418945, "random_agent_time": 0.01084589958190918, "board_size": 11, "swap_players": false, "run_out": "An exception raised. The traceback is as follows:\nTraceback (most recent call last):\n  File \"/home/ml/users/ksinha4/mlp/comp424_final_project/submissions/comp424mcgill/final-project-a_team_name/world.py\", line 310, in step\n    raise ValueError(\nValueError: [INVALID:STEP] Not a valid step from [1 7] to [1 7] and put barrier at 0, with max steps = 6\n\nExecute Random Walk!\nAn exception raised. The traceback is as follows:\nTraceback (most recent call last):\n  File \"/home/ml/users/ksinha4/mlp/comp424_final_project/submissions/comp424mcgill/final-project-a_team_name/world.py\", line 310, in step\n    raise ValueError(\nValueError: [INVALID:STEP] Not a valid step from [1 8] to [1 8] and put barrier at 0, with max steps = 6\n\nExecute Random Walk!\nAn exception raised. The traceback is as follows:\nTraceback (most recent call last):\n  File \"/home/ml/users/ksinha4/mlp/comp424_final_project/submissions/comp424mcgill/final-project-a_team_name/world.py\", line 310, in step\n    raise ValueError(\nValueError: [INVALID:STEP] Not a valid step from [1 6] to [1 6] and put barrier at 0, with max steps = 6\n\nExecute Random Walk!\nAn exception raised. The traceback is as follows:\nTraceback (most recent call last):\n  File \"/home/ml/users/ksinha4/mlp/comp424_final_project/submissions/comp424mcgill/final-project-a_team_name/world.py\", line 310, in step\n    raise ValueError(\nValueError: [INVALID:STEP] Not a valid step from [3 3] to [3 3] and put barrier at 0, with max steps = 6\n\nExecute Random Walk!\nAn exception raised. The traceback is as follows:\nTraceback (most recent call last):\n  File \"/home/ml/users/ksinha4/mlp/comp424_final_project/submissions/comp424mcgill/final-project-a_team_name/world.py\", line 310, in step\n    raise ValueError(\nValueError: [INVALID:STEP] Not a valid step from [3 4] to [3 4] and put barrier at 0, with max steps = 6\n\nExecute Random Walk!\nAn exception raised. The traceback is as follows:\nTraceback (most recent call last):\n  File \"/home/ml/users/ksinha4/mlp/comp424_final_project/submissions/comp424mcgill/final-project-a_team_name/world.py\", line 310, in step\n    raise ValueError(\nValueError: [INVALID:STEP] Not a valid step from [3 4] to [3 4] and put barrier at 0, with max steps = 6\n\nExecute Random Walk!\nAn exception raised. The traceback is as follows:\nTraceback (most recent call last):\n  File \"/home/ml/users/ksinha4/mlp/comp424_final_project/submissions/comp424mcgill/final-project-a_team_name/world.py\", line 310, in step\n    raise ValueError(\nValueError: [INVALID:STEP] Not a valid step from [4 4] to [4 4] and put barrier at 0, with max steps = 6\n\nExecute Random Walk!\nAn exception raised. The traceback is as follows:\nTraceback (most recent call last):\n  File \"/home/ml/users/ksinha4/mlp/comp424_final_project/submissions/comp424mcgill/final-project-a_team_name/world.py\", line 310, in step\n    raise ValueError(\nValueError: [INVALID:STEP] Not a valid step from [4 4] to [4 4] and put barrier at 0, with max steps = 6\n\nExecute Random Walk!\n"}, {"student_agent_score": 99, "random_agent_score": 1, "student_agent_time": 0.0003619194030761719, "random_agent_time": 0.0010955333709716797, "board_size": 10, "swap_players": true, "run_out": ""}, {"student_agent_score": 1, "random_agent_score": 48, "student_agent_time": 0.002597808837890625, "random_agent_time": 0.0024662017822265625, "board_size": 7, "swap_players": true, "run_out": "An exception raised. The traceback is as follows:\nTraceback (most recent call last):\n  File \"/home/ml/users/ksinha4/mlp/comp424_final_project/submissions/comp424mcgill/final-project-a_team_name/world.py\", line 310, in step\n    raise ValueError(\nValueError: [INVALID:STEP] Not a valid step from [2 3] to [2 3] and put barrier at 0, with max steps = 4\n\nExecute Random Walk!\nAn exception raised. The traceback is as follows:\nTraceback (most recent call last):\n  File \"/home/ml/users/ksinha4/mlp/comp424_final_project/submissions/comp424mcgill/final-project-a_team_name/world.py\", line 310, in step\n    raise ValueError(\nValueError: [INVALID:STEP] Not a valid step from [5 4] to [5 4] and put barrier at 0, with max steps = 4\n\nExecute Random Walk!\nAn exception raised. The traceback is as follows:\nTraceback (most recent call last):\n  File \"/home/ml/users/ksinha4/mlp/comp424_final_project/submissions/comp424mcgill/final-project-a_team_name/world.py\", line 310, in step\n    raise ValueError(\nValueError: [INVALID:STEP] Not a valid step from [6 3] to [6 3] and put barrier at 0, with max steps = 4\n\nExecute Random Walk!\n"}, {"student_agent_score": 1, "random_agent_score": 48, "student_agent_time": 0.0036559104919433594, "random_agent_time": 0.0021245479583740234, "board_size": 7, "swap_players": false, "run_out": "An exception raised. The traceback is as follows:\nTraceback (most recent call last):\n  File \"/home/ml/users/ksinha4/mlp/comp424_final_project/submissions/comp424mcgill/final-project-a_team_name/world.py\", line 310, in step\n    raise ValueError(\nValueError: [INVALID:STEP] Not a valid step from [4 3] to [4 3] and put barrier at 0, with max steps = 4\n\nExecute Random Walk!\nAn exception raised. The traceback is as follows:\nTraceback (most recent call last):\n  File \"/home/ml/users/ksinha4/mlp/comp424_final_project/submissions/comp424mcgill/final-project-a_team_name/world.py\", line 310, in step\n    raise ValueError(\nValueError: [INVALID:STEP] Not a valid step from [4 2] to [4 2] and put barrier at 0, with max steps = 4\n\nExecute Random Walk!\nAn exception raised. The traceback is as follows:\nTraceback (most recent call last):\n  File \"/home/ml/users/ksinha4/mlp/comp424_final_project/submissions/comp424mcgill/final-project-a_team_name/world.py\", line 310, in step\n    raise ValueError(\nValueError: [INVALID:STEP] Not a valid step from [4 3] to [4 3] and put barrier at 0, with max steps = 4\n\nExecute Random Walk!\nAn exception raised. The traceback is as follows:\nTraceback (most recent call last):\n  File \"/home/ml/users/ksinha4/mlp/comp424_final_project/submissions/comp424mcgill/final-project-a_team_name/world.py\", line 310, in step\n    raise ValueError(\nValueError: [INVALID:STEP] Not a valid step from [5 4] to [5 4] and put barrier at 0, with max steps = 4\n\nExecute Random Walk!\nAn exception raised. The traceback is as follows:\nTraceback (most recent call last):\n  File \"/home/ml/users/ksinha4/mlp/comp424_final_project/submissions/comp424mcgill/final-project-a_team_name/world.py\", line 310, in step\n    raise ValueError(\nValueError: [INVALID:STEP] Not a valid step from [6 3] to [6 3] and put barrier at 0, with max steps = 4\n\nExecute Random Walk!\n"}, {"student_agent_score": 1, "random_agent_score": 48, "student_agent_time": 0.0035278797149658203, "random_agent_time": 0.0025408267974853516, "board_size": 7, "swap_players": false, "run_out": "An exception raised. The traceback is as follows:\nTraceback (most recent call last):\n  File \"/home/ml/users/ksinha4/mlp/comp424_final_project/submissions/comp424mcgill/final-project-a_team_name/world.py\", line 310, in step\n    raise ValueError(\nValueError: [INVALID:STEP] Not a valid step from [4 3] to [4 3] and put barrier at 0, with max steps = 4\n\nExecute Random Walk!\nAn exception raised. The traceback is as follows:\nTraceback (most recent call last):\n  File \"/home/ml/users/ksinha4/mlp/comp424_final_project/submissions/comp424mcgill/final-project-a_team_name/world.py\", line 310, in step\n    raise ValueError(\nValueError: [INVALID:STEP] Not a valid step from [4 2] to [4 2] and put barrier at 0, with max steps = 4\n\nExecute Random Walk!\nAn exception raised. The traceback is as follows:\nTraceback (most recent call last):\n  File \"/home/ml/users/ksinha4/mlp/comp424_final_project/submissions/comp424mcgill/final-project-a_team_name/world.py\", line 310, in step\n    raise ValueError(\nValueError: [INVALID:STEP] Not a valid step from [4 3] to [4 3] and put barrier at 0, with max steps = 4\n\nExecute Random Walk!\nAn exception raised. The traceback is as follows:\nTraceback (most recent call last):\n  File \"/home/ml/users/ksinha4/mlp/comp424_final_project/submissions/comp424mcgill/final-project-a_team_name/world.py\", line 310, in step\n    raise ValueError(\nValueError: [INVALID:STEP] Not a valid step from [5 4] to [5 4] and put barrier at 0, with max steps = 4\n\nExecute Random Walk!\nAn exception raised. The traceback is as follows:\nTraceback (most recent call last):\n  File \"/home/ml/users/ksinha4/mlp/comp424_final_project/submissions/comp424mcgill/final-project-a_team_name/world.py\", line 310, in step\n    raise ValueError(\nValueError: [INVALID:STEP] Not a valid step from [6 3] to [6 3] and put barrier at 0, with max steps = 4\n\nExecute Random Walk!\n"}, {"student_agent_score": 1, "random_agent_score": 48, "student_agent_time": 0.0041887760162353516, "random_agent_time": 0.0023245811462402344, "board_size": 7, "swap_players": false, "run_out": "An exception raised. The traceback is as follows:\nTraceback (most recent call last):\n  File \"/home/ml/users/ksinha4/mlp/comp424_final_project/submissions/comp424mcgill/final-project-a_team_name/world.py\", line 310, in step\n    raise ValueError(\nValueError: [INVALID:STEP] Not a valid step from [4 3] to [4 3] and put barrier at 0, with max steps = 4\n\nExecute Random Walk!\nAn exception raised. The traceback is as follows:\nTraceback (most recent call last):\n  File \"/home/ml/users/ksinha4/mlp/comp424_final_project/submissions/comp424mcgill/final-project-a_team_name/world.py\", line 310, in step\n    raise ValueError(\nValueError: [INVALID:STEP] Not a valid step from [4 2] to [4 2] and put barrier at 0, with max steps = 4\n\nExecute Random Walk!\nAn exception raised. The traceback is as follows:\nTraceback (most recent call last):\n  File \"/home/ml/users/ksinha4/mlp/comp424_final_project/submissions/comp424mcgill/final-project-a_team_name/world.py\", line 310, in step\n    raise ValueError(\nValueError: [INVALID:STEP] Not a valid step from [4 3] to [4 3] and put barrier at 0, with max steps = 4\n\nExecute Random Walk!\nAn exception raised. The traceback is as follows:\nTraceback (most recent call last):\n  File \"/home/ml/users/ksinha4/mlp/comp424_final_project/submissions/comp424mcgill/final-project-a_team_name/world.py\", line 310, in step\n    raise ValueError(\nValueError: [INVALID:STEP] Not a valid step from [5 4] to [5 4] and put barrier at 0, with max steps = 4\n\nExecute Random Walk!\nAn exception raised. The traceback is as follows:\nTraceback (most recent call last):\n  File \"/home/ml/users/ksinha4/mlp/comp424_final_project/submissions/comp424mcgill/final-project-a_team_name/world.py\", line 310, in step\n    raise ValueError(\nValueError: [INVALID:STEP] Not a valid step from [6 3] to [6 3] and put barrier at 0, with max steps = 4\n\nExecute Random Walk!\n"}, {"student_agent_score": 1, "random_agent_score": 48, "student_agent_time": 0.0030956268310546875, "random_agent_time": 0.0015943050384521484, "board_size": 7, "swap_players": false, "run_out": "An exception raised. The traceback is as follows:\nTraceback (most recent call last):\n  File \"/home/ml/users/ksinha4/mlp/comp424_final_project/submissions/comp424mcgill/final-project-a_team_name/world.py\", line 310, in step\n    raise ValueError(\nValueError: [INVALID:STEP] Not a valid step from [4 3] to [4 3] and put barrier at 0, with max steps = 4\n\nExecute Random Walk!\nAn exception raised. The traceback is as follows:\nTraceback (most recent call last):\n  File \"/home/ml/users/ksinha4/mlp/comp424_final_project/submissions/comp424mcgill/final-project-a_team_name/world.py\", line 310, in step\n    raise ValueError(\nValueError: [INVALID:STEP] Not a valid step from [4 2] to [4 2] and put barrier at 0, with max steps = 4\n\nExecute Random Walk!\nAn exception raised. The traceback is as follows:\nTraceback (most recent call last):\n  File \"/home/ml/users/ksinha4/mlp/comp424_final_project/submissions/comp424mcgill/final-project-a_team_name/world.py\", line 310, in step\n    raise ValueError(\nValueError: [INVALID:STEP] Not a valid step from [4 3] to [4 3] and put barrier at 0, with max steps = 4\n\nExecute Random Walk!\nAn exception raised. The traceback is as follows:\nTraceback (most recent call last):\n  File \"/home/ml/users/ksinha4/mlp/comp424_final_project/submissions/comp424mcgill/final-project-a_team_name/world.py\", line 310, in step\n    raise ValueError(\nValueError: [INVALID:STEP] Not a valid step from [5 4] to [5 4] and put barrier at 0, with max steps = 4\n\nExecute Random Walk!\nAn exception raised. The traceback is as follows:\nTraceback (most recent call last):\n  File \"/home/ml/users/ksinha4/mlp/comp424_final_project/submissions/comp424mcgill/final-project-a_team_name/world.py\", line 310, in step\n    raise ValueError(\nValueError: [INVALID:STEP] Not a valid step from [6 3] to [6 3] and put barrier at 0, with max steps = 4\n\nExecute Random Walk!\n"}, {"student_agent_score": 120, "random_agent_score": 1, "student_agent_time": 0.0020799636840820312, "random_agent_time": 0.002614736557006836, "board_size": 11, "swap_players": true, "run_out": "An exception raised. The traceback is as follows:\nTraceback (most recent call last):\n  File \"/home/ml/users/ksinha4/mlp/comp424_final_project/submissions/comp424mcgill/final-project-a_team_name/world.py\", line 310, in step\n    raise ValueError(\nValueError: [INVALID:STEP] Not a valid step from [9 3] to [9 3] and put barrier at 0, with max steps = 6\n\nExecute Random Walk!\nAn exception raised. The traceback is as follows:\nTraceback (most recent call last):\n  File \"/home/ml/users/ksinha4/mlp/comp424_final_project/submissions/comp424mcgill/final-project-a_team_name/world.py\", line 310, in step\n    raise ValueError(\nValueError: [INVALID:STEP] Not a valid step from [9 3] to [9 3] and put barrier at 0, with max steps = 6\n\nExecute Random Walk!\n"}, {"student_agent_score": 117, "random_agent_score": 1, "student_agent_time": 0.006769657135009766, "random_agent_time": 0.0065801143646240234, "board_size": 11, "swap_players": false, "run_out": "An exception raised. The traceback is as follows:\nTraceback (most recent call last):\n  File \"/home/ml/users/ksinha4/mlp/comp424_final_project/submissions/comp424mcgill/final-project-a_team_name/world.py\", line 310, in step\n    raise ValueError(\nValueError: [INVALID:STEP] Not a valid step from [1 7] to [1 7] and put barrier at 0, with max steps = 6\n\nExecute Random Walk!\nAn exception raised. The traceback is as follows:\nTraceback (most recent call last):\n  File \"/home/ml/users/ksinha4/mlp/comp424_final_project/submissions/comp424mcgill/final-project-a_team_name/world.py\", line 310, in step\n    raise ValueError(\nValueError: [INVALID:STEP] Not a valid step from [1 8] to [1 8] and put barrier at 0, with max steps = 6\n\nExecute Random Walk!\nAn exception raised. The traceback is as follows:\nTraceback (most recent call last):\n  File \"/home/ml/users/ksinha4/mlp/comp424_final_project/submissions/comp424mcgill/final-project-a_team_name/world.py\", line 310, in step\n    raise ValueError(\nValueError: [INVALID:STEP] Not a valid step from [1 6] to [1 6] and put barrier at 0, with max steps = 6\n\nExecute Random Walk!\nAn exception raised. The traceback is as follows:\nTraceback (most recent call last):\n  File \"/home/ml/users/ksinha4/mlp/comp424_final_project/submissions/comp424mcgill/final-project-a_team_name/world.py\", line 310, in step\n    raise ValueError(\nValueError: [INVALID:STEP] Not a valid step from [3 3] to [3 3] and put barrier at 0, with max steps = 6\n\nExecute Random Walk!\nAn exception raised. The traceback is as follows:\nTraceback (most recent call last):\n  File \"/home/ml/users/ksinha4/mlp/comp424_final_project/submissions/comp424mcgill/final-project-a_team_name/world.py\", line 310, in step\n    raise ValueError(\nValueError: [INVALID:STEP] Not a valid step from [3 4] to [3 4] and put barrier at 0, with max steps = 6\n\nExecute Random Walk!\nAn exception raised. The traceback is as follows:\nTraceback (most recent call last):\n  File \"/home/ml/users/ksinha4/mlp/comp424_final_project/submissions/comp424mcgill/final-project-a_team_name/world.py\", line 310, in step\n    raise ValueError(\nValueError: [INVALID:STEP] Not a valid step from [3 4] to [3 4] and put barrier at 0, with max steps = 6\n\nExecute Random Walk!\nAn exception raised. The traceback is as follows:\nTraceback (most recent call last):\n  File \"/home/ml/users/ksinha4/mlp/comp424_final_project/submissions/comp424mcgill/final-project-a_team_name/world.py\", line 310, in step\n    raise ValueError(\nValueError: [INVALID:STEP] Not a valid step from [4 4] to [4 4] and put barrier at 0, with max steps = 6\n\nExecute Random Walk!\nAn exception raised. The traceback is as follows:\nTraceback (most recent call last):\n  File \"/home/ml/users/ksinha4/mlp/comp424_final_project/submissions/comp424mcgill/final-project-a_team_name/world.py\", line 310, in step\n    raise ValueError(\nValueError: [INVALID:STEP] Not a valid step from [4 4] to [4 4] and put barrier at 0, with max steps = 6\n\nExecute Random Walk!\n"}]}