{"num_games": 100, "student_agent_wins": [0, 0, 0, 0, 0, 0, 0, 1, 1, 0, 0, 0, 0, 0, 1, 1, 1, 0, 0, 0, 0, 0, 1, 1, 0, 1, 1, 0, 0, 0, 0, 0, 0, 0, 0, 0, 0, 0, 1, 0, 0, 0, 0, 1, 1, 0, 0, 0, 0, 0, 0, 1, 0, 0, 1, 0, 0, 0, 0, 0, 0, 0, 0, 1, 1, 0, 0, 0, 0, 0, 0, 1, 0, 0, 0, 0, 0, 0, 0, 1, 0, 0, 0, 1, 0, 0, 0, 0, 0, 0, 0, 0, 0, 0, 0, 0, 0, 0, 0, 1], "random_agent_wins": [1, 1, 1, 1, 1, 1, 1, 0, 0, 1, 1, 1, 1, 1, 0, 0, 0, 1, 1, 1, 1, 1, 0, 0, 1, 0, 0, 1, 1, 1, 1, 1, 1, 1, 1, 1, 1, 1, 0, 1, 1, 1, 1, 0, 0, 1, 1, 1, 1, 1, 1, 0, 1, 1, 0, 1, 1, 1, 1, 1, 1, 1, 1, 0, 0, 1, 1, 1, 1, 1, 1, 0, 1, 1, 1, 1, 1, 1, 1, 0, 1, 1, 1, 0, 1, 1, 1, 1, 1, 1, 1, 1, 1, 1, 1, 1, 1, 1, 1, 0], "student_agent_win_count": 20, "random_agent_win_count": 80, "student_agent_win_percentage": 0.2, "random_agent_win_percentage": 0.8, "student_agent_time_taken": 0.003980989456176758, "random_agent_time_taken": 0.0031376290321350098, "run_info": [{"student_agent_score": 1, "random_agent_score": 48, "student_agent_time": 0.0036139488220214844, "random_agent_time": 0.0026617050170898438, "board_size": 7, "swap_players": true, "run_out": "An exception raised. The traceback is as follows:\nTraceback (most recent call last):\n  File \"/home/ml/users/ksinha4/mlp/comp424_final_project/submissions/comp424mcgill/final-project-a_team_name/world.py\", line 310, in step\n    raise ValueError(\nValueError: [INVALID:STEP] Not a valid step from [2 3] to [2 3] and put barrier at 0, with max steps = 4\n\nExecute Random Walk!\nAn exception raised. The traceback is as follows:\nTraceback (most recent call last):\n  File \"/home/ml/users/ksinha4/mlp/comp424_final_project/submissions/comp424mcgill/final-project-a_team_name/world.py\", line 310, in step\n    raise ValueError(\nValueError: [INVALID:STEP] Not a valid step from [5 4] to [5 4] and put barrier at 0, with max steps = 4\n\nExecute Random Walk!\nAn exception raised. The traceback is as follows:\nTraceback (most recent call last):\n  File \"/home/ml/users/ksinha4/mlp/comp424_final_project/submissions/comp424mcgill/final-project-a_team_name/world.py\", line 310, in step\n    raise ValueError(\nValueError: [INVALID:STEP] Not a valid step from [6 3] to [6 3] and put barrier at 0, with max steps = 4\n\nExecute Random Walk!\n"}, {"student_agent_score": 1, "random_agent_score": 48, "student_agent_time": 0.005155086517333984, "random_agent_time": 0.0024607181549072266, "board_size": 7, "swap_players": false, "run_out": "An exception raised. The traceback is as follows:\nTraceback (most recent call last):\n  File \"/home/ml/users/ksinha4/mlp/comp424_final_project/submissions/comp424mcgill/final-project-a_team_name/world.py\", line 310, in step\n    raise ValueError(\nValueError: [INVALID:STEP] Not a valid step from [4 3] to [4 3] and put barrier at 0, with max steps = 4\n\nExecute Random Walk!\nAn exception raised. The traceback is as follows:\nTraceback (most recent call last):\n  File \"/home/ml/users/ksinha4/mlp/comp424_final_project/submissions/comp424mcgill/final-project-a_team_name/world.py\", line 310, in step\n    raise ValueError(\nValueError: [INVALID:STEP] Not a valid step from [4 2] to [4 2] and put barrier at 0, with max steps = 4\n\nExecute Random Walk!\nAn exception raised. The traceback is as follows:\nTraceback (most recent call last):\n  File \"/home/ml/users/ksinha4/mlp/comp424_final_project/submissions/comp424mcgill/final-project-a_team_name/world.py\", line 310, in step\n    raise ValueError(\nValueError: [INVALID:STEP] Not a valid step from [4 3] to [4 3] and put barrier at 0, with max steps = 4\n\nExecute Random Walk!\nAn exception raised. The traceback is as follows:\nTraceback (most recent call last):\n  File \"/home/ml/users/ksinha4/mlp/comp424_final_project/submissions/comp424mcgill/final-project-a_team_name/world.py\", line 310, in step\n    raise ValueError(\nValueError: [INVALID:STEP] Not a valid step from [5 4] to [5 4] and put barrier at 0, with max steps = 4\n\nExecute Random Walk!\nAn exception raised. The traceback is as follows:\nTraceback (most recent call last):\n  File \"/home/ml/users/ksinha4/mlp/comp424_final_project/submissions/comp424mcgill/final-project-a_team_name/world.py\", line 310, in step\n    raise ValueError(\nValueError: [INVALID:STEP] Not a valid step from [6 3] to [6 3] and put barrier at 0, with max steps = 4\n\nExecute Random Walk!\n"}, {"student_agent_score": 1, "random_agent_score": 35, "student_agent_time": 0.002648591995239258, "random_agent_time": 0.00341796875, "board_size": 6, "swap_players": true, "run_out": "An exception raised. The traceback is as follows:\nTraceback (most recent call last):\n  File \"/home/ml/users/ksinha4/mlp/comp424_final_project/submissions/comp424mcgill/final-project-a_team_name/world.py\", line 310, in step\n    raise ValueError(\nValueError: [INVALID:STEP] Not a valid step from [3 3] to [3 3] and put barrier at 0, with max steps = 3\n\nExecute Random Walk!\nAn exception raised. The traceback is as follows:\nTraceback (most recent call last):\n  File \"/home/ml/users/ksinha4/mlp/comp424_final_project/submissions/comp424mcgill/final-project-a_team_name/world.py\", line 310, in step\n    raise ValueError(\nValueError: [INVALID:STEP] Not a valid step from [3 3] to [3 3] and put barrier at 0, with max steps = 3\n\nExecute Random Walk!\n"}, {"student_agent_score": 1, "random_agent_score": 48, "student_agent_time": 0.004058361053466797, "random_agent_time": 0.003381013870239258, "board_size": 7, "swap_players": true, "run_out": "An exception raised. The traceback is as follows:\nTraceback (most recent call last):\n  File \"/home/ml/users/ksinha4/mlp/comp424_final_project/submissions/comp424mcgill/final-project-a_team_name/world.py\", line 310, in step\n    raise ValueError(\nValueError: [INVALID:STEP] Not a valid step from [2 3] to [2 3] and put barrier at 0, with max steps = 4\n\nExecute Random Walk!\nAn exception raised. The traceback is as follows:\nTraceback (most recent call last):\n  File \"/home/ml/users/ksinha4/mlp/comp424_final_project/submissions/comp424mcgill/final-project-a_team_name/world.py\", line 310, in step\n    raise ValueError(\nValueError: [INVALID:STEP] Not a valid step from [5 4] to [5 4] and put barrier at 0, with max steps = 4\n\nExecute Random Walk!\nAn exception raised. The traceback is as follows:\nTraceback (most recent call last):\n  File \"/home/ml/users/ksinha4/mlp/comp424_final_project/submissions/comp424mcgill/final-project-a_team_name/world.py\", line 310, in step\n    raise ValueError(\nValueError: [INVALID:STEP] Not a valid step from [6 3] to [6 3] and put barrier at 0, with max steps = 4\n\nExecute Random Walk!\n"}, {"student_agent_score": 2, "random_agent_score": 98, "student_agent_time": 0.006583452224731445, "random_agent_time": 0.006926774978637695, "board_size": 10, "swap_players": false, "run_out": "An exception raised. The traceback is as follows:\nTraceback (most recent call last):\n  File \"/home/ml/users/ksinha4/mlp/comp424_final_project/submissions/comp424mcgill/final-project-a_team_name/world.py\", line 310, in step\n    raise ValueError(\nValueError: [INVALID:STEP] Not a valid step from [7 5] to [7 5] and put barrier at 0, with max steps = 5\n\nExecute Random Walk!\nAn exception raised. The traceback is as follows:\nTraceback (most recent call last):\n  File \"/home/ml/users/ksinha4/mlp/comp424_final_project/submissions/comp424mcgill/final-project-a_team_name/world.py\", line 310, in step\n    raise ValueError(\nValueError: [INVALID:STEP] Not a valid step from [6 6] to [6 6] and put barrier at 0, with max steps = 5\n\nExecute Random Walk!\nAn exception raised. The traceback is as follows:\nTraceback (most recent call last):\n  File \"/home/ml/users/ksinha4/mlp/comp424_final_project/submissions/comp424mcgill/final-project-a_team_name/world.py\", line 310, in step\n    raise ValueError(\nValueError: [INVALID:STEP] Not a valid step from [7 8] to [7 8] and put barrier at 0, with max steps = 5\n\nExecute Random Walk!\nAn exception raised. The traceback is as follows:\nTraceback (most recent call last):\n  File \"/home/ml/users/ksinha4/mlp/comp424_final_project/submissions/comp424mcgill/final-project-a_team_name/world.py\", line 310, in step\n    raise ValueError(\nValueError: [INVALID:STEP] Not a valid step from [7 8] to [7 8] and put barrier at 0, with max steps = 5\n\nExecute Random Walk!\n"}, {"student_agent_score": 1, "random_agent_score": 48, "student_agent_time": 0.005700111389160156, "random_agent_time": 0.0037817955017089844, "board_size": 7, "swap_players": false, "run_out": "An exception raised. The traceback is as follows:\nTraceback (most recent call last):\n  File \"/home/ml/users/ksinha4/mlp/comp424_final_project/submissions/comp424mcgill/final-project-a_team_name/world.py\", line 310, in step\n    raise ValueError(\nValueError: [INVALID:STEP] Not a valid step from [4 3] to [4 3] and put barrier at 0, with max steps = 4\n\nExecute Random Walk!\nAn exception raised. The traceback is as follows:\nTraceback (most recent call last):\n  File \"/home/ml/users/ksinha4/mlp/comp424_final_project/submissions/comp424mcgill/final-project-a_team_name/world.py\", line 310, in step\n    raise ValueError(\nValueError: [INVALID:STEP] Not a valid step from [4 2] to [4 2] and put barrier at 0, with max steps = 4\n\nExecute Random Walk!\nAn exception raised. The traceback is as follows:\nTraceback (most recent call last):\n  File \"/home/ml/users/ksinha4/mlp/comp424_final_project/submissions/comp424mcgill/final-project-a_team_name/world.py\", line 310, in step\n    raise ValueError(\nValueError: [INVALID:STEP] Not a valid step from [4 3] to [4 3] and put barrier at 0, with max steps = 4\n\nExecute Random Walk!\nAn exception raised. The traceback is as follows:\nTraceback (most recent call last):\n  File \"/home/ml/users/ksinha4/mlp/comp424_final_project/submissions/comp424mcgill/final-project-a_team_name/world.py\", line 310, in step\n    raise ValueError(\nValueError: [INVALID:STEP] Not a valid step from [5 4] to [5 4] and put barrier at 0, with max steps = 4\n\nExecute Random Walk!\nAn exception raised. The traceback is as follows:\nTraceback (most recent call last):\n  File \"/home/ml/users/ksinha4/mlp/comp424_final_project/submissions/comp424mcgill/final-project-a_team_name/world.py\", line 310, in step\n    raise ValueError(\nValueError: [INVALID:STEP] Not a valid step from [6 3] to [6 3] and put barrier at 0, with max steps = 4\n\nExecute Random Walk!\n"}, {"student_agent_score": 1, "random_agent_score": 35, "student_agent_time": 0.0029249191284179688, "random_agent_time": 0.0021851062774658203, "board_size": 6, "swap_players": true, "run_out": "An exception raised. The traceback is as follows:\nTraceback (most recent call last):\n  File \"/home/ml/users/ksinha4/mlp/comp424_final_project/submissions/comp424mcgill/final-project-a_team_name/world.py\", line 310, in step\n    raise ValueError(\nValueError: [INVALID:STEP] Not a valid step from [3 3] to [3 3] and put barrier at 0, with max steps = 3\n\nExecute Random Walk!\nAn exception raised. The traceback is as follows:\nTraceback (most recent call last):\n  File \"/home/ml/users/ksinha4/mlp/comp424_final_project/submissions/comp424mcgill/final-project-a_team_name/world.py\", line 310, in step\n    raise ValueError(\nValueError: [INVALID:STEP] Not a valid step from [3 3] to [3 3] and put barrier at 0, with max steps = 3\n\nExecute Random Walk!\n"}, {"student_agent_score": 120, "random_agent_score": 1, "student_agent_time": 0.0022263526916503906, "random_agent_time": 0.002474069595336914, "board_size": 11, "swap_players": true, "run_out": "An exception raised. The traceback is as follows:\nTraceback (most recent call last):\n  File \"/home/ml/users/ksinha4/mlp/comp424_final_project/submissions/comp424mcgill/final-project-a_team_name/world.py\", line 310, in step\n    raise ValueError(\nValueError: [INVALID:STEP] Not a valid step from [9 3] to [9 3] and put barrier at 0, with max steps = 6\n\nExecute Random Walk!\nAn exception raised. The traceback is as follows:\nTraceback (most recent call last):\n  File \"/home/ml/users/ksinha4/mlp/comp424_final_project/submissions/comp424mcgill/final-project-a_team_name/world.py\", line 310, in step\n    raise ValueError(\nValueError: [INVALID:STEP] Not a valid step from [9 3] to [9 3] and put barrier at 0, with max steps = 6\n\nExecute Random Walk!\n"}, {"student_agent_score": 63, "random_agent_score": 1, "student_agent_time": 0.0024487972259521484, "random_agent_time": 0.001951456069946289, "board_size": 8, "swap_players": true, "run_out": "An exception raised. The traceback is as follows:\nTraceback (most recent call last):\n  File \"/home/ml/users/ksinha4/mlp/comp424_final_project/submissions/comp424mcgill/final-project-a_team_name/world.py\", line 310, in step\n    raise ValueError(\nValueError: [INVALID:STEP] Not a valid step from [5 5] to [5 5] and put barrier at 0, with max steps = 4\n\nExecute Random Walk!\nAn exception raised. The traceback is as follows:\nTraceback (most recent call last):\n  File \"/home/ml/users/ksinha4/mlp/comp424_final_project/submissions/comp424mcgill/final-project-a_team_name/world.py\", line 310, in step\n    raise ValueError(\nValueError: [INVALID:STEP] Not a valid step from [5 4] to [5 4] and put barrier at 0, with max steps = 4\n\nExecute Random Walk!\nAn exception raised. The traceback is as follows:\nTraceback (most recent call last):\n  File \"/home/ml/users/ksinha4/mlp/comp424_final_project/submissions/comp424mcgill/final-project-a_team_name/world.py\", line 310, in step\n    raise ValueError(\nValueError: [INVALID:STEP] Not a valid step from [5 4] to [5 4] and put barrier at 0, with max steps = 4\n\nExecute Random Walk!\n"}, {"student_agent_score": 1, "random_agent_score": 48, "student_agent_time": 0.004810333251953125, "random_agent_time": 0.0033288002014160156, "board_size": 7, "swap_players": false, "run_out": "An exception raised. The traceback is as follows:\nTraceback (most recent call last):\n  File \"/home/ml/users/ksinha4/mlp/comp424_final_project/submissions/comp424mcgill/final-project-a_team_name/world.py\", line 310, in step\n    raise ValueError(\nValueError: [INVALID:STEP] Not a valid step from [4 3] to [4 3] and put barrier at 0, with max steps = 4\n\nExecute Random Walk!\nAn exception raised. The traceback is as follows:\nTraceback (most recent call last):\n  File \"/home/ml/users/ksinha4/mlp/comp424_final_project/submissions/comp424mcgill/final-project-a_team_name/world.py\", line 310, in step\n    raise ValueError(\nValueError: [INVALID:STEP] Not a valid step from [4 2] to [4 2] and put barrier at 0, with max steps = 4\n\nExecute Random Walk!\nAn exception raised. The traceback is as follows:\nTraceback (most recent call last):\n  File \"/home/ml/users/ksinha4/mlp/comp424_final_project/submissions/comp424mcgill/final-project-a_team_name/world.py\", line 310, in step\n    raise ValueError(\nValueError: [INVALID:STEP] Not a valid step from [4 3] to [4 3] and put barrier at 0, with max steps = 4\n\nExecute Random Walk!\nAn exception raised. The traceback is as follows:\nTraceback (most recent call last):\n  File \"/home/ml/users/ksinha4/mlp/comp424_final_project/submissions/comp424mcgill/final-project-a_team_name/world.py\", line 310, in step\n    raise ValueError(\nValueError: [INVALID:STEP] Not a valid step from [5 4] to [5 4] and put barrier at 0, with max steps = 4\n\nExecute Random Walk!\nAn exception raised. The traceback is as follows:\nTraceback (most recent call last):\n  File \"/home/ml/users/ksinha4/mlp/comp424_final_project/submissions/comp424mcgill/final-project-a_team_name/world.py\", line 310, in step\n    raise ValueError(\nValueError: [INVALID:STEP] Not a valid step from [6 3] to [6 3] and put barrier at 0, with max steps = 4\n\nExecute Random Walk!\n"}, {"student_agent_score": 1, "random_agent_score": 63, "student_agent_time": 0.0050776004791259766, "random_agent_time": 0.002406597137451172, "board_size": 8, "swap_players": false, "run_out": "An exception raised. The traceback is as follows:\nTraceback (most recent call last):\n  File \"/home/ml/users/ksinha4/mlp/comp424_final_project/submissions/comp424mcgill/final-project-a_team_name/world.py\", line 310, in step\n    raise ValueError(\nValueError: [INVALID:STEP] Not a valid step from [2 2] to [2 2] and put barrier at 0, with max steps = 4\n\nExecute Random Walk!\nAn exception raised. The traceback is as follows:\nTraceback (most recent call last):\n  File \"/home/ml/users/ksinha4/mlp/comp424_final_project/submissions/comp424mcgill/final-project-a_team_name/world.py\", line 310, in step\n    raise ValueError(\nValueError: [INVALID:STEP] Not a valid step from [3 1] to [3 1] and put barrier at 0, with max steps = 4\n\nExecute Random Walk!\nAn exception raised. The traceback is as follows:\nTraceback (most recent call last):\n  File \"/home/ml/users/ksinha4/mlp/comp424_final_project/submissions/comp424mcgill/final-project-a_team_name/world.py\", line 310, in step\n    raise ValueError(\nValueError: [INVALID:STEP] Not a valid step from [3 0] to [3 0] and put barrier at 0, with max steps = 4\n\nExecute Random Walk!\nAn exception raised. The traceback is as follows:\nTraceback (most recent call last):\n  File \"/home/ml/users/ksinha4/mlp/comp424_final_project/submissions/comp424mcgill/final-project-a_team_name/world.py\", line 310, in step\n    raise ValueError(\nValueError: [INVALID:STEP] Not a valid step from [6 1] to [6 1] and put barrier at 0, with max steps = 4\n\nExecute Random Walk!\n"}, {"student_agent_score": 1, "random_agent_score": 48, "student_agent_time": 0.0022606849670410156, "random_agent_time": 0.0020704269409179688, "board_size": 7, "swap_players": true, "run_out": "An exception raised. The traceback is as follows:\nTraceback (most recent call last):\n  File \"/home/ml/users/ksinha4/mlp/comp424_final_project/submissions/comp424mcgill/final-project-a_team_name/world.py\", line 310, in step\n    raise ValueError(\nValueError: [INVALID:STEP] Not a valid step from [2 3] to [2 3] and put barrier at 0, with max steps = 4\n\nExecute Random Walk!\nAn exception raised. The traceback is as follows:\nTraceback (most recent call last):\n  File \"/home/ml/users/ksinha4/mlp/comp424_final_project/submissions/comp424mcgill/final-project-a_team_name/world.py\", line 310, in step\n    raise ValueError(\nValueError: [INVALID:STEP] Not a valid step from [5 4] to [5 4] and put barrier at 0, with max steps = 4\n\nExecute Random Walk!\nAn exception raised. The traceback is as follows:\nTraceback (most recent call last):\n  File \"/home/ml/users/ksinha4/mlp/comp424_final_project/submissions/comp424mcgill/final-project-a_team_name/world.py\", line 310, in step\n    raise ValueError(\nValueError: [INVALID:STEP] Not a valid step from [6 3] to [6 3] and put barrier at 0, with max steps = 4\n\nExecute Random Walk!\n"}, {"student_agent_score": 2, "random_agent_score": 79, "student_agent_time": 0.0021169185638427734, "random_agent_time": 0.002006053924560547, "board_size": 9, "swap_players": false, "run_out": "An exception raised. The traceback is as follows:\nTraceback (most recent call last):\n  File \"/home/ml/users/ksinha4/mlp/comp424_final_project/submissions/comp424mcgill/final-project-a_team_name/world.py\", line 310, in step\n    raise ValueError(\nValueError: [INVALID:STEP] Not a valid step from [5 4] to [5 4] and put barrier at 0, with max steps = 5\n\nExecute Random Walk!\nAn exception raised. The traceback is as follows:\nTraceback (most recent call last):\n  File \"/home/ml/users/ksinha4/mlp/comp424_final_project/submissions/comp424mcgill/final-project-a_team_name/world.py\", line 310, in step\n    raise ValueError(\nValueError: [INVALID:STEP] Not a valid step from [5 3] to [5 3] and put barrier at 0, with max steps = 5\n\nExecute Random Walk!\n"}, {"student_agent_score": 1, "random_agent_score": 48, "student_agent_time": 0.0046846866607666016, "random_agent_time": 0.0032362937927246094, "board_size": 7, "swap_players": false, "run_out": "An exception raised. The traceback is as follows:\nTraceback (most recent call last):\n  File \"/home/ml/users/ksinha4/mlp/comp424_final_project/submissions/comp424mcgill/final-project-a_team_name/world.py\", line 310, in step\n    raise ValueError(\nValueError: [INVALID:STEP] Not a valid step from [4 3] to [4 3] and put barrier at 0, with max steps = 4\n\nExecute Random Walk!\nAn exception raised. The traceback is as follows:\nTraceback (most recent call last):\n  File \"/home/ml/users/ksinha4/mlp/comp424_final_project/submissions/comp424mcgill/final-project-a_team_name/world.py\", line 310, in step\n    raise ValueError(\nValueError: [INVALID:STEP] Not a valid step from [4 2] to [4 2] and put barrier at 0, with max steps = 4\n\nExecute Random Walk!\nAn exception raised. The traceback is as follows:\nTraceback (most recent call last):\n  File \"/home/ml/users/ksinha4/mlp/comp424_final_project/submissions/comp424mcgill/final-project-a_team_name/world.py\", line 310, in step\n    raise ValueError(\nValueError: [INVALID:STEP] Not a valid step from [4 3] to [4 3] and put barrier at 0, with max steps = 4\n\nExecute Random Walk!\nAn exception raised. The traceback is as follows:\nTraceback (most recent call last):\n  File \"/home/ml/users/ksinha4/mlp/comp424_final_project/submissions/comp424mcgill/final-project-a_team_name/world.py\", line 310, in step\n    raise ValueError(\nValueError: [INVALID:STEP] Not a valid step from [5 4] to [5 4] and put barrier at 0, with max steps = 4\n\nExecute Random Walk!\nAn exception raised. The traceback is as follows:\nTraceback (most recent call last):\n  File \"/home/ml/users/ksinha4/mlp/comp424_final_project/submissions/comp424mcgill/final-project-a_team_name/world.py\", line 310, in step\n    raise ValueError(\nValueError: [INVALID:STEP] Not a valid step from [6 3] to [6 3] and put barrier at 0, with max steps = 4\n\nExecute Random Walk!\n"}, {"student_agent_score": 120, "random_agent_score": 1, "student_agent_time": 0.0018990039825439453, "random_agent_time": 0.0029141902923583984, "board_size": 11, "swap_players": true, "run_out": "An exception raised. The traceback is as follows:\nTraceback (most recent call last):\n  File \"/home/ml/users/ksinha4/mlp/comp424_final_project/submissions/comp424mcgill/final-project-a_team_name/world.py\", line 310, in step\n    raise ValueError(\nValueError: [INVALID:STEP] Not a valid step from [9 3] to [9 3] and put barrier at 0, with max steps = 6\n\nExecute Random Walk!\nAn exception raised. The traceback is as follows:\nTraceback (most recent call last):\n  File \"/home/ml/users/ksinha4/mlp/comp424_final_project/submissions/comp424mcgill/final-project-a_team_name/world.py\", line 310, in step\n    raise ValueError(\nValueError: [INVALID:STEP] Not a valid step from [9 3] to [9 3] and put barrier at 0, with max steps = 6\n\nExecute Random Walk!\n"}, {"student_agent_score": 99, "random_agent_score": 1, "student_agent_time": 0.0002808570861816406, "random_agent_time": 0.0009093284606933594, "board_size": 10, "swap_players": true, "run_out": ""}, {"student_agent_score": 99, "random_agent_score": 1, "student_agent_time": 0.0002624988555908203, "random_agent_time": 0.0008981227874755859, "board_size": 10, "swap_players": true, "run_out": ""}, {"student_agent_score": 1, "random_agent_score": 48, "student_agent_time": 0.0043795108795166016, "random_agent_time": 0.0026886463165283203, "board_size": 7, "swap_players": false, "run_out": "An exception raised. The traceback is as follows:\nTraceback (most recent call last):\n  File \"/home/ml/users/ksinha4/mlp/comp424_final_project/submissions/comp424mcgill/final-project-a_team_name/world.py\", line 310, in step\n    raise ValueError(\nValueError: [INVALID:STEP] Not a valid step from [4 3] to [4 3] and put barrier at 0, with max steps = 4\n\nExecute Random Walk!\nAn exception raised. The traceback is as follows:\nTraceback (most recent call last):\n  File \"/home/ml/users/ksinha4/mlp/comp424_final_project/submissions/comp424mcgill/final-project-a_team_name/world.py\", line 310, in step\n    raise ValueError(\nValueError: [INVALID:STEP] Not a valid step from [4 2] to [4 2] and put barrier at 0, with max steps = 4\n\nExecute Random Walk!\nAn exception raised. The traceback is as follows:\nTraceback (most recent call last):\n  File \"/home/ml/users/ksinha4/mlp/comp424_final_project/submissions/comp424mcgill/final-project-a_team_name/world.py\", line 310, in step\n    raise ValueError(\nValueError: [INVALID:STEP] Not a valid step from [4 3] to [4 3] and put barrier at 0, with max steps = 4\n\nExecute Random Walk!\nAn exception raised. The traceback is as follows:\nTraceback (most recent call last):\n  File \"/home/ml/users/ksinha4/mlp/comp424_final_project/submissions/comp424mcgill/final-project-a_team_name/world.py\", line 310, in step\n    raise ValueError(\nValueError: [INVALID:STEP] Not a valid step from [5 4] to [5 4] and put barrier at 0, with max steps = 4\n\nExecute Random Walk!\nAn exception raised. The traceback is as follows:\nTraceback (most recent call last):\n  File \"/home/ml/users/ksinha4/mlp/comp424_final_project/submissions/comp424mcgill/final-project-a_team_name/world.py\", line 310, in step\n    raise ValueError(\nValueError: [INVALID:STEP] Not a valid step from [6 3] to [6 3] and put barrier at 0, with max steps = 4\n\nExecute Random Walk!\n"}, {"student_agent_score": 2, "random_agent_score": 79, "student_agent_time": 0.003968715667724609, "random_agent_time": 0.002745389938354492, "board_size": 9, "swap_players": false, "run_out": "An exception raised. The traceback is as follows:\nTraceback (most recent call last):\n  File \"/home/ml/users/ksinha4/mlp/comp424_final_project/submissions/comp424mcgill/final-project-a_team_name/world.py\", line 310, in step\n    raise ValueError(\nValueError: [INVALID:STEP] Not a valid step from [5 4] to [5 4] and put barrier at 0, with max steps = 5\n\nExecute Random Walk!\nAn exception raised. The traceback is as follows:\nTraceback (most recent call last):\n  File \"/home/ml/users/ksinha4/mlp/comp424_final_project/submissions/comp424mcgill/final-project-a_team_name/world.py\", line 310, in step\n    raise ValueError(\nValueError: [INVALID:STEP] Not a valid step from [5 3] to [5 3] and put barrier at 0, with max steps = 5\n\nExecute Random Walk!\n"}, {"student_agent_score": 2, "random_agent_score": 79, "student_agent_time": 0.0022437572479248047, "random_agent_time": 0.001733541488647461, "board_size": 9, "swap_players": false, "run_out": "An exception raised. The traceback is as follows:\nTraceback (most recent call last):\n  File \"/home/ml/users/ksinha4/mlp/comp424_final_project/submissions/comp424mcgill/final-project-a_team_name/world.py\", line 310, in step\n    raise ValueError(\nValueError: [INVALID:STEP] Not a valid step from [5 4] to [5 4] and put barrier at 0, with max steps = 5\n\nExecute Random Walk!\nAn exception raised. The traceback is as follows:\nTraceback (most recent call last):\n  File \"/home/ml/users/ksinha4/mlp/comp424_final_project/submissions/comp424mcgill/final-project-a_team_name/world.py\", line 310, in step\n    raise ValueError(\nValueError: [INVALID:STEP] Not a valid step from [5 3] to [5 3] and put barrier at 0, with max steps = 5\n\nExecute Random Walk!\n"}, {"student_agent_score": 1, "random_agent_score": 48, "student_agent_time": 0.004117727279663086, "random_agent_time": 0.0019540786743164062, "board_size": 7, "swap_players": false, "run_out": "An exception raised. The traceback is as follows:\nTraceback (most recent call last):\n  File \"/home/ml/users/ksinha4/mlp/comp424_final_project/submissions/comp424mcgill/final-project-a_team_name/world.py\", line 310, in step\n    raise ValueError(\nValueError: [INVALID:STEP] Not a valid step from [4 3] to [4 3] and put barrier at 0, with max steps = 4\n\nExecute Random Walk!\nAn exception raised. The traceback is as follows:\nTraceback (most recent call last):\n  File \"/home/ml/users/ksinha4/mlp/comp424_final_project/submissions/comp424mcgill/final-project-a_team_name/world.py\", line 310, in step\n    raise ValueError(\nValueError: [INVALID:STEP] Not a valid step from [4 2] to [4 2] and put barrier at 0, with max steps = 4\n\nExecute Random Walk!\nAn exception raised. The traceback is as follows:\nTraceback (most recent call last):\n  File \"/home/ml/users/ksinha4/mlp/comp424_final_project/submissions/comp424mcgill/final-project-a_team_name/world.py\", line 310, in step\n    raise ValueError(\nValueError: [INVALID:STEP] Not a valid step from [4 3] to [4 3] and put barrier at 0, with max steps = 4\n\nExecute Random Walk!\nAn exception raised. The traceback is as follows:\nTraceback (most recent call last):\n  File \"/home/ml/users/ksinha4/mlp/comp424_final_project/submissions/comp424mcgill/final-project-a_team_name/world.py\", line 310, in step\n    raise ValueError(\nValueError: [INVALID:STEP] Not a valid step from [5 4] to [5 4] and put barrier at 0, with max steps = 4\n\nExecute Random Walk!\nAn exception raised. The traceback is as follows:\nTraceback (most recent call last):\n  File \"/home/ml/users/ksinha4/mlp/comp424_final_project/submissions/comp424mcgill/final-project-a_team_name/world.py\", line 310, in step\n    raise ValueError(\nValueError: [INVALID:STEP] Not a valid step from [6 3] to [6 3] and put barrier at 0, with max steps = 4\n\nExecute Random Walk!\n"}, {"student_agent_score": 1, "random_agent_score": 48, "student_agent_time": 0.007035017013549805, "random_agent_time": 0.0030875205993652344, "board_size": 7, "swap_players": false, "run_out": "An exception raised. The traceback is as follows:\nTraceback (most recent call last):\n  File \"/home/ml/users/ksinha4/mlp/comp424_final_project/submissions/comp424mcgill/final-project-a_team_name/world.py\", line 310, in step\n    raise ValueError(\nValueError: [INVALID:STEP] Not a valid step from [4 3] to [4 3] and put barrier at 0, with max steps = 4\n\nExecute Random Walk!\nAn exception raised. The traceback is as follows:\nTraceback (most recent call last):\n  File \"/home/ml/users/ksinha4/mlp/comp424_final_project/submissions/comp424mcgill/final-project-a_team_name/world.py\", line 310, in step\n    raise ValueError(\nValueError: [INVALID:STEP] Not a valid step from [4 2] to [4 2] and put barrier at 0, with max steps = 4\n\nExecute Random Walk!\nAn exception raised. The traceback is as follows:\nTraceback (most recent call last):\n  File \"/home/ml/users/ksinha4/mlp/comp424_final_project/submissions/comp424mcgill/final-project-a_team_name/world.py\", line 310, in step\n    raise ValueError(\nValueError: [INVALID:STEP] Not a valid step from [4 3] to [4 3] and put barrier at 0, with max steps = 4\n\nExecute Random Walk!\nAn exception raised. The traceback is as follows:\nTraceback (most recent call last):\n  File \"/home/ml/users/ksinha4/mlp/comp424_final_project/submissions/comp424mcgill/final-project-a_team_name/world.py\", line 310, in step\n    raise ValueError(\nValueError: [INVALID:STEP] Not a valid step from [5 4] to [5 4] and put barrier at 0, with max steps = 4\n\nExecute Random Walk!\nAn exception raised. The traceback is as follows:\nTraceback (most recent call last):\n  File \"/home/ml/users/ksinha4/mlp/comp424_final_project/submissions/comp424mcgill/final-project-a_team_name/world.py\", line 310, in step\n    raise ValueError(\nValueError: [INVALID:STEP] Not a valid step from [6 3] to [6 3] and put barrier at 0, with max steps = 4\n\nExecute Random Walk!\n"}, {"student_agent_score": 63, "random_agent_score": 1, "student_agent_time": 0.0031845569610595703, "random_agent_time": 0.0026526451110839844, "board_size": 8, "swap_players": true, "run_out": "An exception raised. The traceback is as follows:\nTraceback (most recent call last):\n  File \"/home/ml/users/ksinha4/mlp/comp424_final_project/submissions/comp424mcgill/final-project-a_team_name/world.py\", line 310, in step\n    raise ValueError(\nValueError: [INVALID:STEP] Not a valid step from [5 5] to [5 5] and put barrier at 0, with max steps = 4\n\nExecute Random Walk!\nAn exception raised. The traceback is as follows:\nTraceback (most recent call last):\n  File \"/home/ml/users/ksinha4/mlp/comp424_final_project/submissions/comp424mcgill/final-project-a_team_name/world.py\", line 310, in step\n    raise ValueError(\nValueError: [INVALID:STEP] Not a valid step from [5 4] to [5 4] and put barrier at 0, with max steps = 4\n\nExecute Random Walk!\nAn exception raised. The traceback is as follows:\nTraceback (most recent call last):\n  File \"/home/ml/users/ksinha4/mlp/comp424_final_project/submissions/comp424mcgill/final-project-a_team_name/world.py\", line 310, in step\n    raise ValueError(\nValueError: [INVALID:STEP] Not a valid step from [5 4] to [5 4] and put barrier at 0, with max steps = 4\n\nExecute Random Walk!\n"}, {"student_agent_score": 99, "random_agent_score": 1, "student_agent_time": 0.0003476142883300781, "random_agent_time": 0.0012743473052978516, "board_size": 10, "swap_players": true, "run_out": ""}, {"student_agent_score": 1, "random_agent_score": 48, "student_agent_time": 0.006250619888305664, "random_agent_time": 0.001959562301635742, "board_size": 7, "swap_players": false, "run_out": "An exception raised. The traceback is as follows:\nTraceback (most recent call last):\n  File \"/home/ml/users/ksinha4/mlp/comp424_final_project/submissions/comp424mcgill/final-project-a_team_name/world.py\", line 310, in step\n    raise ValueError(\nValueError: [INVALID:STEP] Not a valid step from [4 3] to [4 3] and put barrier at 0, with max steps = 4\n\nExecute Random Walk!\nAn exception raised. The traceback is as follows:\nTraceback (most recent call last):\n  File \"/home/ml/users/ksinha4/mlp/comp424_final_project/submissions/comp424mcgill/final-project-a_team_name/world.py\", line 310, in step\n    raise ValueError(\nValueError: [INVALID:STEP] Not a valid step from [4 2] to [4 2] and put barrier at 0, with max steps = 4\n\nExecute Random Walk!\nAn exception raised. The traceback is as follows:\nTraceback (most recent call last):\n  File \"/home/ml/users/ksinha4/mlp/comp424_final_project/submissions/comp424mcgill/final-project-a_team_name/world.py\", line 310, in step\n    raise ValueError(\nValueError: [INVALID:STEP] Not a valid step from [4 3] to [4 3] and put barrier at 0, with max steps = 4\n\nExecute Random Walk!\nAn exception raised. The traceback is as follows:\nTraceback (most recent call last):\n  File \"/home/ml/users/ksinha4/mlp/comp424_final_project/submissions/comp424mcgill/final-project-a_team_name/world.py\", line 310, in step\n    raise ValueError(\nValueError: [INVALID:STEP] Not a valid step from [5 4] to [5 4] and put barrier at 0, with max steps = 4\n\nExecute Random Walk!\nAn exception raised. The traceback is as follows:\nTraceback (most recent call last):\n  File \"/home/ml/users/ksinha4/mlp/comp424_final_project/submissions/comp424mcgill/final-project-a_team_name/world.py\", line 310, in step\n    raise ValueError(\nValueError: [INVALID:STEP] Not a valid step from [6 3] to [6 3] and put barrier at 0, with max steps = 4\n\nExecute Random Walk!\n"}, {"student_agent_score": 120, "random_agent_score": 1, "student_agent_time": 0.0022253990173339844, "random_agent_time": 0.006147861480712891, "board_size": 11, "swap_players": true, "run_out": "An exception raised. The traceback is as follows:\nTraceback (most recent call last):\n  File \"/home/ml/users/ksinha4/mlp/comp424_final_project/submissions/comp424mcgill/final-project-a_team_name/world.py\", line 310, in step\n    raise ValueError(\nValueError: [INVALID:STEP] Not a valid step from [9 3] to [9 3] and put barrier at 0, with max steps = 6\n\nExecute Random Walk!\nAn exception raised. The traceback is as follows:\nTraceback (most recent call last):\n  File \"/home/ml/users/ksinha4/mlp/comp424_final_project/submissions/comp424mcgill/final-project-a_team_name/world.py\", line 310, in step\n    raise ValueError(\nValueError: [INVALID:STEP] Not a valid step from [9 3] to [9 3] and put barrier at 0, with max steps = 6\n\nExecute Random Walk!\n"}, {"student_agent_score": 120, "random_agent_score": 1, "student_agent_time": 0.001950979232788086, "random_agent_time": 0.002495288848876953, "board_size": 11, "swap_players": true, "run_out": "An exception raised. The traceback is as follows:\nTraceback (most recent call last):\n  File \"/home/ml/users/ksinha4/mlp/comp424_final_project/submissions/comp424mcgill/final-project-a_team_name/world.py\", line 310, in step\n    raise ValueError(\nValueError: [INVALID:STEP] Not a valid step from [9 3] to [9 3] and put barrier at 0, with max steps = 6\n\nExecute Random Walk!\nAn exception raised. The traceback is as follows:\nTraceback (most recent call last):\n  File \"/home/ml/users/ksinha4/mlp/comp424_final_project/submissions/comp424mcgill/final-project-a_team_name/world.py\", line 310, in step\n    raise ValueError(\nValueError: [INVALID:STEP] Not a valid step from [9 3] to [9 3] and put barrier at 0, with max steps = 6\n\nExecute Random Walk!\n"}, {"student_agent_score": 1, "random_agent_score": 48, "student_agent_time": 0.0023844242095947266, "random_agent_time": 0.0025720596313476562, "board_size": 7, "swap_players": true, "run_out": "An exception raised. The traceback is as follows:\nTraceback (most recent call last):\n  File \"/home/ml/users/ksinha4/mlp/comp424_final_project/submissions/comp424mcgill/final-project-a_team_name/world.py\", line 310, in step\n    raise ValueError(\nValueError: [INVALID:STEP] Not a valid step from [2 3] to [2 3] and put barrier at 0, with max steps = 4\n\nExecute Random Walk!\nAn exception raised. The traceback is as follows:\nTraceback (most recent call last):\n  File \"/home/ml/users/ksinha4/mlp/comp424_final_project/submissions/comp424mcgill/final-project-a_team_name/world.py\", line 310, in step\n    raise ValueError(\nValueError: [INVALID:STEP] Not a valid step from [5 4] to [5 4] and put barrier at 0, with max steps = 4\n\nExecute Random Walk!\nAn exception raised. The traceback is as follows:\nTraceback (most recent call last):\n  File \"/home/ml/users/ksinha4/mlp/comp424_final_project/submissions/comp424mcgill/final-project-a_team_name/world.py\", line 310, in step\n    raise ValueError(\nValueError: [INVALID:STEP] Not a valid step from [6 3] to [6 3] and put barrier at 0, with max steps = 4\n\nExecute Random Walk!\n"}, {"student_agent_score": 1, "random_agent_score": 48, "student_agent_time": 0.0027284622192382812, "random_agent_time": 0.002736330032348633, "board_size": 7, "swap_players": true, "run_out": "An exception raised. The traceback is as follows:\nTraceback (most recent call last):\n  File \"/home/ml/users/ksinha4/mlp/comp424_final_project/submissions/comp424mcgill/final-project-a_team_name/world.py\", line 310, in step\n    raise ValueError(\nValueError: [INVALID:STEP] Not a valid step from [2 3] to [2 3] and put barrier at 0, with max steps = 4\n\nExecute Random Walk!\nAn exception raised. The traceback is as follows:\nTraceback (most recent call last):\n  File \"/home/ml/users/ksinha4/mlp/comp424_final_project/submissions/comp424mcgill/final-project-a_team_name/world.py\", line 310, in step\n    raise ValueError(\nValueError: [INVALID:STEP] Not a valid step from [5 4] to [5 4] and put barrier at 0, with max steps = 4\n\nExecute Random Walk!\nAn exception raised. The traceback is as follows:\nTraceback (most recent call last):\n  File \"/home/ml/users/ksinha4/mlp/comp424_final_project/submissions/comp424mcgill/final-project-a_team_name/world.py\", line 310, in step\n    raise ValueError(\nValueError: [INVALID:STEP] Not a valid step from [6 3] to [6 3] and put barrier at 0, with max steps = 4\n\nExecute Random Walk!\n"}, {"student_agent_score": 1, "random_agent_score": 48, "student_agent_time": 0.004792451858520508, "random_agent_time": 0.0033838748931884766, "board_size": 7, "swap_players": false, "run_out": "An exception raised. The traceback is as follows:\nTraceback (most recent call last):\n  File \"/home/ml/users/ksinha4/mlp/comp424_final_project/submissions/comp424mcgill/final-project-a_team_name/world.py\", line 310, in step\n    raise ValueError(\nValueError: [INVALID:STEP] Not a valid step from [4 3] to [4 3] and put barrier at 0, with max steps = 4\n\nExecute Random Walk!\nAn exception raised. The traceback is as follows:\nTraceback (most recent call last):\n  File \"/home/ml/users/ksinha4/mlp/comp424_final_project/submissions/comp424mcgill/final-project-a_team_name/world.py\", line 310, in step\n    raise ValueError(\nValueError: [INVALID:STEP] Not a valid step from [4 2] to [4 2] and put barrier at 0, with max steps = 4\n\nExecute Random Walk!\nAn exception raised. The traceback is as follows:\nTraceback (most recent call last):\n  File \"/home/ml/users/ksinha4/mlp/comp424_final_project/submissions/comp424mcgill/final-project-a_team_name/world.py\", line 310, in step\n    raise ValueError(\nValueError: [INVALID:STEP] Not a valid step from [4 3] to [4 3] and put barrier at 0, with max steps = 4\n\nExecute Random Walk!\nAn exception raised. The traceback is as follows:\nTraceback (most recent call last):\n  File \"/home/ml/users/ksinha4/mlp/comp424_final_project/submissions/comp424mcgill/final-project-a_team_name/world.py\", line 310, in step\n    raise ValueError(\nValueError: [INVALID:STEP] Not a valid step from [5 4] to [5 4] and put barrier at 0, with max steps = 4\n\nExecute Random Walk!\nAn exception raised. The traceback is as follows:\nTraceback (most recent call last):\n  File \"/home/ml/users/ksinha4/mlp/comp424_final_project/submissions/comp424mcgill/final-project-a_team_name/world.py\", line 310, in step\n    raise ValueError(\nValueError: [INVALID:STEP] Not a valid step from [6 3] to [6 3] and put barrier at 0, with max steps = 4\n\nExecute Random Walk!\n"}, {"student_agent_score": 1, "random_agent_score": 48, "student_agent_time": 0.004679441452026367, "random_agent_time": 0.0029985904693603516, "board_size": 7, "swap_players": true, "run_out": "An exception raised. The traceback is as follows:\nTraceback (most recent call last):\n  File \"/home/ml/users/ksinha4/mlp/comp424_final_project/submissions/comp424mcgill/final-project-a_team_name/world.py\", line 310, in step\n    raise ValueError(\nValueError: [INVALID:STEP] Not a valid step from [2 3] to [2 3] and put barrier at 0, with max steps = 4\n\nExecute Random Walk!\nAn exception raised. The traceback is as follows:\nTraceback (most recent call last):\n  File \"/home/ml/users/ksinha4/mlp/comp424_final_project/submissions/comp424mcgill/final-project-a_team_name/world.py\", line 310, in step\n    raise ValueError(\nValueError: [INVALID:STEP] Not a valid step from [5 4] to [5 4] and put barrier at 0, with max steps = 4\n\nExecute Random Walk!\nAn exception raised. The traceback is as follows:\nTraceback (most recent call last):\n  File \"/home/ml/users/ksinha4/mlp/comp424_final_project/submissions/comp424mcgill/final-project-a_team_name/world.py\", line 310, in step\n    raise ValueError(\nValueError: [INVALID:STEP] Not a valid step from [6 3] to [6 3] and put barrier at 0, with max steps = 4\n\nExecute Random Walk!\n"}, {"student_agent_score": 2, "random_agent_score": 98, "student_agent_time": 0.003993511199951172, "random_agent_time": 0.004622459411621094, "board_size": 10, "swap_players": false, "run_out": "An exception raised. The traceback is as follows:\nTraceback (most recent call last):\n  File \"/home/ml/users/ksinha4/mlp/comp424_final_project/submissions/comp424mcgill/final-project-a_team_name/world.py\", line 310, in step\n    raise ValueError(\nValueError: [INVALID:STEP] Not a valid step from [7 5] to [7 5] and put barrier at 0, with max steps = 5\n\nExecute Random Walk!\nAn exception raised. The traceback is as follows:\nTraceback (most recent call last):\n  File \"/home/ml/users/ksinha4/mlp/comp424_final_project/submissions/comp424mcgill/final-project-a_team_name/world.py\", line 310, in step\n    raise ValueError(\nValueError: [INVALID:STEP] Not a valid step from [6 6] to [6 6] and put barrier at 0, with max steps = 5\n\nExecute Random Walk!\nAn exception raised. The traceback is as follows:\nTraceback (most recent call last):\n  File \"/home/ml/users/ksinha4/mlp/comp424_final_project/submissions/comp424mcgill/final-project-a_team_name/world.py\", line 310, in step\n    raise ValueError(\nValueError: [INVALID:STEP] Not a valid step from [7 8] to [7 8] and put barrier at 0, with max steps = 5\n\nExecute Random Walk!\nAn exception raised. The traceback is as follows:\nTraceback (most recent call last):\n  File \"/home/ml/users/ksinha4/mlp/comp424_final_project/submissions/comp424mcgill/final-project-a_team_name/world.py\", line 310, in step\n    raise ValueError(\nValueError: [INVALID:STEP] Not a valid step from [7 8] to [7 8] and put barrier at 0, with max steps = 5\n\nExecute Random Walk!\n"}, {"student_agent_score": 1, "random_agent_score": 48, "student_agent_time": 0.004509925842285156, "random_agent_time": 0.0021066665649414062, "board_size": 7, "swap_players": false, "run_out": "An exception raised. The traceback is as follows:\nTraceback (most recent call last):\n  File \"/home/ml/users/ksinha4/mlp/comp424_final_project/submissions/comp424mcgill/final-project-a_team_name/world.py\", line 310, in step\n    raise ValueError(\nValueError: [INVALID:STEP] Not a valid step from [4 3] to [4 3] and put barrier at 0, with max steps = 4\n\nExecute Random Walk!\nAn exception raised. The traceback is as follows:\nTraceback (most recent call last):\n  File \"/home/ml/users/ksinha4/mlp/comp424_final_project/submissions/comp424mcgill/final-project-a_team_name/world.py\", line 310, in step\n    raise ValueError(\nValueError: [INVALID:STEP] Not a valid step from [4 2] to [4 2] and put barrier at 0, with max steps = 4\n\nExecute Random Walk!\nAn exception raised. The traceback is as follows:\nTraceback (most recent call last):\n  File \"/home/ml/users/ksinha4/mlp/comp424_final_project/submissions/comp424mcgill/final-project-a_team_name/world.py\", line 310, in step\n    raise ValueError(\nValueError: [INVALID:STEP] Not a valid step from [4 3] to [4 3] and put barrier at 0, with max steps = 4\n\nExecute Random Walk!\nAn exception raised. The traceback is as follows:\nTraceback (most recent call last):\n  File \"/home/ml/users/ksinha4/mlp/comp424_final_project/submissions/comp424mcgill/final-project-a_team_name/world.py\", line 310, in step\n    raise ValueError(\nValueError: [INVALID:STEP] Not a valid step from [5 4] to [5 4] and put barrier at 0, with max steps = 4\n\nExecute Random Walk!\nAn exception raised. The traceback is as follows:\nTraceback (most recent call last):\n  File \"/home/ml/users/ksinha4/mlp/comp424_final_project/submissions/comp424mcgill/final-project-a_team_name/world.py\", line 310, in step\n    raise ValueError(\nValueError: [INVALID:STEP] Not a valid step from [6 3] to [6 3] and put barrier at 0, with max steps = 4\n\nExecute Random Walk!\n"}, {"student_agent_score": 2, "random_agent_score": 79, "student_agent_time": 0.004509449005126953, "random_agent_time": 0.003492593765258789, "board_size": 9, "swap_players": false, "run_out": "An exception raised. The traceback is as follows:\nTraceback (most recent call last):\n  File \"/home/ml/users/ksinha4/mlp/comp424_final_project/submissions/comp424mcgill/final-project-a_team_name/world.py\", line 310, in step\n    raise ValueError(\nValueError: [INVALID:STEP] Not a valid step from [5 4] to [5 4] and put barrier at 0, with max steps = 5\n\nExecute Random Walk!\nAn exception raised. The traceback is as follows:\nTraceback (most recent call last):\n  File \"/home/ml/users/ksinha4/mlp/comp424_final_project/submissions/comp424mcgill/final-project-a_team_name/world.py\", line 310, in step\n    raise ValueError(\nValueError: [INVALID:STEP] Not a valid step from [5 3] to [5 3] and put barrier at 0, with max steps = 5\n\nExecute Random Walk!\n"}, {"student_agent_score": 1, "random_agent_score": 48, "student_agent_time": 0.004453420639038086, "random_agent_time": 0.0029647350311279297, "board_size": 7, "swap_players": true, "run_out": "An exception raised. The traceback is as follows:\nTraceback (most recent call last):\n  File \"/home/ml/users/ksinha4/mlp/comp424_final_project/submissions/comp424mcgill/final-project-a_team_name/world.py\", line 310, in step\n    raise ValueError(\nValueError: [INVALID:STEP] Not a valid step from [2 3] to [2 3] and put barrier at 0, with max steps = 4\n\nExecute Random Walk!\nAn exception raised. The traceback is as follows:\nTraceback (most recent call last):\n  File \"/home/ml/users/ksinha4/mlp/comp424_final_project/submissions/comp424mcgill/final-project-a_team_name/world.py\", line 310, in step\n    raise ValueError(\nValueError: [INVALID:STEP] Not a valid step from [5 4] to [5 4] and put barrier at 0, with max steps = 4\n\nExecute Random Walk!\nAn exception raised. The traceback is as follows:\nTraceback (most recent call last):\n  File \"/home/ml/users/ksinha4/mlp/comp424_final_project/submissions/comp424mcgill/final-project-a_team_name/world.py\", line 310, in step\n    raise ValueError(\nValueError: [INVALID:STEP] Not a valid step from [6 3] to [6 3] and put barrier at 0, with max steps = 4\n\nExecute Random Walk!\n"}, {"student_agent_score": 1, "random_agent_score": 48, "student_agent_time": 0.004638671875, "random_agent_time": 0.002662181854248047, "board_size": 7, "swap_players": false, "run_out": "An exception raised. The traceback is as follows:\nTraceback (most recent call last):\n  File \"/home/ml/users/ksinha4/mlp/comp424_final_project/submissions/comp424mcgill/final-project-a_team_name/world.py\", line 310, in step\n    raise ValueError(\nValueError: [INVALID:STEP] Not a valid step from [4 3] to [4 3] and put barrier at 0, with max steps = 4\n\nExecute Random Walk!\nAn exception raised. The traceback is as follows:\nTraceback (most recent call last):\n  File \"/home/ml/users/ksinha4/mlp/comp424_final_project/submissions/comp424mcgill/final-project-a_team_name/world.py\", line 310, in step\n    raise ValueError(\nValueError: [INVALID:STEP] Not a valid step from [4 2] to [4 2] and put barrier at 0, with max steps = 4\n\nExecute Random Walk!\nAn exception raised. The traceback is as follows:\nTraceback (most recent call last):\n  File \"/home/ml/users/ksinha4/mlp/comp424_final_project/submissions/comp424mcgill/final-project-a_team_name/world.py\", line 310, in step\n    raise ValueError(\nValueError: [INVALID:STEP] Not a valid step from [4 3] to [4 3] and put barrier at 0, with max steps = 4\n\nExecute Random Walk!\nAn exception raised. The traceback is as follows:\nTraceback (most recent call last):\n  File \"/home/ml/users/ksinha4/mlp/comp424_final_project/submissions/comp424mcgill/final-project-a_team_name/world.py\", line 310, in step\n    raise ValueError(\nValueError: [INVALID:STEP] Not a valid step from [5 4] to [5 4] and put barrier at 0, with max steps = 4\n\nExecute Random Walk!\nAn exception raised. The traceback is as follows:\nTraceback (most recent call last):\n  File \"/home/ml/users/ksinha4/mlp/comp424_final_project/submissions/comp424mcgill/final-project-a_team_name/world.py\", line 310, in step\n    raise ValueError(\nValueError: [INVALID:STEP] Not a valid step from [6 3] to [6 3] and put barrier at 0, with max steps = 4\n\nExecute Random Walk!\n"}, {"student_agent_score": 1, "random_agent_score": 48, "student_agent_time": 0.002496957778930664, "random_agent_time": 0.0042531490325927734, "board_size": 7, "swap_players": true, "run_out": "An exception raised. The traceback is as follows:\nTraceback (most recent call last):\n  File \"/home/ml/users/ksinha4/mlp/comp424_final_project/submissions/comp424mcgill/final-project-a_team_name/world.py\", line 310, in step\n    raise ValueError(\nValueError: [INVALID:STEP] Not a valid step from [2 3] to [2 3] and put barrier at 0, with max steps = 4\n\nExecute Random Walk!\nAn exception raised. The traceback is as follows:\nTraceback (most recent call last):\n  File \"/home/ml/users/ksinha4/mlp/comp424_final_project/submissions/comp424mcgill/final-project-a_team_name/world.py\", line 310, in step\n    raise ValueError(\nValueError: [INVALID:STEP] Not a valid step from [5 4] to [5 4] and put barrier at 0, with max steps = 4\n\nExecute Random Walk!\nAn exception raised. The traceback is as follows:\nTraceback (most recent call last):\n  File \"/home/ml/users/ksinha4/mlp/comp424_final_project/submissions/comp424mcgill/final-project-a_team_name/world.py\", line 310, in step\n    raise ValueError(\nValueError: [INVALID:STEP] Not a valid step from [6 3] to [6 3] and put barrier at 0, with max steps = 4\n\nExecute Random Walk!\n"}, {"student_agent_score": 1, "random_agent_score": 48, "student_agent_time": 0.002581357955932617, "random_agent_time": 0.0026869773864746094, "board_size": 7, "swap_players": true, "run_out": "An exception raised. The traceback is as follows:\nTraceback (most recent call last):\n  File \"/home/ml/users/ksinha4/mlp/comp424_final_project/submissions/comp424mcgill/final-project-a_team_name/world.py\", line 310, in step\n    raise ValueError(\nValueError: [INVALID:STEP] Not a valid step from [2 3] to [2 3] and put barrier at 0, with max steps = 4\n\nExecute Random Walk!\nAn exception raised. The traceback is as follows:\nTraceback (most recent call last):\n  File \"/home/ml/users/ksinha4/mlp/comp424_final_project/submissions/comp424mcgill/final-project-a_team_name/world.py\", line 310, in step\n    raise ValueError(\nValueError: [INVALID:STEP] Not a valid step from [5 4] to [5 4] and put barrier at 0, with max steps = 4\n\nExecute Random Walk!\nAn exception raised. The traceback is as follows:\nTraceback (most recent call last):\n  File \"/home/ml/users/ksinha4/mlp/comp424_final_project/submissions/comp424mcgill/final-project-a_team_name/world.py\", line 310, in step\n    raise ValueError(\nValueError: [INVALID:STEP] Not a valid step from [6 3] to [6 3] and put barrier at 0, with max steps = 4\n\nExecute Random Walk!\n"}, {"student_agent_score": 80, "random_agent_score": 1, "student_agent_time": 0.008863449096679688, "random_agent_time": 0.008955955505371094, "board_size": 9, "swap_players": true, "run_out": "An exception raised. The traceback is as follows:\nTraceback (most recent call last):\n  File \"/home/ml/users/ksinha4/mlp/comp424_final_project/submissions/comp424mcgill/final-project-a_team_name/world.py\", line 310, in step\n    raise ValueError(\nValueError: [INVALID:STEP] Not a valid step from [3 4] to [3 4] and put barrier at 0, with max steps = 5\n\nExecute Random Walk!\nAn exception raised. The traceback is as follows:\nTraceback (most recent call last):\n  File \"/home/ml/users/ksinha4/mlp/comp424_final_project/submissions/comp424mcgill/final-project-a_team_name/world.py\", line 310, in step\n    raise ValueError(\nValueError: [INVALID:STEP] Not a valid step from [3 5] to [3 5] and put barrier at 0, with max steps = 5\n\nExecute Random Walk!\nAn exception raised. The traceback is as follows:\nTraceback (most recent call last):\n  File \"/home/ml/users/ksinha4/mlp/comp424_final_project/submissions/comp424mcgill/final-project-a_team_name/world.py\", line 310, in step\n    raise ValueError(\nValueError: [INVALID:STEP] Not a valid step from [3 4] to [3 4] and put barrier at 0, with max steps = 5\n\nExecute Random Walk!\nAn exception raised. The traceback is as follows:\nTraceback (most recent call last):\n  File \"/home/ml/users/ksinha4/mlp/comp424_final_project/submissions/comp424mcgill/final-project-a_team_name/world.py\", line 310, in step\n    raise ValueError(\nValueError: [INVALID:STEP] Not a valid step from [5 4] to [5 4] and put barrier at 0, with max steps = 5\n\nExecute Random Walk!\nAn exception raised. The traceback is as follows:\nTraceback (most recent call last):\n  File \"/home/ml/users/ksinha4/mlp/comp424_final_project/submissions/comp424mcgill/final-project-a_team_name/world.py\", line 310, in step\n    raise ValueError(\nValueError: [INVALID:STEP] Not a valid step from [5 5] to [5 5] and put barrier at 0, with max steps = 5\n\nExecute Random Walk!\n"}, {"student_agent_score": 1, "random_agent_score": 48, "student_agent_time": 0.0035543441772460938, "random_agent_time": 0.0032999515533447266, "board_size": 7, "swap_players": true, "run_out": "An exception raised. The traceback is as follows:\nTraceback (most recent call last):\n  File \"/home/ml/users/ksinha4/mlp/comp424_final_project/submissions/comp424mcgill/final-project-a_team_name/world.py\", line 310, in step\n    raise ValueError(\nValueError: [INVALID:STEP] Not a valid step from [2 3] to [2 3] and put barrier at 0, with max steps = 4\n\nExecute Random Walk!\nAn exception raised. The traceback is as follows:\nTraceback (most recent call last):\n  File \"/home/ml/users/ksinha4/mlp/comp424_final_project/submissions/comp424mcgill/final-project-a_team_name/world.py\", line 310, in step\n    raise ValueError(\nValueError: [INVALID:STEP] Not a valid step from [5 4] to [5 4] and put barrier at 0, with max steps = 4\n\nExecute Random Walk!\nAn exception raised. The traceback is as follows:\nTraceback (most recent call last):\n  File \"/home/ml/users/ksinha4/mlp/comp424_final_project/submissions/comp424mcgill/final-project-a_team_name/world.py\", line 310, in step\n    raise ValueError(\nValueError: [INVALID:STEP] Not a valid step from [6 3] to [6 3] and put barrier at 0, with max steps = 4\n\nExecute Random Walk!\n"}, {"student_agent_score": 1, "random_agent_score": 63, "student_agent_time": 0.010865211486816406, "random_agent_time": 0.0019268989562988281, "board_size": 8, "swap_players": false, "run_out": "An exception raised. The traceback is as follows:\nTraceback (most recent call last):\n  File \"/home/ml/users/ksinha4/mlp/comp424_final_project/submissions/comp424mcgill/final-project-a_team_name/world.py\", line 310, in step\n    raise ValueError(\nValueError: [INVALID:STEP] Not a valid step from [2 2] to [2 2] and put barrier at 0, with max steps = 4\n\nExecute Random Walk!\nAn exception raised. The traceback is as follows:\nTraceback (most recent call last):\n  File \"/home/ml/users/ksinha4/mlp/comp424_final_project/submissions/comp424mcgill/final-project-a_team_name/world.py\", line 310, in step\n    raise ValueError(\nValueError: [INVALID:STEP] Not a valid step from [3 1] to [3 1] and put barrier at 0, with max steps = 4\n\nExecute Random Walk!\nAn exception raised. The traceback is as follows:\nTraceback (most recent call last):\n  File \"/home/ml/users/ksinha4/mlp/comp424_final_project/submissions/comp424mcgill/final-project-a_team_name/world.py\", line 310, in step\n    raise ValueError(\nValueError: [INVALID:STEP] Not a valid step from [3 0] to [3 0] and put barrier at 0, with max steps = 4\n\nExecute Random Walk!\nAn exception raised. The traceback is as follows:\nTraceback (most recent call last):\n  File \"/home/ml/users/ksinha4/mlp/comp424_final_project/submissions/comp424mcgill/final-project-a_team_name/world.py\", line 310, in step\n    raise ValueError(\nValueError: [INVALID:STEP] Not a valid step from [6 1] to [6 1] and put barrier at 0, with max steps = 4\n\nExecute Random Walk!\n"}, {"student_agent_score": 1, "random_agent_score": 48, "student_agent_time": 0.0028688907623291016, "random_agent_time": 0.002382516860961914, "board_size": 7, "swap_players": true, "run_out": "An exception raised. The traceback is as follows:\nTraceback (most recent call last):\n  File \"/home/ml/users/ksinha4/mlp/comp424_final_project/submissions/comp424mcgill/final-project-a_team_name/world.py\", line 310, in step\n    raise ValueError(\nValueError: [INVALID:STEP] Not a valid step from [2 3] to [2 3] and put barrier at 0, with max steps = 4\n\nExecute Random Walk!\nAn exception raised. The traceback is as follows:\nTraceback (most recent call last):\n  File \"/home/ml/users/ksinha4/mlp/comp424_final_project/submissions/comp424mcgill/final-project-a_team_name/world.py\", line 310, in step\n    raise ValueError(\nValueError: [INVALID:STEP] Not a valid step from [5 4] to [5 4] and put barrier at 0, with max steps = 4\n\nExecute Random Walk!\nAn exception raised. The traceback is as follows:\nTraceback (most recent call last):\n  File \"/home/ml/users/ksinha4/mlp/comp424_final_project/submissions/comp424mcgill/final-project-a_team_name/world.py\", line 310, in step\n    raise ValueError(\nValueError: [INVALID:STEP] Not a valid step from [6 3] to [6 3] and put barrier at 0, with max steps = 4\n\nExecute Random Walk!\n"}, {"student_agent_score": 1, "random_agent_score": 48, "student_agent_time": 0.004309892654418945, "random_agent_time": 0.0026612281799316406, "board_size": 7, "swap_players": false, "run_out": "An exception raised. The traceback is as follows:\nTraceback (most recent call last):\n  File \"/home/ml/users/ksinha4/mlp/comp424_final_project/submissions/comp424mcgill/final-project-a_team_name/world.py\", line 310, in step\n    raise ValueError(\nValueError: [INVALID:STEP] Not a valid step from [4 3] to [4 3] and put barrier at 0, with max steps = 4\n\nExecute Random Walk!\nAn exception raised. The traceback is as follows:\nTraceback (most recent call last):\n  File \"/home/ml/users/ksinha4/mlp/comp424_final_project/submissions/comp424mcgill/final-project-a_team_name/world.py\", line 310, in step\n    raise ValueError(\nValueError: [INVALID:STEP] Not a valid step from [4 2] to [4 2] and put barrier at 0, with max steps = 4\n\nExecute Random Walk!\nAn exception raised. The traceback is as follows:\nTraceback (most recent call last):\n  File \"/home/ml/users/ksinha4/mlp/comp424_final_project/submissions/comp424mcgill/final-project-a_team_name/world.py\", line 310, in step\n    raise ValueError(\nValueError: [INVALID:STEP] Not a valid step from [4 3] to [4 3] and put barrier at 0, with max steps = 4\n\nExecute Random Walk!\nAn exception raised. The traceback is as follows:\nTraceback (most recent call last):\n  File \"/home/ml/users/ksinha4/mlp/comp424_final_project/submissions/comp424mcgill/final-project-a_team_name/world.py\", line 310, in step\n    raise ValueError(\nValueError: [INVALID:STEP] Not a valid step from [5 4] to [5 4] and put barrier at 0, with max steps = 4\n\nExecute Random Walk!\nAn exception raised. The traceback is as follows:\nTraceback (most recent call last):\n  File \"/home/ml/users/ksinha4/mlp/comp424_final_project/submissions/comp424mcgill/final-project-a_team_name/world.py\", line 310, in step\n    raise ValueError(\nValueError: [INVALID:STEP] Not a valid step from [6 3] to [6 3] and put barrier at 0, with max steps = 4\n\nExecute Random Walk!\n"}, {"student_agent_score": 99, "random_agent_score": 1, "student_agent_time": 0.0003654956817626953, "random_agent_time": 0.0019009113311767578, "board_size": 10, "swap_players": true, "run_out": ""}, {"student_agent_score": 117, "random_agent_score": 1, "student_agent_time": 0.008817195892333984, "random_agent_time": 0.0074083805084228516, "board_size": 11, "swap_players": false, "run_out": "An exception raised. The traceback is as follows:\nTraceback (most recent call last):\n  File \"/home/ml/users/ksinha4/mlp/comp424_final_project/submissions/comp424mcgill/final-project-a_team_name/world.py\", line 310, in step\n    raise ValueError(\nValueError: [INVALID:STEP] Not a valid step from [1 7] to [1 7] and put barrier at 0, with max steps = 6\n\nExecute Random Walk!\nAn exception raised. The traceback is as follows:\nTraceback (most recent call last):\n  File \"/home/ml/users/ksinha4/mlp/comp424_final_project/submissions/comp424mcgill/final-project-a_team_name/world.py\", line 310, in step\n    raise ValueError(\nValueError: [INVALID:STEP] Not a valid step from [1 8] to [1 8] and put barrier at 0, with max steps = 6\n\nExecute Random Walk!\nAn exception raised. The traceback is as follows:\nTraceback (most recent call last):\n  File \"/home/ml/users/ksinha4/mlp/comp424_final_project/submissions/comp424mcgill/final-project-a_team_name/world.py\", line 310, in step\n    raise ValueError(\nValueError: [INVALID:STEP] Not a valid step from [1 6] to [1 6] and put barrier at 0, with max steps = 6\n\nExecute Random Walk!\nAn exception raised. The traceback is as follows:\nTraceback (most recent call last):\n  File \"/home/ml/users/ksinha4/mlp/comp424_final_project/submissions/comp424mcgill/final-project-a_team_name/world.py\", line 310, in step\n    raise ValueError(\nValueError: [INVALID:STEP] Not a valid step from [3 3] to [3 3] and put barrier at 0, with max steps = 6\n\nExecute Random Walk!\nAn exception raised. The traceback is as follows:\nTraceback (most recent call last):\n  File \"/home/ml/users/ksinha4/mlp/comp424_final_project/submissions/comp424mcgill/final-project-a_team_name/world.py\", line 310, in step\n    raise ValueError(\nValueError: [INVALID:STEP] Not a valid step from [3 4] to [3 4] and put barrier at 0, with max steps = 6\n\nExecute Random Walk!\nAn exception raised. The traceback is as follows:\nTraceback (most recent call last):\n  File \"/home/ml/users/ksinha4/mlp/comp424_final_project/submissions/comp424mcgill/final-project-a_team_name/world.py\", line 310, in step\n    raise ValueError(\nValueError: [INVALID:STEP] Not a valid step from [3 4] to [3 4] and put barrier at 0, with max steps = 6\n\nExecute Random Walk!\nAn exception raised. The traceback is as follows:\nTraceback (most recent call last):\n  File \"/home/ml/users/ksinha4/mlp/comp424_final_project/submissions/comp424mcgill/final-project-a_team_name/world.py\", line 310, in step\n    raise ValueError(\nValueError: [INVALID:STEP] Not a valid step from [4 4] to [4 4] and put barrier at 0, with max steps = 6\n\nExecute Random Walk!\nAn exception raised. The traceback is as follows:\nTraceback (most recent call last):\n  File \"/home/ml/users/ksinha4/mlp/comp424_final_project/submissions/comp424mcgill/final-project-a_team_name/world.py\", line 310, in step\n    raise ValueError(\nValueError: [INVALID:STEP] Not a valid step from [4 4] to [4 4] and put barrier at 0, with max steps = 6\n\nExecute Random Walk!\n"}, {"student_agent_score": 1, "random_agent_score": 48, "student_agent_time": 0.005733013153076172, "random_agent_time": 0.002150297164916992, "board_size": 7, "swap_players": false, "run_out": "An exception raised. The traceback is as follows:\nTraceback (most recent call last):\n  File \"/home/ml/users/ksinha4/mlp/comp424_final_project/submissions/comp424mcgill/final-project-a_team_name/world.py\", line 310, in step\n    raise ValueError(\nValueError: [INVALID:STEP] Not a valid step from [4 3] to [4 3] and put barrier at 0, with max steps = 4\n\nExecute Random Walk!\nAn exception raised. The traceback is as follows:\nTraceback (most recent call last):\n  File \"/home/ml/users/ksinha4/mlp/comp424_final_project/submissions/comp424mcgill/final-project-a_team_name/world.py\", line 310, in step\n    raise ValueError(\nValueError: [INVALID:STEP] Not a valid step from [4 2] to [4 2] and put barrier at 0, with max steps = 4\n\nExecute Random Walk!\nAn exception raised. The traceback is as follows:\nTraceback (most recent call last):\n  File \"/home/ml/users/ksinha4/mlp/comp424_final_project/submissions/comp424mcgill/final-project-a_team_name/world.py\", line 310, in step\n    raise ValueError(\nValueError: [INVALID:STEP] Not a valid step from [4 3] to [4 3] and put barrier at 0, with max steps = 4\n\nExecute Random Walk!\nAn exception raised. The traceback is as follows:\nTraceback (most recent call last):\n  File \"/home/ml/users/ksinha4/mlp/comp424_final_project/submissions/comp424mcgill/final-project-a_team_name/world.py\", line 310, in step\n    raise ValueError(\nValueError: [INVALID:STEP] Not a valid step from [5 4] to [5 4] and put barrier at 0, with max steps = 4\n\nExecute Random Walk!\nAn exception raised. The traceback is as follows:\nTraceback (most recent call last):\n  File \"/home/ml/users/ksinha4/mlp/comp424_final_project/submissions/comp424mcgill/final-project-a_team_name/world.py\", line 310, in step\n    raise ValueError(\nValueError: [INVALID:STEP] Not a valid step from [6 3] to [6 3] and put barrier at 0, with max steps = 4\n\nExecute Random Walk!\n"}, {"student_agent_score": 2, "random_agent_score": 98, "student_agent_time": 0.004568338394165039, "random_agent_time": 0.005239725112915039, "board_size": 10, "swap_players": false, "run_out": "An exception raised. The traceback is as follows:\nTraceback (most recent call last):\n  File \"/home/ml/users/ksinha4/mlp/comp424_final_project/submissions/comp424mcgill/final-project-a_team_name/world.py\", line 310, in step\n    raise ValueError(\nValueError: [INVALID:STEP] Not a valid step from [7 5] to [7 5] and put barrier at 0, with max steps = 5\n\nExecute Random Walk!\nAn exception raised. The traceback is as follows:\nTraceback (most recent call last):\n  File \"/home/ml/users/ksinha4/mlp/comp424_final_project/submissions/comp424mcgill/final-project-a_team_name/world.py\", line 310, in step\n    raise ValueError(\nValueError: [INVALID:STEP] Not a valid step from [6 6] to [6 6] and put barrier at 0, with max steps = 5\n\nExecute Random Walk!\nAn exception raised. The traceback is as follows:\nTraceback (most recent call last):\n  File \"/home/ml/users/ksinha4/mlp/comp424_final_project/submissions/comp424mcgill/final-project-a_team_name/world.py\", line 310, in step\n    raise ValueError(\nValueError: [INVALID:STEP] Not a valid step from [7 8] to [7 8] and put barrier at 0, with max steps = 5\n\nExecute Random Walk!\nAn exception raised. The traceback is as follows:\nTraceback (most recent call last):\n  File \"/home/ml/users/ksinha4/mlp/comp424_final_project/submissions/comp424mcgill/final-project-a_team_name/world.py\", line 310, in step\n    raise ValueError(\nValueError: [INVALID:STEP] Not a valid step from [7 8] to [7 8] and put barrier at 0, with max steps = 5\n\nExecute Random Walk!\n"}, {"student_agent_score": 1, "random_agent_score": 48, "student_agent_time": 0.0043506622314453125, "random_agent_time": 0.00379180908203125, "board_size": 7, "swap_players": false, "run_out": "An exception raised. The traceback is as follows:\nTraceback (most recent call last):\n  File \"/home/ml/users/ksinha4/mlp/comp424_final_project/submissions/comp424mcgill/final-project-a_team_name/world.py\", line 310, in step\n    raise ValueError(\nValueError: [INVALID:STEP] Not a valid step from [4 3] to [4 3] and put barrier at 0, with max steps = 4\n\nExecute Random Walk!\nAn exception raised. The traceback is as follows:\nTraceback (most recent call last):\n  File \"/home/ml/users/ksinha4/mlp/comp424_final_project/submissions/comp424mcgill/final-project-a_team_name/world.py\", line 310, in step\n    raise ValueError(\nValueError: [INVALID:STEP] Not a valid step from [4 2] to [4 2] and put barrier at 0, with max steps = 4\n\nExecute Random Walk!\nAn exception raised. The traceback is as follows:\nTraceback (most recent call last):\n  File \"/home/ml/users/ksinha4/mlp/comp424_final_project/submissions/comp424mcgill/final-project-a_team_name/world.py\", line 310, in step\n    raise ValueError(\nValueError: [INVALID:STEP] Not a valid step from [4 3] to [4 3] and put barrier at 0, with max steps = 4\n\nExecute Random Walk!\nAn exception raised. The traceback is as follows:\nTraceback (most recent call last):\n  File \"/home/ml/users/ksinha4/mlp/comp424_final_project/submissions/comp424mcgill/final-project-a_team_name/world.py\", line 310, in step\n    raise ValueError(\nValueError: [INVALID:STEP] Not a valid step from [5 4] to [5 4] and put barrier at 0, with max steps = 4\n\nExecute Random Walk!\nAn exception raised. The traceback is as follows:\nTraceback (most recent call last):\n  File \"/home/ml/users/ksinha4/mlp/comp424_final_project/submissions/comp424mcgill/final-project-a_team_name/world.py\", line 310, in step\n    raise ValueError(\nValueError: [INVALID:STEP] Not a valid step from [6 3] to [6 3] and put barrier at 0, with max steps = 4\n\nExecute Random Walk!\n"}, {"student_agent_score": 1, "random_agent_score": 48, "student_agent_time": 0.0042607784271240234, "random_agent_time": 0.002003192901611328, "board_size": 7, "swap_players": false, "run_out": "An exception raised. The traceback is as follows:\nTraceback (most recent call last):\n  File \"/home/ml/users/ksinha4/mlp/comp424_final_project/submissions/comp424mcgill/final-project-a_team_name/world.py\", line 310, in step\n    raise ValueError(\nValueError: [INVALID:STEP] Not a valid step from [4 3] to [4 3] and put barrier at 0, with max steps = 4\n\nExecute Random Walk!\nAn exception raised. The traceback is as follows:\nTraceback (most recent call last):\n  File \"/home/ml/users/ksinha4/mlp/comp424_final_project/submissions/comp424mcgill/final-project-a_team_name/world.py\", line 310, in step\n    raise ValueError(\nValueError: [INVALID:STEP] Not a valid step from [4 2] to [4 2] and put barrier at 0, with max steps = 4\n\nExecute Random Walk!\nAn exception raised. The traceback is as follows:\nTraceback (most recent call last):\n  File \"/home/ml/users/ksinha4/mlp/comp424_final_project/submissions/comp424mcgill/final-project-a_team_name/world.py\", line 310, in step\n    raise ValueError(\nValueError: [INVALID:STEP] Not a valid step from [4 3] to [4 3] and put barrier at 0, with max steps = 4\n\nExecute Random Walk!\nAn exception raised. The traceback is as follows:\nTraceback (most recent call last):\n  File \"/home/ml/users/ksinha4/mlp/comp424_final_project/submissions/comp424mcgill/final-project-a_team_name/world.py\", line 310, in step\n    raise ValueError(\nValueError: [INVALID:STEP] Not a valid step from [5 4] to [5 4] and put barrier at 0, with max steps = 4\n\nExecute Random Walk!\nAn exception raised. The traceback is as follows:\nTraceback (most recent call last):\n  File \"/home/ml/users/ksinha4/mlp/comp424_final_project/submissions/comp424mcgill/final-project-a_team_name/world.py\", line 310, in step\n    raise ValueError(\nValueError: [INVALID:STEP] Not a valid step from [6 3] to [6 3] and put barrier at 0, with max steps = 4\n\nExecute Random Walk!\n"}, {"student_agent_score": 1, "random_agent_score": 35, "student_agent_time": 0.002320528030395508, "random_agent_time": 0.002547740936279297, "board_size": 6, "swap_players": true, "run_out": "An exception raised. The traceback is as follows:\nTraceback (most recent call last):\n  File \"/home/ml/users/ksinha4/mlp/comp424_final_project/submissions/comp424mcgill/final-project-a_team_name/world.py\", line 310, in step\n    raise ValueError(\nValueError: [INVALID:STEP] Not a valid step from [3 3] to [3 3] and put barrier at 0, with max steps = 3\n\nExecute Random Walk!\nAn exception raised. The traceback is as follows:\nTraceback (most recent call last):\n  File \"/home/ml/users/ksinha4/mlp/comp424_final_project/submissions/comp424mcgill/final-project-a_team_name/world.py\", line 310, in step\n    raise ValueError(\nValueError: [INVALID:STEP] Not a valid step from [3 3] to [3 3] and put barrier at 0, with max steps = 3\n\nExecute Random Walk!\n"}, {"student_agent_score": 1, "random_agent_score": 48, "student_agent_time": 0.00305938720703125, "random_agent_time": 0.004333019256591797, "board_size": 7, "swap_players": true, "run_out": "An exception raised. The traceback is as follows:\nTraceback (most recent call last):\n  File \"/home/ml/users/ksinha4/mlp/comp424_final_project/submissions/comp424mcgill/final-project-a_team_name/world.py\", line 310, in step\n    raise ValueError(\nValueError: [INVALID:STEP] Not a valid step from [2 3] to [2 3] and put barrier at 0, with max steps = 4\n\nExecute Random Walk!\nAn exception raised. The traceback is as follows:\nTraceback (most recent call last):\n  File \"/home/ml/users/ksinha4/mlp/comp424_final_project/submissions/comp424mcgill/final-project-a_team_name/world.py\", line 310, in step\n    raise ValueError(\nValueError: [INVALID:STEP] Not a valid step from [5 4] to [5 4] and put barrier at 0, with max steps = 4\n\nExecute Random Walk!\nAn exception raised. The traceback is as follows:\nTraceback (most recent call last):\n  File \"/home/ml/users/ksinha4/mlp/comp424_final_project/submissions/comp424mcgill/final-project-a_team_name/world.py\", line 310, in step\n    raise ValueError(\nValueError: [INVALID:STEP] Not a valid step from [6 3] to [6 3] and put barrier at 0, with max steps = 4\n\nExecute Random Walk!\n"}, {"student_agent_score": 63, "random_agent_score": 1, "student_agent_time": 0.0024678707122802734, "random_agent_time": 0.0026061534881591797, "board_size": 8, "swap_players": true, "run_out": "An exception raised. The traceback is as follows:\nTraceback (most recent call last):\n  File \"/home/ml/users/ksinha4/mlp/comp424_final_project/submissions/comp424mcgill/final-project-a_team_name/world.py\", line 310, in step\n    raise ValueError(\nValueError: [INVALID:STEP] Not a valid step from [5 5] to [5 5] and put barrier at 0, with max steps = 4\n\nExecute Random Walk!\nAn exception raised. The traceback is as follows:\nTraceback (most recent call last):\n  File \"/home/ml/users/ksinha4/mlp/comp424_final_project/submissions/comp424mcgill/final-project-a_team_name/world.py\", line 310, in step\n    raise ValueError(\nValueError: [INVALID:STEP] Not a valid step from [5 4] to [5 4] and put barrier at 0, with max steps = 4\n\nExecute Random Walk!\nAn exception raised. The traceback is as follows:\nTraceback (most recent call last):\n  File \"/home/ml/users/ksinha4/mlp/comp424_final_project/submissions/comp424mcgill/final-project-a_team_name/world.py\", line 310, in step\n    raise ValueError(\nValueError: [INVALID:STEP] Not a valid step from [5 4] to [5 4] and put barrier at 0, with max steps = 4\n\nExecute Random Walk!\n"}, {"student_agent_score": 1, "random_agent_score": 48, "student_agent_time": 0.0023250579833984375, "random_agent_time": 0.0018970966339111328, "board_size": 7, "swap_players": true, "run_out": "An exception raised. The traceback is as follows:\nTraceback (most recent call last):\n  File \"/home/ml/users/ksinha4/mlp/comp424_final_project/submissions/comp424mcgill/final-project-a_team_name/world.py\", line 310, in step\n    raise ValueError(\nValueError: [INVALID:STEP] Not a valid step from [2 3] to [2 3] and put barrier at 0, with max steps = 4\n\nExecute Random Walk!\nAn exception raised. The traceback is as follows:\nTraceback (most recent call last):\n  File \"/home/ml/users/ksinha4/mlp/comp424_final_project/submissions/comp424mcgill/final-project-a_team_name/world.py\", line 310, in step\n    raise ValueError(\nValueError: [INVALID:STEP] Not a valid step from [5 4] to [5 4] and put barrier at 0, with max steps = 4\n\nExecute Random Walk!\nAn exception raised. The traceback is as follows:\nTraceback (most recent call last):\n  File \"/home/ml/users/ksinha4/mlp/comp424_final_project/submissions/comp424mcgill/final-project-a_team_name/world.py\", line 310, in step\n    raise ValueError(\nValueError: [INVALID:STEP] Not a valid step from [6 3] to [6 3] and put barrier at 0, with max steps = 4\n\nExecute Random Walk!\n"}, {"student_agent_score": 1, "random_agent_score": 48, "student_agent_time": 0.0050318241119384766, "random_agent_time": 0.002231597900390625, "board_size": 7, "swap_players": false, "run_out": "An exception raised. The traceback is as follows:\nTraceback (most recent call last):\n  File \"/home/ml/users/ksinha4/mlp/comp424_final_project/submissions/comp424mcgill/final-project-a_team_name/world.py\", line 310, in step\n    raise ValueError(\nValueError: [INVALID:STEP] Not a valid step from [4 3] to [4 3] and put barrier at 0, with max steps = 4\n\nExecute Random Walk!\nAn exception raised. The traceback is as follows:\nTraceback (most recent call last):\n  File \"/home/ml/users/ksinha4/mlp/comp424_final_project/submissions/comp424mcgill/final-project-a_team_name/world.py\", line 310, in step\n    raise ValueError(\nValueError: [INVALID:STEP] Not a valid step from [4 2] to [4 2] and put barrier at 0, with max steps = 4\n\nExecute Random Walk!\nAn exception raised. The traceback is as follows:\nTraceback (most recent call last):\n  File \"/home/ml/users/ksinha4/mlp/comp424_final_project/submissions/comp424mcgill/final-project-a_team_name/world.py\", line 310, in step\n    raise ValueError(\nValueError: [INVALID:STEP] Not a valid step from [4 3] to [4 3] and put barrier at 0, with max steps = 4\n\nExecute Random Walk!\nAn exception raised. The traceback is as follows:\nTraceback (most recent call last):\n  File \"/home/ml/users/ksinha4/mlp/comp424_final_project/submissions/comp424mcgill/final-project-a_team_name/world.py\", line 310, in step\n    raise ValueError(\nValueError: [INVALID:STEP] Not a valid step from [5 4] to [5 4] and put barrier at 0, with max steps = 4\n\nExecute Random Walk!\nAn exception raised. The traceback is as follows:\nTraceback (most recent call last):\n  File \"/home/ml/users/ksinha4/mlp/comp424_final_project/submissions/comp424mcgill/final-project-a_team_name/world.py\", line 310, in step\n    raise ValueError(\nValueError: [INVALID:STEP] Not a valid step from [6 3] to [6 3] and put barrier at 0, with max steps = 4\n\nExecute Random Walk!\n"}, {"student_agent_score": 80, "random_agent_score": 1, "student_agent_time": 0.005664348602294922, "random_agent_time": 0.008391857147216797, "board_size": 9, "swap_players": true, "run_out": "An exception raised. The traceback is as follows:\nTraceback (most recent call last):\n  File \"/home/ml/users/ksinha4/mlp/comp424_final_project/submissions/comp424mcgill/final-project-a_team_name/world.py\", line 310, in step\n    raise ValueError(\nValueError: [INVALID:STEP] Not a valid step from [3 4] to [3 4] and put barrier at 0, with max steps = 5\n\nExecute Random Walk!\nAn exception raised. The traceback is as follows:\nTraceback (most recent call last):\n  File \"/home/ml/users/ksinha4/mlp/comp424_final_project/submissions/comp424mcgill/final-project-a_team_name/world.py\", line 310, in step\n    raise ValueError(\nValueError: [INVALID:STEP] Not a valid step from [3 5] to [3 5] and put barrier at 0, with max steps = 5\n\nExecute Random Walk!\nAn exception raised. The traceback is as follows:\nTraceback (most recent call last):\n  File \"/home/ml/users/ksinha4/mlp/comp424_final_project/submissions/comp424mcgill/final-project-a_team_name/world.py\", line 310, in step\n    raise ValueError(\nValueError: [INVALID:STEP] Not a valid step from [3 4] to [3 4] and put barrier at 0, with max steps = 5\n\nExecute Random Walk!\nAn exception raised. The traceback is as follows:\nTraceback (most recent call last):\n  File \"/home/ml/users/ksinha4/mlp/comp424_final_project/submissions/comp424mcgill/final-project-a_team_name/world.py\", line 310, in step\n    raise ValueError(\nValueError: [INVALID:STEP] Not a valid step from [5 4] to [5 4] and put barrier at 0, with max steps = 5\n\nExecute Random Walk!\nAn exception raised. The traceback is as follows:\nTraceback (most recent call last):\n  File \"/home/ml/users/ksinha4/mlp/comp424_final_project/submissions/comp424mcgill/final-project-a_team_name/world.py\", line 310, in step\n    raise ValueError(\nValueError: [INVALID:STEP] Not a valid step from [5 5] to [5 5] and put barrier at 0, with max steps = 5\n\nExecute Random Walk!\n"}, {"student_agent_score": 1, "random_agent_score": 48, "student_agent_time": 0.0048787593841552734, "random_agent_time": 0.001928567886352539, "board_size": 7, "swap_players": false, "run_out": "An exception raised. The traceback is as follows:\nTraceback (most recent call last):\n  File \"/home/ml/users/ksinha4/mlp/comp424_final_project/submissions/comp424mcgill/final-project-a_team_name/world.py\", line 310, in step\n    raise ValueError(\nValueError: [INVALID:STEP] Not a valid step from [4 3] to [4 3] and put barrier at 0, with max steps = 4\n\nExecute Random Walk!\nAn exception raised. The traceback is as follows:\nTraceback (most recent call last):\n  File \"/home/ml/users/ksinha4/mlp/comp424_final_project/submissions/comp424mcgill/final-project-a_team_name/world.py\", line 310, in step\n    raise ValueError(\nValueError: [INVALID:STEP] Not a valid step from [4 2] to [4 2] and put barrier at 0, with max steps = 4\n\nExecute Random Walk!\nAn exception raised. The traceback is as follows:\nTraceback (most recent call last):\n  File \"/home/ml/users/ksinha4/mlp/comp424_final_project/submissions/comp424mcgill/final-project-a_team_name/world.py\", line 310, in step\n    raise ValueError(\nValueError: [INVALID:STEP] Not a valid step from [4 3] to [4 3] and put barrier at 0, with max steps = 4\n\nExecute Random Walk!\nAn exception raised. The traceback is as follows:\nTraceback (most recent call last):\n  File \"/home/ml/users/ksinha4/mlp/comp424_final_project/submissions/comp424mcgill/final-project-a_team_name/world.py\", line 310, in step\n    raise ValueError(\nValueError: [INVALID:STEP] Not a valid step from [5 4] to [5 4] and put barrier at 0, with max steps = 4\n\nExecute Random Walk!\nAn exception raised. The traceback is as follows:\nTraceback (most recent call last):\n  File \"/home/ml/users/ksinha4/mlp/comp424_final_project/submissions/comp424mcgill/final-project-a_team_name/world.py\", line 310, in step\n    raise ValueError(\nValueError: [INVALID:STEP] Not a valid step from [6 3] to [6 3] and put barrier at 0, with max steps = 4\n\nExecute Random Walk!\n"}, {"student_agent_score": 1, "random_agent_score": 48, "student_agent_time": 0.003349781036376953, "random_agent_time": 0.0030078887939453125, "board_size": 7, "swap_players": true, "run_out": "An exception raised. The traceback is as follows:\nTraceback (most recent call last):\n  File \"/home/ml/users/ksinha4/mlp/comp424_final_project/submissions/comp424mcgill/final-project-a_team_name/world.py\", line 310, in step\n    raise ValueError(\nValueError: [INVALID:STEP] Not a valid step from [2 3] to [2 3] and put barrier at 0, with max steps = 4\n\nExecute Random Walk!\nAn exception raised. The traceback is as follows:\nTraceback (most recent call last):\n  File \"/home/ml/users/ksinha4/mlp/comp424_final_project/submissions/comp424mcgill/final-project-a_team_name/world.py\", line 310, in step\n    raise ValueError(\nValueError: [INVALID:STEP] Not a valid step from [5 4] to [5 4] and put barrier at 0, with max steps = 4\n\nExecute Random Walk!\nAn exception raised. The traceback is as follows:\nTraceback (most recent call last):\n  File \"/home/ml/users/ksinha4/mlp/comp424_final_project/submissions/comp424mcgill/final-project-a_team_name/world.py\", line 310, in step\n    raise ValueError(\nValueError: [INVALID:STEP] Not a valid step from [6 3] to [6 3] and put barrier at 0, with max steps = 4\n\nExecute Random Walk!\n"}, {"student_agent_score": 1, "random_agent_score": 48, "student_agent_time": 0.0023021697998046875, "random_agent_time": 0.0024437904357910156, "board_size": 7, "swap_players": true, "run_out": "An exception raised. The traceback is as follows:\nTraceback (most recent call last):\n  File \"/home/ml/users/ksinha4/mlp/comp424_final_project/submissions/comp424mcgill/final-project-a_team_name/world.py\", line 310, in step\n    raise ValueError(\nValueError: [INVALID:STEP] Not a valid step from [2 3] to [2 3] and put barrier at 0, with max steps = 4\n\nExecute Random Walk!\nAn exception raised. The traceback is as follows:\nTraceback (most recent call last):\n  File \"/home/ml/users/ksinha4/mlp/comp424_final_project/submissions/comp424mcgill/final-project-a_team_name/world.py\", line 310, in step\n    raise ValueError(\nValueError: [INVALID:STEP] Not a valid step from [5 4] to [5 4] and put barrier at 0, with max steps = 4\n\nExecute Random Walk!\nAn exception raised. The traceback is as follows:\nTraceback (most recent call last):\n  File \"/home/ml/users/ksinha4/mlp/comp424_final_project/submissions/comp424mcgill/final-project-a_team_name/world.py\", line 310, in step\n    raise ValueError(\nValueError: [INVALID:STEP] Not a valid step from [6 3] to [6 3] and put barrier at 0, with max steps = 4\n\nExecute Random Walk!\n"}, {"student_agent_score": 1, "random_agent_score": 48, "student_agent_time": 0.004091501235961914, "random_agent_time": 0.0037453174591064453, "board_size": 7, "swap_players": false, "run_out": "An exception raised. The traceback is as follows:\nTraceback (most recent call last):\n  File \"/home/ml/users/ksinha4/mlp/comp424_final_project/submissions/comp424mcgill/final-project-a_team_name/world.py\", line 310, in step\n    raise ValueError(\nValueError: [INVALID:STEP] Not a valid step from [4 3] to [4 3] and put barrier at 0, with max steps = 4\n\nExecute Random Walk!\nAn exception raised. The traceback is as follows:\nTraceback (most recent call last):\n  File \"/home/ml/users/ksinha4/mlp/comp424_final_project/submissions/comp424mcgill/final-project-a_team_name/world.py\", line 310, in step\n    raise ValueError(\nValueError: [INVALID:STEP] Not a valid step from [4 2] to [4 2] and put barrier at 0, with max steps = 4\n\nExecute Random Walk!\nAn exception raised. The traceback is as follows:\nTraceback (most recent call last):\n  File \"/home/ml/users/ksinha4/mlp/comp424_final_project/submissions/comp424mcgill/final-project-a_team_name/world.py\", line 310, in step\n    raise ValueError(\nValueError: [INVALID:STEP] Not a valid step from [4 3] to [4 3] and put barrier at 0, with max steps = 4\n\nExecute Random Walk!\nAn exception raised. The traceback is as follows:\nTraceback (most recent call last):\n  File \"/home/ml/users/ksinha4/mlp/comp424_final_project/submissions/comp424mcgill/final-project-a_team_name/world.py\", line 310, in step\n    raise ValueError(\nValueError: [INVALID:STEP] Not a valid step from [5 4] to [5 4] and put barrier at 0, with max steps = 4\n\nExecute Random Walk!\nAn exception raised. The traceback is as follows:\nTraceback (most recent call last):\n  File \"/home/ml/users/ksinha4/mlp/comp424_final_project/submissions/comp424mcgill/final-project-a_team_name/world.py\", line 310, in step\n    raise ValueError(\nValueError: [INVALID:STEP] Not a valid step from [6 3] to [6 3] and put barrier at 0, with max steps = 4\n\nExecute Random Walk!\n"}, {"student_agent_score": 1, "random_agent_score": 48, "student_agent_time": 0.0034227371215820312, "random_agent_time": 0.0028913021087646484, "board_size": 7, "swap_players": false, "run_out": "An exception raised. The traceback is as follows:\nTraceback (most recent call last):\n  File \"/home/ml/users/ksinha4/mlp/comp424_final_project/submissions/comp424mcgill/final-project-a_team_name/world.py\", line 310, in step\n    raise ValueError(\nValueError: [INVALID:STEP] Not a valid step from [4 3] to [4 3] and put barrier at 0, with max steps = 4\n\nExecute Random Walk!\nAn exception raised. The traceback is as follows:\nTraceback (most recent call last):\n  File \"/home/ml/users/ksinha4/mlp/comp424_final_project/submissions/comp424mcgill/final-project-a_team_name/world.py\", line 310, in step\n    raise ValueError(\nValueError: [INVALID:STEP] Not a valid step from [4 2] to [4 2] and put barrier at 0, with max steps = 4\n\nExecute Random Walk!\nAn exception raised. The traceback is as follows:\nTraceback (most recent call last):\n  File \"/home/ml/users/ksinha4/mlp/comp424_final_project/submissions/comp424mcgill/final-project-a_team_name/world.py\", line 310, in step\n    raise ValueError(\nValueError: [INVALID:STEP] Not a valid step from [4 3] to [4 3] and put barrier at 0, with max steps = 4\n\nExecute Random Walk!\nAn exception raised. The traceback is as follows:\nTraceback (most recent call last):\n  File \"/home/ml/users/ksinha4/mlp/comp424_final_project/submissions/comp424mcgill/final-project-a_team_name/world.py\", line 310, in step\n    raise ValueError(\nValueError: [INVALID:STEP] Not a valid step from [5 4] to [5 4] and put barrier at 0, with max steps = 4\n\nExecute Random Walk!\nAn exception raised. The traceback is as follows:\nTraceback (most recent call last):\n  File \"/home/ml/users/ksinha4/mlp/comp424_final_project/submissions/comp424mcgill/final-project-a_team_name/world.py\", line 310, in step\n    raise ValueError(\nValueError: [INVALID:STEP] Not a valid step from [6 3] to [6 3] and put barrier at 0, with max steps = 4\n\nExecute Random Walk!\n"}, {"student_agent_score": 1, "random_agent_score": 48, "student_agent_time": 0.002591848373413086, "random_agent_time": 0.0021071434020996094, "board_size": 7, "swap_players": true, "run_out": "An exception raised. The traceback is as follows:\nTraceback (most recent call last):\n  File \"/home/ml/users/ksinha4/mlp/comp424_final_project/submissions/comp424mcgill/final-project-a_team_name/world.py\", line 310, in step\n    raise ValueError(\nValueError: [INVALID:STEP] Not a valid step from [2 3] to [2 3] and put barrier at 0, with max steps = 4\n\nExecute Random Walk!\nAn exception raised. The traceback is as follows:\nTraceback (most recent call last):\n  File \"/home/ml/users/ksinha4/mlp/comp424_final_project/submissions/comp424mcgill/final-project-a_team_name/world.py\", line 310, in step\n    raise ValueError(\nValueError: [INVALID:STEP] Not a valid step from [5 4] to [5 4] and put barrier at 0, with max steps = 4\n\nExecute Random Walk!\nAn exception raised. The traceback is as follows:\nTraceback (most recent call last):\n  File \"/home/ml/users/ksinha4/mlp/comp424_final_project/submissions/comp424mcgill/final-project-a_team_name/world.py\", line 310, in step\n    raise ValueError(\nValueError: [INVALID:STEP] Not a valid step from [6 3] to [6 3] and put barrier at 0, with max steps = 4\n\nExecute Random Walk!\n"}, {"student_agent_score": 1, "random_agent_score": 48, "student_agent_time": 0.006931781768798828, "random_agent_time": 0.0024843215942382812, "board_size": 7, "swap_players": false, "run_out": "An exception raised. The traceback is as follows:\nTraceback (most recent call last):\n  File \"/home/ml/users/ksinha4/mlp/comp424_final_project/submissions/comp424mcgill/final-project-a_team_name/world.py\", line 310, in step\n    raise ValueError(\nValueError: [INVALID:STEP] Not a valid step from [4 3] to [4 3] and put barrier at 0, with max steps = 4\n\nExecute Random Walk!\nAn exception raised. The traceback is as follows:\nTraceback (most recent call last):\n  File \"/home/ml/users/ksinha4/mlp/comp424_final_project/submissions/comp424mcgill/final-project-a_team_name/world.py\", line 310, in step\n    raise ValueError(\nValueError: [INVALID:STEP] Not a valid step from [4 2] to [4 2] and put barrier at 0, with max steps = 4\n\nExecute Random Walk!\nAn exception raised. The traceback is as follows:\nTraceback (most recent call last):\n  File \"/home/ml/users/ksinha4/mlp/comp424_final_project/submissions/comp424mcgill/final-project-a_team_name/world.py\", line 310, in step\n    raise ValueError(\nValueError: [INVALID:STEP] Not a valid step from [4 3] to [4 3] and put barrier at 0, with max steps = 4\n\nExecute Random Walk!\nAn exception raised. The traceback is as follows:\nTraceback (most recent call last):\n  File \"/home/ml/users/ksinha4/mlp/comp424_final_project/submissions/comp424mcgill/final-project-a_team_name/world.py\", line 310, in step\n    raise ValueError(\nValueError: [INVALID:STEP] Not a valid step from [5 4] to [5 4] and put barrier at 0, with max steps = 4\n\nExecute Random Walk!\nAn exception raised. The traceback is as follows:\nTraceback (most recent call last):\n  File \"/home/ml/users/ksinha4/mlp/comp424_final_project/submissions/comp424mcgill/final-project-a_team_name/world.py\", line 310, in step\n    raise ValueError(\nValueError: [INVALID:STEP] Not a valid step from [6 3] to [6 3] and put barrier at 0, with max steps = 4\n\nExecute Random Walk!\n"}, {"student_agent_score": 1, "random_agent_score": 48, "student_agent_time": 0.004671335220336914, "random_agent_time": 0.0030975341796875, "board_size": 7, "swap_players": false, "run_out": "An exception raised. The traceback is as follows:\nTraceback (most recent call last):\n  File \"/home/ml/users/ksinha4/mlp/comp424_final_project/submissions/comp424mcgill/final-project-a_team_name/world.py\", line 310, in step\n    raise ValueError(\nValueError: [INVALID:STEP] Not a valid step from [4 3] to [4 3] and put barrier at 0, with max steps = 4\n\nExecute Random Walk!\nAn exception raised. The traceback is as follows:\nTraceback (most recent call last):\n  File \"/home/ml/users/ksinha4/mlp/comp424_final_project/submissions/comp424mcgill/final-project-a_team_name/world.py\", line 310, in step\n    raise ValueError(\nValueError: [INVALID:STEP] Not a valid step from [4 2] to [4 2] and put barrier at 0, with max steps = 4\n\nExecute Random Walk!\nAn exception raised. The traceback is as follows:\nTraceback (most recent call last):\n  File \"/home/ml/users/ksinha4/mlp/comp424_final_project/submissions/comp424mcgill/final-project-a_team_name/world.py\", line 310, in step\n    raise ValueError(\nValueError: [INVALID:STEP] Not a valid step from [4 3] to [4 3] and put barrier at 0, with max steps = 4\n\nExecute Random Walk!\nAn exception raised. The traceback is as follows:\nTraceback (most recent call last):\n  File \"/home/ml/users/ksinha4/mlp/comp424_final_project/submissions/comp424mcgill/final-project-a_team_name/world.py\", line 310, in step\n    raise ValueError(\nValueError: [INVALID:STEP] Not a valid step from [5 4] to [5 4] and put barrier at 0, with max steps = 4\n\nExecute Random Walk!\nAn exception raised. The traceback is as follows:\nTraceback (most recent call last):\n  File \"/home/ml/users/ksinha4/mlp/comp424_final_project/submissions/comp424mcgill/final-project-a_team_name/world.py\", line 310, in step\n    raise ValueError(\nValueError: [INVALID:STEP] Not a valid step from [6 3] to [6 3] and put barrier at 0, with max steps = 4\n\nExecute Random Walk!\n"}, {"student_agent_score": 80, "random_agent_score": 1, "student_agent_time": 0.005810737609863281, "random_agent_time": 0.0048215389251708984, "board_size": 9, "swap_players": true, "run_out": "An exception raised. The traceback is as follows:\nTraceback (most recent call last):\n  File \"/home/ml/users/ksinha4/mlp/comp424_final_project/submissions/comp424mcgill/final-project-a_team_name/world.py\", line 310, in step\n    raise ValueError(\nValueError: [INVALID:STEP] Not a valid step from [3 4] to [3 4] and put barrier at 0, with max steps = 5\n\nExecute Random Walk!\nAn exception raised. The traceback is as follows:\nTraceback (most recent call last):\n  File \"/home/ml/users/ksinha4/mlp/comp424_final_project/submissions/comp424mcgill/final-project-a_team_name/world.py\", line 310, in step\n    raise ValueError(\nValueError: [INVALID:STEP] Not a valid step from [3 5] to [3 5] and put barrier at 0, with max steps = 5\n\nExecute Random Walk!\nAn exception raised. The traceback is as follows:\nTraceback (most recent call last):\n  File \"/home/ml/users/ksinha4/mlp/comp424_final_project/submissions/comp424mcgill/final-project-a_team_name/world.py\", line 310, in step\n    raise ValueError(\nValueError: [INVALID:STEP] Not a valid step from [3 4] to [3 4] and put barrier at 0, with max steps = 5\n\nExecute Random Walk!\nAn exception raised. The traceback is as follows:\nTraceback (most recent call last):\n  File \"/home/ml/users/ksinha4/mlp/comp424_final_project/submissions/comp424mcgill/final-project-a_team_name/world.py\", line 310, in step\n    raise ValueError(\nValueError: [INVALID:STEP] Not a valid step from [5 4] to [5 4] and put barrier at 0, with max steps = 5\n\nExecute Random Walk!\nAn exception raised. The traceback is as follows:\nTraceback (most recent call last):\n  File \"/home/ml/users/ksinha4/mlp/comp424_final_project/submissions/comp424mcgill/final-project-a_team_name/world.py\", line 310, in step\n    raise ValueError(\nValueError: [INVALID:STEP] Not a valid step from [5 5] to [5 5] and put barrier at 0, with max steps = 5\n\nExecute Random Walk!\n"}, {"student_agent_score": 117, "random_agent_score": 1, "student_agent_time": 0.007986307144165039, "random_agent_time": 0.008548736572265625, "board_size": 11, "swap_players": false, "run_out": "An exception raised. The traceback is as follows:\nTraceback (most recent call last):\n  File \"/home/ml/users/ksinha4/mlp/comp424_final_project/submissions/comp424mcgill/final-project-a_team_name/world.py\", line 310, in step\n    raise ValueError(\nValueError: [INVALID:STEP] Not a valid step from [1 7] to [1 7] and put barrier at 0, with max steps = 6\n\nExecute Random Walk!\nAn exception raised. The traceback is as follows:\nTraceback (most recent call last):\n  File \"/home/ml/users/ksinha4/mlp/comp424_final_project/submissions/comp424mcgill/final-project-a_team_name/world.py\", line 310, in step\n    raise ValueError(\nValueError: [INVALID:STEP] Not a valid step from [1 8] to [1 8] and put barrier at 0, with max steps = 6\n\nExecute Random Walk!\nAn exception raised. The traceback is as follows:\nTraceback (most recent call last):\n  File \"/home/ml/users/ksinha4/mlp/comp424_final_project/submissions/comp424mcgill/final-project-a_team_name/world.py\", line 310, in step\n    raise ValueError(\nValueError: [INVALID:STEP] Not a valid step from [1 6] to [1 6] and put barrier at 0, with max steps = 6\n\nExecute Random Walk!\nAn exception raised. The traceback is as follows:\nTraceback (most recent call last):\n  File \"/home/ml/users/ksinha4/mlp/comp424_final_project/submissions/comp424mcgill/final-project-a_team_name/world.py\", line 310, in step\n    raise ValueError(\nValueError: [INVALID:STEP] Not a valid step from [3 3] to [3 3] and put barrier at 0, with max steps = 6\n\nExecute Random Walk!\nAn exception raised. The traceback is as follows:\nTraceback (most recent call last):\n  File \"/home/ml/users/ksinha4/mlp/comp424_final_project/submissions/comp424mcgill/final-project-a_team_name/world.py\", line 310, in step\n    raise ValueError(\nValueError: [INVALID:STEP] Not a valid step from [3 4] to [3 4] and put barrier at 0, with max steps = 6\n\nExecute Random Walk!\nAn exception raised. The traceback is as follows:\nTraceback (most recent call last):\n  File \"/home/ml/users/ksinha4/mlp/comp424_final_project/submissions/comp424mcgill/final-project-a_team_name/world.py\", line 310, in step\n    raise ValueError(\nValueError: [INVALID:STEP] Not a valid step from [3 4] to [3 4] and put barrier at 0, with max steps = 6\n\nExecute Random Walk!\nAn exception raised. The traceback is as follows:\nTraceback (most recent call last):\n  File \"/home/ml/users/ksinha4/mlp/comp424_final_project/submissions/comp424mcgill/final-project-a_team_name/world.py\", line 310, in step\n    raise ValueError(\nValueError: [INVALID:STEP] Not a valid step from [4 4] to [4 4] and put barrier at 0, with max steps = 6\n\nExecute Random Walk!\nAn exception raised. The traceback is as follows:\nTraceback (most recent call last):\n  File \"/home/ml/users/ksinha4/mlp/comp424_final_project/submissions/comp424mcgill/final-project-a_team_name/world.py\", line 310, in step\n    raise ValueError(\nValueError: [INVALID:STEP] Not a valid step from [4 4] to [4 4] and put barrier at 0, with max steps = 6\n\nExecute Random Walk!\n"}, {"student_agent_score": 1, "random_agent_score": 48, "student_agent_time": 0.003759622573852539, "random_agent_time": 0.005230426788330078, "board_size": 7, "swap_players": true, "run_out": "An exception raised. The traceback is as follows:\nTraceback (most recent call last):\n  File \"/home/ml/users/ksinha4/mlp/comp424_final_project/submissions/comp424mcgill/final-project-a_team_name/world.py\", line 310, in step\n    raise ValueError(\nValueError: [INVALID:STEP] Not a valid step from [2 3] to [2 3] and put barrier at 0, with max steps = 4\n\nExecute Random Walk!\nAn exception raised. The traceback is as follows:\nTraceback (most recent call last):\n  File \"/home/ml/users/ksinha4/mlp/comp424_final_project/submissions/comp424mcgill/final-project-a_team_name/world.py\", line 310, in step\n    raise ValueError(\nValueError: [INVALID:STEP] Not a valid step from [5 4] to [5 4] and put barrier at 0, with max steps = 4\n\nExecute Random Walk!\nAn exception raised. The traceback is as follows:\nTraceback (most recent call last):\n  File \"/home/ml/users/ksinha4/mlp/comp424_final_project/submissions/comp424mcgill/final-project-a_team_name/world.py\", line 310, in step\n    raise ValueError(\nValueError: [INVALID:STEP] Not a valid step from [6 3] to [6 3] and put barrier at 0, with max steps = 4\n\nExecute Random Walk!\n"}, {"student_agent_score": 1, "random_agent_score": 48, "student_agent_time": 0.0038254261016845703, "random_agent_time": 0.002084493637084961, "board_size": 7, "swap_players": false, "run_out": "An exception raised. The traceback is as follows:\nTraceback (most recent call last):\n  File \"/home/ml/users/ksinha4/mlp/comp424_final_project/submissions/comp424mcgill/final-project-a_team_name/world.py\", line 310, in step\n    raise ValueError(\nValueError: [INVALID:STEP] Not a valid step from [4 3] to [4 3] and put barrier at 0, with max steps = 4\n\nExecute Random Walk!\nAn exception raised. The traceback is as follows:\nTraceback (most recent call last):\n  File \"/home/ml/users/ksinha4/mlp/comp424_final_project/submissions/comp424mcgill/final-project-a_team_name/world.py\", line 310, in step\n    raise ValueError(\nValueError: [INVALID:STEP] Not a valid step from [4 2] to [4 2] and put barrier at 0, with max steps = 4\n\nExecute Random Walk!\nAn exception raised. The traceback is as follows:\nTraceback (most recent call last):\n  File \"/home/ml/users/ksinha4/mlp/comp424_final_project/submissions/comp424mcgill/final-project-a_team_name/world.py\", line 310, in step\n    raise ValueError(\nValueError: [INVALID:STEP] Not a valid step from [4 3] to [4 3] and put barrier at 0, with max steps = 4\n\nExecute Random Walk!\nAn exception raised. The traceback is as follows:\nTraceback (most recent call last):\n  File \"/home/ml/users/ksinha4/mlp/comp424_final_project/submissions/comp424mcgill/final-project-a_team_name/world.py\", line 310, in step\n    raise ValueError(\nValueError: [INVALID:STEP] Not a valid step from [5 4] to [5 4] and put barrier at 0, with max steps = 4\n\nExecute Random Walk!\nAn exception raised. The traceback is as follows:\nTraceback (most recent call last):\n  File \"/home/ml/users/ksinha4/mlp/comp424_final_project/submissions/comp424mcgill/final-project-a_team_name/world.py\", line 310, in step\n    raise ValueError(\nValueError: [INVALID:STEP] Not a valid step from [6 3] to [6 3] and put barrier at 0, with max steps = 4\n\nExecute Random Walk!\n"}, {"student_agent_score": 1, "random_agent_score": 48, "student_agent_time": 0.0031321048736572266, "random_agent_time": 0.0024459362030029297, "board_size": 7, "swap_players": true, "run_out": "An exception raised. The traceback is as follows:\nTraceback (most recent call last):\n  File \"/home/ml/users/ksinha4/mlp/comp424_final_project/submissions/comp424mcgill/final-project-a_team_name/world.py\", line 310, in step\n    raise ValueError(\nValueError: [INVALID:STEP] Not a valid step from [2 3] to [2 3] and put barrier at 0, with max steps = 4\n\nExecute Random Walk!\nAn exception raised. The traceback is as follows:\nTraceback (most recent call last):\n  File \"/home/ml/users/ksinha4/mlp/comp424_final_project/submissions/comp424mcgill/final-project-a_team_name/world.py\", line 310, in step\n    raise ValueError(\nValueError: [INVALID:STEP] Not a valid step from [5 4] to [5 4] and put barrier at 0, with max steps = 4\n\nExecute Random Walk!\nAn exception raised. The traceback is as follows:\nTraceback (most recent call last):\n  File \"/home/ml/users/ksinha4/mlp/comp424_final_project/submissions/comp424mcgill/final-project-a_team_name/world.py\", line 310, in step\n    raise ValueError(\nValueError: [INVALID:STEP] Not a valid step from [6 3] to [6 3] and put barrier at 0, with max steps = 4\n\nExecute Random Walk!\n"}, {"student_agent_score": 1, "random_agent_score": 48, "student_agent_time": 0.006417989730834961, "random_agent_time": 0.0025072097778320312, "board_size": 7, "swap_players": false, "run_out": "An exception raised. The traceback is as follows:\nTraceback (most recent call last):\n  File \"/home/ml/users/ksinha4/mlp/comp424_final_project/submissions/comp424mcgill/final-project-a_team_name/world.py\", line 310, in step\n    raise ValueError(\nValueError: [INVALID:STEP] Not a valid step from [4 3] to [4 3] and put barrier at 0, with max steps = 4\n\nExecute Random Walk!\nAn exception raised. The traceback is as follows:\nTraceback (most recent call last):\n  File \"/home/ml/users/ksinha4/mlp/comp424_final_project/submissions/comp424mcgill/final-project-a_team_name/world.py\", line 310, in step\n    raise ValueError(\nValueError: [INVALID:STEP] Not a valid step from [4 2] to [4 2] and put barrier at 0, with max steps = 4\n\nExecute Random Walk!\nAn exception raised. The traceback is as follows:\nTraceback (most recent call last):\n  File \"/home/ml/users/ksinha4/mlp/comp424_final_project/submissions/comp424mcgill/final-project-a_team_name/world.py\", line 310, in step\n    raise ValueError(\nValueError: [INVALID:STEP] Not a valid step from [4 3] to [4 3] and put barrier at 0, with max steps = 4\n\nExecute Random Walk!\nAn exception raised. The traceback is as follows:\nTraceback (most recent call last):\n  File \"/home/ml/users/ksinha4/mlp/comp424_final_project/submissions/comp424mcgill/final-project-a_team_name/world.py\", line 310, in step\n    raise ValueError(\nValueError: [INVALID:STEP] Not a valid step from [5 4] to [5 4] and put barrier at 0, with max steps = 4\n\nExecute Random Walk!\nAn exception raised. The traceback is as follows:\nTraceback (most recent call last):\n  File \"/home/ml/users/ksinha4/mlp/comp424_final_project/submissions/comp424mcgill/final-project-a_team_name/world.py\", line 310, in step\n    raise ValueError(\nValueError: [INVALID:STEP] Not a valid step from [6 3] to [6 3] and put barrier at 0, with max steps = 4\n\nExecute Random Walk!\n"}, {"student_agent_score": 1, "random_agent_score": 48, "student_agent_time": 0.002640962600708008, "random_agent_time": 0.0024733543395996094, "board_size": 7, "swap_players": true, "run_out": "An exception raised. The traceback is as follows:\nTraceback (most recent call last):\n  File \"/home/ml/users/ksinha4/mlp/comp424_final_project/submissions/comp424mcgill/final-project-a_team_name/world.py\", line 310, in step\n    raise ValueError(\nValueError: [INVALID:STEP] Not a valid step from [2 3] to [2 3] and put barrier at 0, with max steps = 4\n\nExecute Random Walk!\nAn exception raised. The traceback is as follows:\nTraceback (most recent call last):\n  File \"/home/ml/users/ksinha4/mlp/comp424_final_project/submissions/comp424mcgill/final-project-a_team_name/world.py\", line 310, in step\n    raise ValueError(\nValueError: [INVALID:STEP] Not a valid step from [5 4] to [5 4] and put barrier at 0, with max steps = 4\n\nExecute Random Walk!\nAn exception raised. The traceback is as follows:\nTraceback (most recent call last):\n  File \"/home/ml/users/ksinha4/mlp/comp424_final_project/submissions/comp424mcgill/final-project-a_team_name/world.py\", line 310, in step\n    raise ValueError(\nValueError: [INVALID:STEP] Not a valid step from [6 3] to [6 3] and put barrier at 0, with max steps = 4\n\nExecute Random Walk!\n"}, {"student_agent_score": 1, "random_agent_score": 35, "student_agent_time": 0.005130767822265625, "random_agent_time": 0.0017604827880859375, "board_size": 6, "swap_players": true, "run_out": "An exception raised. The traceback is as follows:\nTraceback (most recent call last):\n  File \"/home/ml/users/ksinha4/mlp/comp424_final_project/submissions/comp424mcgill/final-project-a_team_name/world.py\", line 310, in step\n    raise ValueError(\nValueError: [INVALID:STEP] Not a valid step from [3 3] to [3 3] and put barrier at 0, with max steps = 3\n\nExecute Random Walk!\nAn exception raised. The traceback is as follows:\nTraceback (most recent call last):\n  File \"/home/ml/users/ksinha4/mlp/comp424_final_project/submissions/comp424mcgill/final-project-a_team_name/world.py\", line 310, in step\n    raise ValueError(\nValueError: [INVALID:STEP] Not a valid step from [3 3] to [3 3] and put barrier at 0, with max steps = 3\n\nExecute Random Walk!\n"}, {"student_agent_score": 117, "random_agent_score": 1, "student_agent_time": 0.010190963745117188, "random_agent_time": 0.007277965545654297, "board_size": 11, "swap_players": false, "run_out": "An exception raised. The traceback is as follows:\nTraceback (most recent call last):\n  File \"/home/ml/users/ksinha4/mlp/comp424_final_project/submissions/comp424mcgill/final-project-a_team_name/world.py\", line 310, in step\n    raise ValueError(\nValueError: [INVALID:STEP] Not a valid step from [1 7] to [1 7] and put barrier at 0, with max steps = 6\n\nExecute Random Walk!\nAn exception raised. The traceback is as follows:\nTraceback (most recent call last):\n  File \"/home/ml/users/ksinha4/mlp/comp424_final_project/submissions/comp424mcgill/final-project-a_team_name/world.py\", line 310, in step\n    raise ValueError(\nValueError: [INVALID:STEP] Not a valid step from [1 8] to [1 8] and put barrier at 0, with max steps = 6\n\nExecute Random Walk!\nAn exception raised. The traceback is as follows:\nTraceback (most recent call last):\n  File \"/home/ml/users/ksinha4/mlp/comp424_final_project/submissions/comp424mcgill/final-project-a_team_name/world.py\", line 310, in step\n    raise ValueError(\nValueError: [INVALID:STEP] Not a valid step from [1 6] to [1 6] and put barrier at 0, with max steps = 6\n\nExecute Random Walk!\nAn exception raised. The traceback is as follows:\nTraceback (most recent call last):\n  File \"/home/ml/users/ksinha4/mlp/comp424_final_project/submissions/comp424mcgill/final-project-a_team_name/world.py\", line 310, in step\n    raise ValueError(\nValueError: [INVALID:STEP] Not a valid step from [3 3] to [3 3] and put barrier at 0, with max steps = 6\n\nExecute Random Walk!\nAn exception raised. The traceback is as follows:\nTraceback (most recent call last):\n  File \"/home/ml/users/ksinha4/mlp/comp424_final_project/submissions/comp424mcgill/final-project-a_team_name/world.py\", line 310, in step\n    raise ValueError(\nValueError: [INVALID:STEP] Not a valid step from [3 4] to [3 4] and put barrier at 0, with max steps = 6\n\nExecute Random Walk!\nAn exception raised. The traceback is as follows:\nTraceback (most recent call last):\n  File \"/home/ml/users/ksinha4/mlp/comp424_final_project/submissions/comp424mcgill/final-project-a_team_name/world.py\", line 310, in step\n    raise ValueError(\nValueError: [INVALID:STEP] Not a valid step from [3 4] to [3 4] and put barrier at 0, with max steps = 6\n\nExecute Random Walk!\nAn exception raised. The traceback is as follows:\nTraceback (most recent call last):\n  File \"/home/ml/users/ksinha4/mlp/comp424_final_project/submissions/comp424mcgill/final-project-a_team_name/world.py\", line 310, in step\n    raise ValueError(\nValueError: [INVALID:STEP] Not a valid step from [4 4] to [4 4] and put barrier at 0, with max steps = 6\n\nExecute Random Walk!\nAn exception raised. The traceback is as follows:\nTraceback (most recent call last):\n  File \"/home/ml/users/ksinha4/mlp/comp424_final_project/submissions/comp424mcgill/final-project-a_team_name/world.py\", line 310, in step\n    raise ValueError(\nValueError: [INVALID:STEP] Not a valid step from [4 4] to [4 4] and put barrier at 0, with max steps = 6\n\nExecute Random Walk!\n"}, {"student_agent_score": 1, "random_agent_score": 48, "student_agent_time": 0.0034301280975341797, "random_agent_time": 0.001980304718017578, "board_size": 7, "swap_players": false, "run_out": "An exception raised. The traceback is as follows:\nTraceback (most recent call last):\n  File \"/home/ml/users/ksinha4/mlp/comp424_final_project/submissions/comp424mcgill/final-project-a_team_name/world.py\", line 310, in step\n    raise ValueError(\nValueError: [INVALID:STEP] Not a valid step from [4 3] to [4 3] and put barrier at 0, with max steps = 4\n\nExecute Random Walk!\nAn exception raised. The traceback is as follows:\nTraceback (most recent call last):\n  File \"/home/ml/users/ksinha4/mlp/comp424_final_project/submissions/comp424mcgill/final-project-a_team_name/world.py\", line 310, in step\n    raise ValueError(\nValueError: [INVALID:STEP] Not a valid step from [4 2] to [4 2] and put barrier at 0, with max steps = 4\n\nExecute Random Walk!\nAn exception raised. The traceback is as follows:\nTraceback (most recent call last):\n  File \"/home/ml/users/ksinha4/mlp/comp424_final_project/submissions/comp424mcgill/final-project-a_team_name/world.py\", line 310, in step\n    raise ValueError(\nValueError: [INVALID:STEP] Not a valid step from [4 3] to [4 3] and put barrier at 0, with max steps = 4\n\nExecute Random Walk!\nAn exception raised. The traceback is as follows:\nTraceback (most recent call last):\n  File \"/home/ml/users/ksinha4/mlp/comp424_final_project/submissions/comp424mcgill/final-project-a_team_name/world.py\", line 310, in step\n    raise ValueError(\nValueError: [INVALID:STEP] Not a valid step from [5 4] to [5 4] and put barrier at 0, with max steps = 4\n\nExecute Random Walk!\nAn exception raised. The traceback is as follows:\nTraceback (most recent call last):\n  File \"/home/ml/users/ksinha4/mlp/comp424_final_project/submissions/comp424mcgill/final-project-a_team_name/world.py\", line 310, in step\n    raise ValueError(\nValueError: [INVALID:STEP] Not a valid step from [6 3] to [6 3] and put barrier at 0, with max steps = 4\n\nExecute Random Walk!\n"}, {"student_agent_score": 2, "random_agent_score": 79, "student_agent_time": 0.002980470657348633, "random_agent_time": 0.0022590160369873047, "board_size": 9, "swap_players": false, "run_out": "An exception raised. The traceback is as follows:\nTraceback (most recent call last):\n  File \"/home/ml/users/ksinha4/mlp/comp424_final_project/submissions/comp424mcgill/final-project-a_team_name/world.py\", line 310, in step\n    raise ValueError(\nValueError: [INVALID:STEP] Not a valid step from [5 4] to [5 4] and put barrier at 0, with max steps = 5\n\nExecute Random Walk!\nAn exception raised. The traceback is as follows:\nTraceback (most recent call last):\n  File \"/home/ml/users/ksinha4/mlp/comp424_final_project/submissions/comp424mcgill/final-project-a_team_name/world.py\", line 310, in step\n    raise ValueError(\nValueError: [INVALID:STEP] Not a valid step from [5 3] to [5 3] and put barrier at 0, with max steps = 5\n\nExecute Random Walk!\n"}, {"student_agent_score": 1, "random_agent_score": 48, "student_agent_time": 0.003946781158447266, "random_agent_time": 0.003432035446166992, "board_size": 7, "swap_players": true, "run_out": "An exception raised. The traceback is as follows:\nTraceback (most recent call last):\n  File \"/home/ml/users/ksinha4/mlp/comp424_final_project/submissions/comp424mcgill/final-project-a_team_name/world.py\", line 310, in step\n    raise ValueError(\nValueError: [INVALID:STEP] Not a valid step from [2 3] to [2 3] and put barrier at 0, with max steps = 4\n\nExecute Random Walk!\nAn exception raised. The traceback is as follows:\nTraceback (most recent call last):\n  File \"/home/ml/users/ksinha4/mlp/comp424_final_project/submissions/comp424mcgill/final-project-a_team_name/world.py\", line 310, in step\n    raise ValueError(\nValueError: [INVALID:STEP] Not a valid step from [5 4] to [5 4] and put barrier at 0, with max steps = 4\n\nExecute Random Walk!\nAn exception raised. The traceback is as follows:\nTraceback (most recent call last):\n  File \"/home/ml/users/ksinha4/mlp/comp424_final_project/submissions/comp424mcgill/final-project-a_team_name/world.py\", line 310, in step\n    raise ValueError(\nValueError: [INVALID:STEP] Not a valid step from [6 3] to [6 3] and put barrier at 0, with max steps = 4\n\nExecute Random Walk!\n"}, {"student_agent_score": 1, "random_agent_score": 48, "student_agent_time": 0.004328012466430664, "random_agent_time": 0.003918886184692383, "board_size": 7, "swap_players": false, "run_out": "An exception raised. The traceback is as follows:\nTraceback (most recent call last):\n  File \"/home/ml/users/ksinha4/mlp/comp424_final_project/submissions/comp424mcgill/final-project-a_team_name/world.py\", line 310, in step\n    raise ValueError(\nValueError: [INVALID:STEP] Not a valid step from [4 3] to [4 3] and put barrier at 0, with max steps = 4\n\nExecute Random Walk!\nAn exception raised. The traceback is as follows:\nTraceback (most recent call last):\n  File \"/home/ml/users/ksinha4/mlp/comp424_final_project/submissions/comp424mcgill/final-project-a_team_name/world.py\", line 310, in step\n    raise ValueError(\nValueError: [INVALID:STEP] Not a valid step from [4 2] to [4 2] and put barrier at 0, with max steps = 4\n\nExecute Random Walk!\nAn exception raised. The traceback is as follows:\nTraceback (most recent call last):\n  File \"/home/ml/users/ksinha4/mlp/comp424_final_project/submissions/comp424mcgill/final-project-a_team_name/world.py\", line 310, in step\n    raise ValueError(\nValueError: [INVALID:STEP] Not a valid step from [4 3] to [4 3] and put barrier at 0, with max steps = 4\n\nExecute Random Walk!\nAn exception raised. The traceback is as follows:\nTraceback (most recent call last):\n  File \"/home/ml/users/ksinha4/mlp/comp424_final_project/submissions/comp424mcgill/final-project-a_team_name/world.py\", line 310, in step\n    raise ValueError(\nValueError: [INVALID:STEP] Not a valid step from [5 4] to [5 4] and put barrier at 0, with max steps = 4\n\nExecute Random Walk!\nAn exception raised. The traceback is as follows:\nTraceback (most recent call last):\n  File \"/home/ml/users/ksinha4/mlp/comp424_final_project/submissions/comp424mcgill/final-project-a_team_name/world.py\", line 310, in step\n    raise ValueError(\nValueError: [INVALID:STEP] Not a valid step from [6 3] to [6 3] and put barrier at 0, with max steps = 4\n\nExecute Random Walk!\n"}, {"student_agent_score": 1, "random_agent_score": 35, "student_agent_time": 0.0018074512481689453, "random_agent_time": 0.0007939338684082031, "board_size": 6, "swap_players": false, "run_out": "An exception raised. The traceback is as follows:\nTraceback (most recent call last):\n  File \"/home/ml/users/ksinha4/mlp/comp424_final_project/submissions/comp424mcgill/final-project-a_team_name/world.py\", line 310, in step\n    raise ValueError(\nValueError: [INVALID:STEP] Not a valid step from [2 2] to [2 2] and put barrier at 0, with max steps = 3\n\nExecute Random Walk!\nAn exception raised. The traceback is as follows:\nTraceback (most recent call last):\n  File \"/home/ml/users/ksinha4/mlp/comp424_final_project/submissions/comp424mcgill/final-project-a_team_name/world.py\", line 310, in step\n    raise ValueError(\nValueError: [INVALID:STEP] Not a valid step from [3 0] to [3 0] and put barrier at 0, with max steps = 3\n\nExecute Random Walk!\n"}, {"student_agent_score": 1, "random_agent_score": 48, "student_agent_time": 0.0070803165435791016, "random_agent_time": 0.003122568130493164, "board_size": 7, "swap_players": true, "run_out": "An exception raised. The traceback is as follows:\nTraceback (most recent call last):\n  File \"/home/ml/users/ksinha4/mlp/comp424_final_project/submissions/comp424mcgill/final-project-a_team_name/world.py\", line 310, in step\n    raise ValueError(\nValueError: [INVALID:STEP] Not a valid step from [2 3] to [2 3] and put barrier at 0, with max steps = 4\n\nExecute Random Walk!\nAn exception raised. The traceback is as follows:\nTraceback (most recent call last):\n  File \"/home/ml/users/ksinha4/mlp/comp424_final_project/submissions/comp424mcgill/final-project-a_team_name/world.py\", line 310, in step\n    raise ValueError(\nValueError: [INVALID:STEP] Not a valid step from [5 4] to [5 4] and put barrier at 0, with max steps = 4\n\nExecute Random Walk!\nAn exception raised. The traceback is as follows:\nTraceback (most recent call last):\n  File \"/home/ml/users/ksinha4/mlp/comp424_final_project/submissions/comp424mcgill/final-project-a_team_name/world.py\", line 310, in step\n    raise ValueError(\nValueError: [INVALID:STEP] Not a valid step from [6 3] to [6 3] and put barrier at 0, with max steps = 4\n\nExecute Random Walk!\n"}, {"student_agent_score": 1, "random_agent_score": 48, "student_agent_time": 0.004418849945068359, "random_agent_time": 0.0021469593048095703, "board_size": 7, "swap_players": false, "run_out": "An exception raised. The traceback is as follows:\nTraceback (most recent call last):\n  File \"/home/ml/users/ksinha4/mlp/comp424_final_project/submissions/comp424mcgill/final-project-a_team_name/world.py\", line 310, in step\n    raise ValueError(\nValueError: [INVALID:STEP] Not a valid step from [4 3] to [4 3] and put barrier at 0, with max steps = 4\n\nExecute Random Walk!\nAn exception raised. The traceback is as follows:\nTraceback (most recent call last):\n  File \"/home/ml/users/ksinha4/mlp/comp424_final_project/submissions/comp424mcgill/final-project-a_team_name/world.py\", line 310, in step\n    raise ValueError(\nValueError: [INVALID:STEP] Not a valid step from [4 2] to [4 2] and put barrier at 0, with max steps = 4\n\nExecute Random Walk!\nAn exception raised. The traceback is as follows:\nTraceback (most recent call last):\n  File \"/home/ml/users/ksinha4/mlp/comp424_final_project/submissions/comp424mcgill/final-project-a_team_name/world.py\", line 310, in step\n    raise ValueError(\nValueError: [INVALID:STEP] Not a valid step from [4 3] to [4 3] and put barrier at 0, with max steps = 4\n\nExecute Random Walk!\nAn exception raised. The traceback is as follows:\nTraceback (most recent call last):\n  File \"/home/ml/users/ksinha4/mlp/comp424_final_project/submissions/comp424mcgill/final-project-a_team_name/world.py\", line 310, in step\n    raise ValueError(\nValueError: [INVALID:STEP] Not a valid step from [5 4] to [5 4] and put barrier at 0, with max steps = 4\n\nExecute Random Walk!\nAn exception raised. The traceback is as follows:\nTraceback (most recent call last):\n  File \"/home/ml/users/ksinha4/mlp/comp424_final_project/submissions/comp424mcgill/final-project-a_team_name/world.py\", line 310, in step\n    raise ValueError(\nValueError: [INVALID:STEP] Not a valid step from [6 3] to [6 3] and put barrier at 0, with max steps = 4\n\nExecute Random Walk!\n"}, {"student_agent_score": 120, "random_agent_score": 1, "student_agent_time": 0.0016982555389404297, "random_agent_time": 0.0019905567169189453, "board_size": 11, "swap_players": true, "run_out": "An exception raised. The traceback is as follows:\nTraceback (most recent call last):\n  File \"/home/ml/users/ksinha4/mlp/comp424_final_project/submissions/comp424mcgill/final-project-a_team_name/world.py\", line 310, in step\n    raise ValueError(\nValueError: [INVALID:STEP] Not a valid step from [9 3] to [9 3] and put barrier at 0, with max steps = 6\n\nExecute Random Walk!\nAn exception raised. The traceback is as follows:\nTraceback (most recent call last):\n  File \"/home/ml/users/ksinha4/mlp/comp424_final_project/submissions/comp424mcgill/final-project-a_team_name/world.py\", line 310, in step\n    raise ValueError(\nValueError: [INVALID:STEP] Not a valid step from [9 3] to [9 3] and put barrier at 0, with max steps = 6\n\nExecute Random Walk!\n"}, {"student_agent_score": 1, "random_agent_score": 48, "student_agent_time": 0.0029561519622802734, "random_agent_time": 0.003147125244140625, "board_size": 7, "swap_players": true, "run_out": "An exception raised. The traceback is as follows:\nTraceback (most recent call last):\n  File \"/home/ml/users/ksinha4/mlp/comp424_final_project/submissions/comp424mcgill/final-project-a_team_name/world.py\", line 310, in step\n    raise ValueError(\nValueError: [INVALID:STEP] Not a valid step from [2 3] to [2 3] and put barrier at 0, with max steps = 4\n\nExecute Random Walk!\nAn exception raised. The traceback is as follows:\nTraceback (most recent call last):\n  File \"/home/ml/users/ksinha4/mlp/comp424_final_project/submissions/comp424mcgill/final-project-a_team_name/world.py\", line 310, in step\n    raise ValueError(\nValueError: [INVALID:STEP] Not a valid step from [5 4] to [5 4] and put barrier at 0, with max steps = 4\n\nExecute Random Walk!\nAn exception raised. The traceback is as follows:\nTraceback (most recent call last):\n  File \"/home/ml/users/ksinha4/mlp/comp424_final_project/submissions/comp424mcgill/final-project-a_team_name/world.py\", line 310, in step\n    raise ValueError(\nValueError: [INVALID:STEP] Not a valid step from [6 3] to [6 3] and put barrier at 0, with max steps = 4\n\nExecute Random Walk!\n"}, {"student_agent_score": 1, "random_agent_score": 48, "student_agent_time": 0.003681659698486328, "random_agent_time": 0.0022428035736083984, "board_size": 7, "swap_players": true, "run_out": "An exception raised. The traceback is as follows:\nTraceback (most recent call last):\n  File \"/home/ml/users/ksinha4/mlp/comp424_final_project/submissions/comp424mcgill/final-project-a_team_name/world.py\", line 310, in step\n    raise ValueError(\nValueError: [INVALID:STEP] Not a valid step from [2 3] to [2 3] and put barrier at 0, with max steps = 4\n\nExecute Random Walk!\nAn exception raised. The traceback is as follows:\nTraceback (most recent call last):\n  File \"/home/ml/users/ksinha4/mlp/comp424_final_project/submissions/comp424mcgill/final-project-a_team_name/world.py\", line 310, in step\n    raise ValueError(\nValueError: [INVALID:STEP] Not a valid step from [5 4] to [5 4] and put barrier at 0, with max steps = 4\n\nExecute Random Walk!\nAn exception raised. The traceback is as follows:\nTraceback (most recent call last):\n  File \"/home/ml/users/ksinha4/mlp/comp424_final_project/submissions/comp424mcgill/final-project-a_team_name/world.py\", line 310, in step\n    raise ValueError(\nValueError: [INVALID:STEP] Not a valid step from [6 3] to [6 3] and put barrier at 0, with max steps = 4\n\nExecute Random Walk!\n"}, {"student_agent_score": 1, "random_agent_score": 48, "student_agent_time": 0.003963470458984375, "random_agent_time": 0.00173187255859375, "board_size": 7, "swap_players": false, "run_out": "An exception raised. The traceback is as follows:\nTraceback (most recent call last):\n  File \"/home/ml/users/ksinha4/mlp/comp424_final_project/submissions/comp424mcgill/final-project-a_team_name/world.py\", line 310, in step\n    raise ValueError(\nValueError: [INVALID:STEP] Not a valid step from [4 3] to [4 3] and put barrier at 0, with max steps = 4\n\nExecute Random Walk!\nAn exception raised. The traceback is as follows:\nTraceback (most recent call last):\n  File \"/home/ml/users/ksinha4/mlp/comp424_final_project/submissions/comp424mcgill/final-project-a_team_name/world.py\", line 310, in step\n    raise ValueError(\nValueError: [INVALID:STEP] Not a valid step from [4 2] to [4 2] and put barrier at 0, with max steps = 4\n\nExecute Random Walk!\nAn exception raised. The traceback is as follows:\nTraceback (most recent call last):\n  File \"/home/ml/users/ksinha4/mlp/comp424_final_project/submissions/comp424mcgill/final-project-a_team_name/world.py\", line 310, in step\n    raise ValueError(\nValueError: [INVALID:STEP] Not a valid step from [4 3] to [4 3] and put barrier at 0, with max steps = 4\n\nExecute Random Walk!\nAn exception raised. The traceback is as follows:\nTraceback (most recent call last):\n  File \"/home/ml/users/ksinha4/mlp/comp424_final_project/submissions/comp424mcgill/final-project-a_team_name/world.py\", line 310, in step\n    raise ValueError(\nValueError: [INVALID:STEP] Not a valid step from [5 4] to [5 4] and put barrier at 0, with max steps = 4\n\nExecute Random Walk!\nAn exception raised. The traceback is as follows:\nTraceback (most recent call last):\n  File \"/home/ml/users/ksinha4/mlp/comp424_final_project/submissions/comp424mcgill/final-project-a_team_name/world.py\", line 310, in step\n    raise ValueError(\nValueError: [INVALID:STEP] Not a valid step from [6 3] to [6 3] and put barrier at 0, with max steps = 4\n\nExecute Random Walk!\n"}, {"student_agent_score": 63, "random_agent_score": 1, "student_agent_time": 0.003339052200317383, "random_agent_time": 0.0025167465209960938, "board_size": 8, "swap_players": true, "run_out": "An exception raised. The traceback is as follows:\nTraceback (most recent call last):\n  File \"/home/ml/users/ksinha4/mlp/comp424_final_project/submissions/comp424mcgill/final-project-a_team_name/world.py\", line 310, in step\n    raise ValueError(\nValueError: [INVALID:STEP] Not a valid step from [5 5] to [5 5] and put barrier at 0, with max steps = 4\n\nExecute Random Walk!\nAn exception raised. The traceback is as follows:\nTraceback (most recent call last):\n  File \"/home/ml/users/ksinha4/mlp/comp424_final_project/submissions/comp424mcgill/final-project-a_team_name/world.py\", line 310, in step\n    raise ValueError(\nValueError: [INVALID:STEP] Not a valid step from [5 4] to [5 4] and put barrier at 0, with max steps = 4\n\nExecute Random Walk!\nAn exception raised. The traceback is as follows:\nTraceback (most recent call last):\n  File \"/home/ml/users/ksinha4/mlp/comp424_final_project/submissions/comp424mcgill/final-project-a_team_name/world.py\", line 310, in step\n    raise ValueError(\nValueError: [INVALID:STEP] Not a valid step from [5 4] to [5 4] and put barrier at 0, with max steps = 4\n\nExecute Random Walk!\n"}, {"student_agent_score": 1, "random_agent_score": 48, "student_agent_time": 0.0023331642150878906, "random_agent_time": 0.0025818347930908203, "board_size": 7, "swap_players": true, "run_out": "An exception raised. The traceback is as follows:\nTraceback (most recent call last):\n  File \"/home/ml/users/ksinha4/mlp/comp424_final_project/submissions/comp424mcgill/final-project-a_team_name/world.py\", line 310, in step\n    raise ValueError(\nValueError: [INVALID:STEP] Not a valid step from [2 3] to [2 3] and put barrier at 0, with max steps = 4\n\nExecute Random Walk!\nAn exception raised. The traceback is as follows:\nTraceback (most recent call last):\n  File \"/home/ml/users/ksinha4/mlp/comp424_final_project/submissions/comp424mcgill/final-project-a_team_name/world.py\", line 310, in step\n    raise ValueError(\nValueError: [INVALID:STEP] Not a valid step from [5 4] to [5 4] and put barrier at 0, with max steps = 4\n\nExecute Random Walk!\nAn exception raised. The traceback is as follows:\nTraceback (most recent call last):\n  File \"/home/ml/users/ksinha4/mlp/comp424_final_project/submissions/comp424mcgill/final-project-a_team_name/world.py\", line 310, in step\n    raise ValueError(\nValueError: [INVALID:STEP] Not a valid step from [6 3] to [6 3] and put barrier at 0, with max steps = 4\n\nExecute Random Walk!\n"}, {"student_agent_score": 1, "random_agent_score": 48, "student_agent_time": 0.0036551952362060547, "random_agent_time": 0.0023956298828125, "board_size": 7, "swap_players": false, "run_out": "An exception raised. The traceback is as follows:\nTraceback (most recent call last):\n  File \"/home/ml/users/ksinha4/mlp/comp424_final_project/submissions/comp424mcgill/final-project-a_team_name/world.py\", line 310, in step\n    raise ValueError(\nValueError: [INVALID:STEP] Not a valid step from [4 3] to [4 3] and put barrier at 0, with max steps = 4\n\nExecute Random Walk!\nAn exception raised. The traceback is as follows:\nTraceback (most recent call last):\n  File \"/home/ml/users/ksinha4/mlp/comp424_final_project/submissions/comp424mcgill/final-project-a_team_name/world.py\", line 310, in step\n    raise ValueError(\nValueError: [INVALID:STEP] Not a valid step from [4 2] to [4 2] and put barrier at 0, with max steps = 4\n\nExecute Random Walk!\nAn exception raised. The traceback is as follows:\nTraceback (most recent call last):\n  File \"/home/ml/users/ksinha4/mlp/comp424_final_project/submissions/comp424mcgill/final-project-a_team_name/world.py\", line 310, in step\n    raise ValueError(\nValueError: [INVALID:STEP] Not a valid step from [4 3] to [4 3] and put barrier at 0, with max steps = 4\n\nExecute Random Walk!\nAn exception raised. The traceback is as follows:\nTraceback (most recent call last):\n  File \"/home/ml/users/ksinha4/mlp/comp424_final_project/submissions/comp424mcgill/final-project-a_team_name/world.py\", line 310, in step\n    raise ValueError(\nValueError: [INVALID:STEP] Not a valid step from [5 4] to [5 4] and put barrier at 0, with max steps = 4\n\nExecute Random Walk!\nAn exception raised. The traceback is as follows:\nTraceback (most recent call last):\n  File \"/home/ml/users/ksinha4/mlp/comp424_final_project/submissions/comp424mcgill/final-project-a_team_name/world.py\", line 310, in step\n    raise ValueError(\nValueError: [INVALID:STEP] Not a valid step from [6 3] to [6 3] and put barrier at 0, with max steps = 4\n\nExecute Random Walk!\n"}, {"student_agent_score": 1, "random_agent_score": 48, "student_agent_time": 0.003330230712890625, "random_agent_time": 0.002802133560180664, "board_size": 7, "swap_players": true, "run_out": "An exception raised. The traceback is as follows:\nTraceback (most recent call last):\n  File \"/home/ml/users/ksinha4/mlp/comp424_final_project/submissions/comp424mcgill/final-project-a_team_name/world.py\", line 310, in step\n    raise ValueError(\nValueError: [INVALID:STEP] Not a valid step from [2 3] to [2 3] and put barrier at 0, with max steps = 4\n\nExecute Random Walk!\nAn exception raised. The traceback is as follows:\nTraceback (most recent call last):\n  File \"/home/ml/users/ksinha4/mlp/comp424_final_project/submissions/comp424mcgill/final-project-a_team_name/world.py\", line 310, in step\n    raise ValueError(\nValueError: [INVALID:STEP] Not a valid step from [5 4] to [5 4] and put barrier at 0, with max steps = 4\n\nExecute Random Walk!\nAn exception raised. The traceback is as follows:\nTraceback (most recent call last):\n  File \"/home/ml/users/ksinha4/mlp/comp424_final_project/submissions/comp424mcgill/final-project-a_team_name/world.py\", line 310, in step\n    raise ValueError(\nValueError: [INVALID:STEP] Not a valid step from [6 3] to [6 3] and put barrier at 0, with max steps = 4\n\nExecute Random Walk!\n"}, {"student_agent_score": 1, "random_agent_score": 48, "student_agent_time": 0.0025327205657958984, "random_agent_time": 0.002565145492553711, "board_size": 7, "swap_players": true, "run_out": "An exception raised. The traceback is as follows:\nTraceback (most recent call last):\n  File \"/home/ml/users/ksinha4/mlp/comp424_final_project/submissions/comp424mcgill/final-project-a_team_name/world.py\", line 310, in step\n    raise ValueError(\nValueError: [INVALID:STEP] Not a valid step from [2 3] to [2 3] and put barrier at 0, with max steps = 4\n\nExecute Random Walk!\nAn exception raised. The traceback is as follows:\nTraceback (most recent call last):\n  File \"/home/ml/users/ksinha4/mlp/comp424_final_project/submissions/comp424mcgill/final-project-a_team_name/world.py\", line 310, in step\n    raise ValueError(\nValueError: [INVALID:STEP] Not a valid step from [5 4] to [5 4] and put barrier at 0, with max steps = 4\n\nExecute Random Walk!\nAn exception raised. The traceback is as follows:\nTraceback (most recent call last):\n  File \"/home/ml/users/ksinha4/mlp/comp424_final_project/submissions/comp424mcgill/final-project-a_team_name/world.py\", line 310, in step\n    raise ValueError(\nValueError: [INVALID:STEP] Not a valid step from [6 3] to [6 3] and put barrier at 0, with max steps = 4\n\nExecute Random Walk!\n"}, {"student_agent_score": 1, "random_agent_score": 48, "student_agent_time": 0.004126310348510742, "random_agent_time": 0.002042531967163086, "board_size": 7, "swap_players": false, "run_out": "An exception raised. The traceback is as follows:\nTraceback (most recent call last):\n  File \"/home/ml/users/ksinha4/mlp/comp424_final_project/submissions/comp424mcgill/final-project-a_team_name/world.py\", line 310, in step\n    raise ValueError(\nValueError: [INVALID:STEP] Not a valid step from [4 3] to [4 3] and put barrier at 0, with max steps = 4\n\nExecute Random Walk!\nAn exception raised. The traceback is as follows:\nTraceback (most recent call last):\n  File \"/home/ml/users/ksinha4/mlp/comp424_final_project/submissions/comp424mcgill/final-project-a_team_name/world.py\", line 310, in step\n    raise ValueError(\nValueError: [INVALID:STEP] Not a valid step from [4 2] to [4 2] and put barrier at 0, with max steps = 4\n\nExecute Random Walk!\nAn exception raised. The traceback is as follows:\nTraceback (most recent call last):\n  File \"/home/ml/users/ksinha4/mlp/comp424_final_project/submissions/comp424mcgill/final-project-a_team_name/world.py\", line 310, in step\n    raise ValueError(\nValueError: [INVALID:STEP] Not a valid step from [4 3] to [4 3] and put barrier at 0, with max steps = 4\n\nExecute Random Walk!\nAn exception raised. The traceback is as follows:\nTraceback (most recent call last):\n  File \"/home/ml/users/ksinha4/mlp/comp424_final_project/submissions/comp424mcgill/final-project-a_team_name/world.py\", line 310, in step\n    raise ValueError(\nValueError: [INVALID:STEP] Not a valid step from [5 4] to [5 4] and put barrier at 0, with max steps = 4\n\nExecute Random Walk!\nAn exception raised. The traceback is as follows:\nTraceback (most recent call last):\n  File \"/home/ml/users/ksinha4/mlp/comp424_final_project/submissions/comp424mcgill/final-project-a_team_name/world.py\", line 310, in step\n    raise ValueError(\nValueError: [INVALID:STEP] Not a valid step from [6 3] to [6 3] and put barrier at 0, with max steps = 4\n\nExecute Random Walk!\n"}, {"student_agent_score": 2, "random_agent_score": 79, "student_agent_time": 0.003143310546875, "random_agent_time": 0.0025217533111572266, "board_size": 9, "swap_players": false, "run_out": "An exception raised. The traceback is as follows:\nTraceback (most recent call last):\n  File \"/home/ml/users/ksinha4/mlp/comp424_final_project/submissions/comp424mcgill/final-project-a_team_name/world.py\", line 310, in step\n    raise ValueError(\nValueError: [INVALID:STEP] Not a valid step from [5 4] to [5 4] and put barrier at 0, with max steps = 5\n\nExecute Random Walk!\nAn exception raised. The traceback is as follows:\nTraceback (most recent call last):\n  File \"/home/ml/users/ksinha4/mlp/comp424_final_project/submissions/comp424mcgill/final-project-a_team_name/world.py\", line 310, in step\n    raise ValueError(\nValueError: [INVALID:STEP] Not a valid step from [5 3] to [5 3] and put barrier at 0, with max steps = 5\n\nExecute Random Walk!\n"}, {"student_agent_score": 1, "random_agent_score": 48, "student_agent_time": 0.0035686492919921875, "random_agent_time": 0.0020864009857177734, "board_size": 7, "swap_players": false, "run_out": "An exception raised. The traceback is as follows:\nTraceback (most recent call last):\n  File \"/home/ml/users/ksinha4/mlp/comp424_final_project/submissions/comp424mcgill/final-project-a_team_name/world.py\", line 310, in step\n    raise ValueError(\nValueError: [INVALID:STEP] Not a valid step from [4 3] to [4 3] and put barrier at 0, with max steps = 4\n\nExecute Random Walk!\nAn exception raised. The traceback is as follows:\nTraceback (most recent call last):\n  File \"/home/ml/users/ksinha4/mlp/comp424_final_project/submissions/comp424mcgill/final-project-a_team_name/world.py\", line 310, in step\n    raise ValueError(\nValueError: [INVALID:STEP] Not a valid step from [4 2] to [4 2] and put barrier at 0, with max steps = 4\n\nExecute Random Walk!\nAn exception raised. The traceback is as follows:\nTraceback (most recent call last):\n  File \"/home/ml/users/ksinha4/mlp/comp424_final_project/submissions/comp424mcgill/final-project-a_team_name/world.py\", line 310, in step\n    raise ValueError(\nValueError: [INVALID:STEP] Not a valid step from [4 3] to [4 3] and put barrier at 0, with max steps = 4\n\nExecute Random Walk!\nAn exception raised. The traceback is as follows:\nTraceback (most recent call last):\n  File \"/home/ml/users/ksinha4/mlp/comp424_final_project/submissions/comp424mcgill/final-project-a_team_name/world.py\", line 310, in step\n    raise ValueError(\nValueError: [INVALID:STEP] Not a valid step from [5 4] to [5 4] and put barrier at 0, with max steps = 4\n\nExecute Random Walk!\nAn exception raised. The traceback is as follows:\nTraceback (most recent call last):\n  File \"/home/ml/users/ksinha4/mlp/comp424_final_project/submissions/comp424mcgill/final-project-a_team_name/world.py\", line 310, in step\n    raise ValueError(\nValueError: [INVALID:STEP] Not a valid step from [6 3] to [6 3] and put barrier at 0, with max steps = 4\n\nExecute Random Walk!\n"}, {"student_agent_score": 1, "random_agent_score": 48, "student_agent_time": 0.0032160282135009766, "random_agent_time": 0.006569623947143555, "board_size": 7, "swap_players": true, "run_out": "An exception raised. The traceback is as follows:\nTraceback (most recent call last):\n  File \"/home/ml/users/ksinha4/mlp/comp424_final_project/submissions/comp424mcgill/final-project-a_team_name/world.py\", line 310, in step\n    raise ValueError(\nValueError: [INVALID:STEP] Not a valid step from [2 3] to [2 3] and put barrier at 0, with max steps = 4\n\nExecute Random Walk!\nAn exception raised. The traceback is as follows:\nTraceback (most recent call last):\n  File \"/home/ml/users/ksinha4/mlp/comp424_final_project/submissions/comp424mcgill/final-project-a_team_name/world.py\", line 310, in step\n    raise ValueError(\nValueError: [INVALID:STEP] Not a valid step from [5 4] to [5 4] and put barrier at 0, with max steps = 4\n\nExecute Random Walk!\nAn exception raised. The traceback is as follows:\nTraceback (most recent call last):\n  File \"/home/ml/users/ksinha4/mlp/comp424_final_project/submissions/comp424mcgill/final-project-a_team_name/world.py\", line 310, in step\n    raise ValueError(\nValueError: [INVALID:STEP] Not a valid step from [6 3] to [6 3] and put barrier at 0, with max steps = 4\n\nExecute Random Walk!\n"}, {"student_agent_score": 1, "random_agent_score": 48, "student_agent_time": 0.003104686737060547, "random_agent_time": 0.002423524856567383, "board_size": 7, "swap_players": true, "run_out": "An exception raised. The traceback is as follows:\nTraceback (most recent call last):\n  File \"/home/ml/users/ksinha4/mlp/comp424_final_project/submissions/comp424mcgill/final-project-a_team_name/world.py\", line 310, in step\n    raise ValueError(\nValueError: [INVALID:STEP] Not a valid step from [2 3] to [2 3] and put barrier at 0, with max steps = 4\n\nExecute Random Walk!\nAn exception raised. The traceback is as follows:\nTraceback (most recent call last):\n  File \"/home/ml/users/ksinha4/mlp/comp424_final_project/submissions/comp424mcgill/final-project-a_team_name/world.py\", line 310, in step\n    raise ValueError(\nValueError: [INVALID:STEP] Not a valid step from [5 4] to [5 4] and put barrier at 0, with max steps = 4\n\nExecute Random Walk!\nAn exception raised. The traceback is as follows:\nTraceback (most recent call last):\n  File \"/home/ml/users/ksinha4/mlp/comp424_final_project/submissions/comp424mcgill/final-project-a_team_name/world.py\", line 310, in step\n    raise ValueError(\nValueError: [INVALID:STEP] Not a valid step from [6 3] to [6 3] and put barrier at 0, with max steps = 4\n\nExecute Random Walk!\n"}, {"student_agent_score": 2, "random_agent_score": 98, "student_agent_time": 0.004506349563598633, "random_agent_time": 0.0074634552001953125, "board_size": 10, "swap_players": false, "run_out": "An exception raised. The traceback is as follows:\nTraceback (most recent call last):\n  File \"/home/ml/users/ksinha4/mlp/comp424_final_project/submissions/comp424mcgill/final-project-a_team_name/world.py\", line 310, in step\n    raise ValueError(\nValueError: [INVALID:STEP] Not a valid step from [7 5] to [7 5] and put barrier at 0, with max steps = 5\n\nExecute Random Walk!\nAn exception raised. The traceback is as follows:\nTraceback (most recent call last):\n  File \"/home/ml/users/ksinha4/mlp/comp424_final_project/submissions/comp424mcgill/final-project-a_team_name/world.py\", line 310, in step\n    raise ValueError(\nValueError: [INVALID:STEP] Not a valid step from [6 6] to [6 6] and put barrier at 0, with max steps = 5\n\nExecute Random Walk!\nAn exception raised. The traceback is as follows:\nTraceback (most recent call last):\n  File \"/home/ml/users/ksinha4/mlp/comp424_final_project/submissions/comp424mcgill/final-project-a_team_name/world.py\", line 310, in step\n    raise ValueError(\nValueError: [INVALID:STEP] Not a valid step from [7 8] to [7 8] and put barrier at 0, with max steps = 5\n\nExecute Random Walk!\nAn exception raised. The traceback is as follows:\nTraceback (most recent call last):\n  File \"/home/ml/users/ksinha4/mlp/comp424_final_project/submissions/comp424mcgill/final-project-a_team_name/world.py\", line 310, in step\n    raise ValueError(\nValueError: [INVALID:STEP] Not a valid step from [7 8] to [7 8] and put barrier at 0, with max steps = 5\n\nExecute Random Walk!\n"}, {"student_agent_score": 1, "random_agent_score": 48, "student_agent_time": 0.003717184066772461, "random_agent_time": 0.0022301673889160156, "board_size": 7, "swap_players": true, "run_out": "An exception raised. The traceback is as follows:\nTraceback (most recent call last):\n  File \"/home/ml/users/ksinha4/mlp/comp424_final_project/submissions/comp424mcgill/final-project-a_team_name/world.py\", line 310, in step\n    raise ValueError(\nValueError: [INVALID:STEP] Not a valid step from [2 3] to [2 3] and put barrier at 0, with max steps = 4\n\nExecute Random Walk!\nAn exception raised. The traceback is as follows:\nTraceback (most recent call last):\n  File \"/home/ml/users/ksinha4/mlp/comp424_final_project/submissions/comp424mcgill/final-project-a_team_name/world.py\", line 310, in step\n    raise ValueError(\nValueError: [INVALID:STEP] Not a valid step from [5 4] to [5 4] and put barrier at 0, with max steps = 4\n\nExecute Random Walk!\nAn exception raised. The traceback is as follows:\nTraceback (most recent call last):\n  File \"/home/ml/users/ksinha4/mlp/comp424_final_project/submissions/comp424mcgill/final-project-a_team_name/world.py\", line 310, in step\n    raise ValueError(\nValueError: [INVALID:STEP] Not a valid step from [6 3] to [6 3] and put barrier at 0, with max steps = 4\n\nExecute Random Walk!\n"}, {"student_agent_score": 1, "random_agent_score": 48, "student_agent_time": 0.004350185394287109, "random_agent_time": 0.002199888229370117, "board_size": 7, "swap_players": false, "run_out": "An exception raised. The traceback is as follows:\nTraceback (most recent call last):\n  File \"/home/ml/users/ksinha4/mlp/comp424_final_project/submissions/comp424mcgill/final-project-a_team_name/world.py\", line 310, in step\n    raise ValueError(\nValueError: [INVALID:STEP] Not a valid step from [4 3] to [4 3] and put barrier at 0, with max steps = 4\n\nExecute Random Walk!\nAn exception raised. The traceback is as follows:\nTraceback (most recent call last):\n  File \"/home/ml/users/ksinha4/mlp/comp424_final_project/submissions/comp424mcgill/final-project-a_team_name/world.py\", line 310, in step\n    raise ValueError(\nValueError: [INVALID:STEP] Not a valid step from [4 2] to [4 2] and put barrier at 0, with max steps = 4\n\nExecute Random Walk!\nAn exception raised. The traceback is as follows:\nTraceback (most recent call last):\n  File \"/home/ml/users/ksinha4/mlp/comp424_final_project/submissions/comp424mcgill/final-project-a_team_name/world.py\", line 310, in step\n    raise ValueError(\nValueError: [INVALID:STEP] Not a valid step from [4 3] to [4 3] and put barrier at 0, with max steps = 4\n\nExecute Random Walk!\nAn exception raised. The traceback is as follows:\nTraceback (most recent call last):\n  File \"/home/ml/users/ksinha4/mlp/comp424_final_project/submissions/comp424mcgill/final-project-a_team_name/world.py\", line 310, in step\n    raise ValueError(\nValueError: [INVALID:STEP] Not a valid step from [5 4] to [5 4] and put barrier at 0, with max steps = 4\n\nExecute Random Walk!\nAn exception raised. The traceback is as follows:\nTraceback (most recent call last):\n  File \"/home/ml/users/ksinha4/mlp/comp424_final_project/submissions/comp424mcgill/final-project-a_team_name/world.py\", line 310, in step\n    raise ValueError(\nValueError: [INVALID:STEP] Not a valid step from [6 3] to [6 3] and put barrier at 0, with max steps = 4\n\nExecute Random Walk!\n"}, {"student_agent_score": 1, "random_agent_score": 48, "student_agent_time": 0.0025718212127685547, "random_agent_time": 0.002142667770385742, "board_size": 7, "swap_players": true, "run_out": "An exception raised. The traceback is as follows:\nTraceback (most recent call last):\n  File \"/home/ml/users/ksinha4/mlp/comp424_final_project/submissions/comp424mcgill/final-project-a_team_name/world.py\", line 310, in step\n    raise ValueError(\nValueError: [INVALID:STEP] Not a valid step from [2 3] to [2 3] and put barrier at 0, with max steps = 4\n\nExecute Random Walk!\nAn exception raised. The traceback is as follows:\nTraceback (most recent call last):\n  File \"/home/ml/users/ksinha4/mlp/comp424_final_project/submissions/comp424mcgill/final-project-a_team_name/world.py\", line 310, in step\n    raise ValueError(\nValueError: [INVALID:STEP] Not a valid step from [5 4] to [5 4] and put barrier at 0, with max steps = 4\n\nExecute Random Walk!\nAn exception raised. The traceback is as follows:\nTraceback (most recent call last):\n  File \"/home/ml/users/ksinha4/mlp/comp424_final_project/submissions/comp424mcgill/final-project-a_team_name/world.py\", line 310, in step\n    raise ValueError(\nValueError: [INVALID:STEP] Not a valid step from [6 3] to [6 3] and put barrier at 0, with max steps = 4\n\nExecute Random Walk!\n"}, {"student_agent_score": 1, "random_agent_score": 48, "student_agent_time": 0.004524707794189453, "random_agent_time": 0.0031175613403320312, "board_size": 7, "swap_players": false, "run_out": "An exception raised. The traceback is as follows:\nTraceback (most recent call last):\n  File \"/home/ml/users/ksinha4/mlp/comp424_final_project/submissions/comp424mcgill/final-project-a_team_name/world.py\", line 310, in step\n    raise ValueError(\nValueError: [INVALID:STEP] Not a valid step from [4 3] to [4 3] and put barrier at 0, with max steps = 4\n\nExecute Random Walk!\nAn exception raised. The traceback is as follows:\nTraceback (most recent call last):\n  File \"/home/ml/users/ksinha4/mlp/comp424_final_project/submissions/comp424mcgill/final-project-a_team_name/world.py\", line 310, in step\n    raise ValueError(\nValueError: [INVALID:STEP] Not a valid step from [4 2] to [4 2] and put barrier at 0, with max steps = 4\n\nExecute Random Walk!\nAn exception raised. The traceback is as follows:\nTraceback (most recent call last):\n  File \"/home/ml/users/ksinha4/mlp/comp424_final_project/submissions/comp424mcgill/final-project-a_team_name/world.py\", line 310, in step\n    raise ValueError(\nValueError: [INVALID:STEP] Not a valid step from [4 3] to [4 3] and put barrier at 0, with max steps = 4\n\nExecute Random Walk!\nAn exception raised. The traceback is as follows:\nTraceback (most recent call last):\n  File \"/home/ml/users/ksinha4/mlp/comp424_final_project/submissions/comp424mcgill/final-project-a_team_name/world.py\", line 310, in step\n    raise ValueError(\nValueError: [INVALID:STEP] Not a valid step from [5 4] to [5 4] and put barrier at 0, with max steps = 4\n\nExecute Random Walk!\nAn exception raised. The traceback is as follows:\nTraceback (most recent call last):\n  File \"/home/ml/users/ksinha4/mlp/comp424_final_project/submissions/comp424mcgill/final-project-a_team_name/world.py\", line 310, in step\n    raise ValueError(\nValueError: [INVALID:STEP] Not a valid step from [6 3] to [6 3] and put barrier at 0, with max steps = 4\n\nExecute Random Walk!\n"}, {"student_agent_score": 2, "random_agent_score": 98, "student_agent_time": 0.003338336944580078, "random_agent_time": 0.0040950775146484375, "board_size": 10, "swap_players": false, "run_out": "An exception raised. The traceback is as follows:\nTraceback (most recent call last):\n  File \"/home/ml/users/ksinha4/mlp/comp424_final_project/submissions/comp424mcgill/final-project-a_team_name/world.py\", line 310, in step\n    raise ValueError(\nValueError: [INVALID:STEP] Not a valid step from [7 5] to [7 5] and put barrier at 0, with max steps = 5\n\nExecute Random Walk!\nAn exception raised. The traceback is as follows:\nTraceback (most recent call last):\n  File \"/home/ml/users/ksinha4/mlp/comp424_final_project/submissions/comp424mcgill/final-project-a_team_name/world.py\", line 310, in step\n    raise ValueError(\nValueError: [INVALID:STEP] Not a valid step from [6 6] to [6 6] and put barrier at 0, with max steps = 5\n\nExecute Random Walk!\nAn exception raised. The traceback is as follows:\nTraceback (most recent call last):\n  File \"/home/ml/users/ksinha4/mlp/comp424_final_project/submissions/comp424mcgill/final-project-a_team_name/world.py\", line 310, in step\n    raise ValueError(\nValueError: [INVALID:STEP] Not a valid step from [7 8] to [7 8] and put barrier at 0, with max steps = 5\n\nExecute Random Walk!\nAn exception raised. The traceback is as follows:\nTraceback (most recent call last):\n  File \"/home/ml/users/ksinha4/mlp/comp424_final_project/submissions/comp424mcgill/final-project-a_team_name/world.py\", line 310, in step\n    raise ValueError(\nValueError: [INVALID:STEP] Not a valid step from [7 8] to [7 8] and put barrier at 0, with max steps = 5\n\nExecute Random Walk!\n"}, {"student_agent_score": 117, "random_agent_score": 1, "student_agent_time": 0.007664203643798828, "random_agent_time": 0.006429433822631836, "board_size": 11, "swap_players": false, "run_out": "An exception raised. The traceback is as follows:\nTraceback (most recent call last):\n  File \"/home/ml/users/ksinha4/mlp/comp424_final_project/submissions/comp424mcgill/final-project-a_team_name/world.py\", line 310, in step\n    raise ValueError(\nValueError: [INVALID:STEP] Not a valid step from [1 7] to [1 7] and put barrier at 0, with max steps = 6\n\nExecute Random Walk!\nAn exception raised. The traceback is as follows:\nTraceback (most recent call last):\n  File \"/home/ml/users/ksinha4/mlp/comp424_final_project/submissions/comp424mcgill/final-project-a_team_name/world.py\", line 310, in step\n    raise ValueError(\nValueError: [INVALID:STEP] Not a valid step from [1 8] to [1 8] and put barrier at 0, with max steps = 6\n\nExecute Random Walk!\nAn exception raised. The traceback is as follows:\nTraceback (most recent call last):\n  File \"/home/ml/users/ksinha4/mlp/comp424_final_project/submissions/comp424mcgill/final-project-a_team_name/world.py\", line 310, in step\n    raise ValueError(\nValueError: [INVALID:STEP] Not a valid step from [1 6] to [1 6] and put barrier at 0, with max steps = 6\n\nExecute Random Walk!\nAn exception raised. The traceback is as follows:\nTraceback (most recent call last):\n  File \"/home/ml/users/ksinha4/mlp/comp424_final_project/submissions/comp424mcgill/final-project-a_team_name/world.py\", line 310, in step\n    raise ValueError(\nValueError: [INVALID:STEP] Not a valid step from [3 3] to [3 3] and put barrier at 0, with max steps = 6\n\nExecute Random Walk!\nAn exception raised. The traceback is as follows:\nTraceback (most recent call last):\n  File \"/home/ml/users/ksinha4/mlp/comp424_final_project/submissions/comp424mcgill/final-project-a_team_name/world.py\", line 310, in step\n    raise ValueError(\nValueError: [INVALID:STEP] Not a valid step from [3 4] to [3 4] and put barrier at 0, with max steps = 6\n\nExecute Random Walk!\nAn exception raised. The traceback is as follows:\nTraceback (most recent call last):\n  File \"/home/ml/users/ksinha4/mlp/comp424_final_project/submissions/comp424mcgill/final-project-a_team_name/world.py\", line 310, in step\n    raise ValueError(\nValueError: [INVALID:STEP] Not a valid step from [3 4] to [3 4] and put barrier at 0, with max steps = 6\n\nExecute Random Walk!\nAn exception raised. The traceback is as follows:\nTraceback (most recent call last):\n  File \"/home/ml/users/ksinha4/mlp/comp424_final_project/submissions/comp424mcgill/final-project-a_team_name/world.py\", line 310, in step\n    raise ValueError(\nValueError: [INVALID:STEP] Not a valid step from [4 4] to [4 4] and put barrier at 0, with max steps = 6\n\nExecute Random Walk!\nAn exception raised. The traceback is as follows:\nTraceback (most recent call last):\n  File \"/home/ml/users/ksinha4/mlp/comp424_final_project/submissions/comp424mcgill/final-project-a_team_name/world.py\", line 310, in step\n    raise ValueError(\nValueError: [INVALID:STEP] Not a valid step from [4 4] to [4 4] and put barrier at 0, with max steps = 6\n\nExecute Random Walk!\n"}]}